Workbook

Sheet RESUMEN
A1: HISTORIAL DE PRECIOS DE PROVEEDORES — CONSOLIDADO
A2: Dic 2024 → Jul 2026 · fuente: 12 tablas mensuales de órdenes + historial previo · generado 12/08/2026
A4: TIPO DE CAMBIO (MXN por USD): | B4: 20 | C4: ← editable; las columnas MXN de todas las hojas usan esta celda
A6: PROVEEDOR | B6: HOJA | C6: ÓRDENES | D6: PRIMERA ORDEN | E6: ÚLTIMA ORDEN | F6: SKUs DISTINTOS | G6: LÍNEAS | H6: PIEZAS
A7: HAIFENG | B7: HAIFENG | C7: 13 | D7: 2025-09-01 | E7: 2026-06-16 | F7: 1015 | G7: 2601 | H7: 8885
A8: ZOEY | B8: ZOEY | C8: 11 | D8: 2025-09-01 | E8: 2026-06-08 | F8: 468 | G8: 1020 | H8: 2589
A9: CYNTHIA | B9: CYNTHIA CAO | C9: 8 | D9: 2025-09-05 | E9: 2026-07-07 | F9: 361 | G9: 905 | H9: 2759
A10: NANCY | B10: NANCY VIP | C10: 7 | D10: 2025-09-06 | E10: 2026-07-09 | F10: 305 | G10: 582 | H10: 2230
A11: DINA DU | B11: DINA DU | C11: 5 | D11: 2024-12-01 | E11: 2026-04-27 | F11: 85 | G11: 106 | H11: 377
A12: COCOMA | B12: COCOMA | C12: 2 | D12: 2025-05-01 | E12: 2026-01-20 | F12: 51 | G12: 73 | H12: 368
A13: MOLLY | B13: MOLLY | C13: 1 | D13: 2025-10-10 | E13: 2025-10-10 | F13: 19 | G13: 19 | H13: 38
A14: COCO ZHANG | B14: COCO ZHANG | C14: 1 | D14: 2026-02-16 | E14: 2026-02-16 | F14: 13 | G14: 13 | H14: 20
A15: TOTAL | C15: =SUM(C7:C14) | F15: =SUM(F7:F14) | G15: =SUM(G7:G14) | H15: =SUM(H7:H14)
A17: CÓMO LEER LAS HOJAS DE PROVEEDOR:
A18: • Una fila por SKU. Cada columna de orden muestra el COSTO UNITARIO (USD) pagado en esa orden; celda vacía = no se ordenó.
A19: • MEJOR (US) = mínimo histórico · ÚLTIMA (US) = costo de la orden más reciente · MXN = MEJOR × tipo de cambio (celda B4).
A20: • Columnas marcadas con * vienen del historial previo (órdenes que no están en las tablas mensuales: CYNTHIA 07/07/26, ZOEY dic 25, DINA DU orden 1046 dic 24/ene 25).
A21: • CYNTHIA: desde abril 2026 cambió el método (precio de lista + descuento sobre el total). La columna "MEJOR DESDE ABR ★" es la referencia real.
A22: • NANCY 09/07/2026: se usaron los costos de la tabla mensual de julio (con descuento), no los del historial viejo.
A23: • La hoja TODAS LAS ORDENES tiene el detalle línea por línea (cantidad, costos con envío/comisiones, ROAS y precio de venta al momento de la orden).
A24: • De los dos archivos de FEBRERO 2026 se usó la versión "(1)", que incluye la orden COCO ZHANG 16/02/2026 que falta en el otro.

Sheet ALERTA ROAS
A1: ALERTA ROAS — PRODUCTOS VENDIÉNDOSE POR DEBAJO DE 3.5× SU COSTO
A2: 40 CRÍTICOS (precio < 2.5× costo) y 194 en PELIGRO (2.5×–3.5×) de 2,191 SKUs cruzados con Shopify el 12/08/2026. Costo = COSTO UNIT TOTAL (MXN) de la última orden (incluye envío, comisión Alibaba y Shop&Cross).
A3: MÚLTIPLO = precio Shopify ÷ costo. Con múltiplo < 2.5 la publicidad casi seguro pierde dinero; entre 2.5 y 3.5 el margen es frágil.
A5: ESTADO | B5: SKU | C5: PRODUCTO (Shopify) | D5: VARIANTE | E5: PROVEEDOR | F5: ÚLT. ORDEN | G5: COSTO UNIT TOTAL (MXN) | H5: PRECIO SHOPIFY (MXN) | I5: MÚLTIPLO | J5: PRECIO MÍN ROAS 2.5 | K5: PRECIO ROAS 3.5 | L5: PRECIO ROAS 4 | M5: STATUS | N5: INVENTARIO
A6: CRÍTICO (<2.5) | B6: 94530225617804 | C6: ARETES TRIBALES CD | D6: Default Title | E6: CYNTHIA | F6: 2025-09-05 | G6: 221.58 | H6: 250 | I6: =IF(G6=0,"",H6/G6) | J6: =ROUND(G6*2.5,0) | K6: =ROUND(G6*3.5,0) | L6: =ROUND(G6*4,0) | M6: DRAFT | N6: 2
A7: CRÍTICO (<2.5) | B7: 11915825763755 | C7: TRAJE DE BAÑO C | D7: L | E7: CYNTHIA | F7: 2026-04-27 | G7: 830.4 | H7: 1099 | I7: =IF(G7=0,"",H7/G7) | J7: =ROUND(G7*2.5,0) | K7: =ROUND(G7*3.5,0) | L7: =ROUND(G7*4,0) | M7: ACTIVE | N7: 0
A8: CRÍTICO (<2.5) | B8: 68802901471244 | C8: BOLSO LV MESSENGER | D8: 30cm de largo x 20cm de alto x 10 cm de ancho | E8: ZOEY | F8: 2026-03-02 | G8: 1261.29 | H8: 1900 | I8: =IF(G8=0,"",H8/G8) | J8: =ROUND(G8*2.5,0) | K8: =ROUND(G8*3.5,0) | L8: =ROUND(G8*4,0) | M8: ACTIVE | N8: 3
A9: CRÍTICO (<2.5) | B9: 85887252483277 | C9: CHAMARRA BLACK JW | D9: L | E9: MOLLY | F9: 2025-10-10 | G9: 594.3 | H9: 899 | I9: =IF(G9=0,"",H9/G9) | J9: =ROUND(G9*2.5,0) | K9: =ROUND(G9*3.5,0) | L9: =ROUND(G9*4,0) | M9: ACTIVE | N9: 0
A10: CRÍTICO (<2.5) | B10: 43728085695276 | C10: BOLSO F FENDIGRAPHY BLACK | D10: 14cm de largo x 11cm de alto x 4cm de ancho | E10: ZOEY | F10: 2025-09-01 | G10: 1255.89 | H10: 2050 | I10: =IF(G10=0,"",H10/G10) | J10: =ROUND(G10*2.5,0) | K10: =ROUND(G10*3.5,0) | L10: =ROUND(G10*4,0) | M10: ACTIVE | N10: 0
A11: CRÍTICO (<2.5) | B11: 41889241004845 | C11: CHOKER KNOT ZIRCONIAS GOLD | D11: Default Title | E11: CYNTHIA | F11: 2025-10-25 | G11: 518.8 | H11: 866 | I11: =IF(G11=0,"",H11/G11) | J11: =ROUND(G11*2.5,0) | K11: =ROUND(G11*3.5,0) | L11: =ROUND(G11*4,0) | M11: ACTIVE | N11: 1
A12: CRÍTICO (<2.5) | B12: 85887251827853 | C12: CAMISETA BLUE JW | D12: L | E12: MOLLY | F12: 2025-10-10 | G12: 405.73 | H12: 676 | I12: =IF(G12=0,"",H12/G12) | J12: =ROUND(G12*2.5,0) | K12: =ROUND(G12*3.5,0) | L12: =ROUND(G12*4,0) | M12: ACTIVE | N12: 1
A13: CRÍTICO (<2.5) | B13: 14679511089581 | C13: PULSERA H SILVER | D13: Default Title | E13: HAIFENG | F13: 2026-04-16 | G13: 273.2 | H13: 460 | I13: =IF(G13=0,"",H13/G13) | J13: =ROUND(G13*2.5,0) | K13: =ROUND(G13*3.5,0) | L13: =ROUND(G13*4,0) | M13: ACTIVE | N13: 2
A14: CRÍTICO (<2.5) | B14: 95383471436684 | C14: HOODIE C BLACK | D14: L | E14: DINA DU | F14: 2025-10-21 | G14: 756.93 | H14: 1285 | I14: =IF(G14=0,"",H14/G14) | J14: =ROUND(G14*2.5,0) | K14: =ROUND(G14*3.5,0) | L14: =ROUND(G14*4,0) | M14: ACTIVE | N14: 1
A15: CRÍTICO (<2.5) | B15: 37309581067981 | C15: HOODIE ALLS BLACK | D15: M | E15: ZOEY | F15: 2025-10-02 | G15: 826.84 | H15: 1449 | I15: =IF(G15=0,"",H15/G15) | J15: =ROUND(G15*2.5,0) | K15: =ROUND(G15*3.5,0) | L15: =ROUND(G15*4,0) | M15: ACTIVE | N15: 1
A16: CRÍTICO (<2.5) | B16: 85887251331053 | C16: SUDADERA ZIPPER BEIGE JW | D16: M | E16: MOLLY | F16: 2025-10-10 | G16: 540.02 | H16: 950 | I16: =IF(G16=0,"",H16/G16) | J16: =ROUND(G16*2.5,0) | K16: =ROUND(G16*3.5,0) | L16: =ROUND(G16*4,0) | M16: ACTIVE | N16: 0
A17: CRÍTICO (<2.5) | B17: 42981601575052 | C17: ANILLO ESSENTIAL V PERLE | D17: Default Title | E17: NANCY | F17: 2026-07-09 | G17: 136.2 | H17: 250 | I17: =IF(G17=0,"",H17/G17) | J17: =ROUND(G17*2.5,0) | K17: =ROUND(G17*3.5,0) | L17: =ROUND(G17*4,0) | M17: ACTIVE | N17: 0
... A47: PELIGRO (<3.5) | B47: 12314361636973 | C47: ANILLO F SILVER ZIRCONIAS | D47: 9 | E47: HAIFENG | F47: 2025-10-22 | G47: 147.9 | H47: 374 | I47: =IF(G47=0,"",H47/G47) | J47: =ROUND(G47*2.5,0) | K47: =ROUND(G47*3.5,0) | L47: =ROUND(G47*4,0) | M47: ACTIVE | N47: 2
A48: PELIGRO (<3.5) | B48: 89790741803853 | C48: COLLAR BV SILVER GRABADO CON ZIRCONIA | E48: HAIFENG | F48: 2025-09-25 | G48: 147.68 | H48: 375 | I48: =IF(G48=0,"",H48/G48) | J48: =ROUND(G48*2.5,0) | K48: =ROUND(G48*3.5,0) | L48: =ROUND(G48*4,0) | M48: ACTIVE | N48: 1
A49: PELIGRO (<3.5) | B49: 89790741914029 | C49: COLLAR BV ROSEGOLD GRABADO CON ZIRCONIA | D49: Default Title | E49: HAIFENG | F49: 2025-09-25 | G49: 147.68 | H49: 375 | I49: =IF(G49=0,"",H49/G49) | J49: =ROUND(G49*2.5,0) | K49: =ROUND(G49*3.5,0) | L49: =ROUND(G49*4,0) | M49: ACTIVE | N49: 3
A50: PELIGRO (<3.5) | B50: 16117871480237 | C50: PULSERA KNOT ONE ROSEGOLD CON ZIRCONIA | D50: Default Title | E50: HAIFENG | F50: 2025-09-25 | G50: 210.97 | H50: 535 | I50: =IF(G50=0,"",H50/G50) | J50: =ROUND(G50*2.5,0) | K50: =ROUND(G50*3.5,0) | L50: =ROUND(G50*4,0) | M50: ACTIVE | N50: 2
A51: PELIGRO (<3.5) | B51: 30410821083277 | C51: PULSERA KNOT ONE GOLD CON ZIRCONIA | D51: Default Title | E51: HAIFENG | F51: 2025-09-25 | G51: 210.97 | H51: 535 | I51: =IF(G51=0,"",H51/G51) | J51: =ROUND(G51*2.5,0) | K51: =ROUND(G51*3.5,0) | L51: =ROUND(G51*4,0) | M51: ACTIVE | N51: 1
A52: PELIGRO (<3.5) | B52: 17964141887725 | C52: LENTES CD LINK A1U | D52: Default Title | E52: HAIFENG | F52: 2026-05-06 | G52: 742.65 | H52: 1884 | I52: =IF(G52=0,"",H52/G52) | J52: =ROUND(G52*2.5,0) | K52: =ROUND(G52*3.5,0) | L52: =ROUND(G52*4,0) | M52: ACTIVE | N52: 2
A53: PELIGRO (<3.5) | B53: 34361211039213 | C53: PULSERA DIVAS DREAM SILVER | D53: Default Title | E53: HAIFENG | F53: 2026-04-16 | G53: 157.74 | H53: 403 | I53: =IF(G53=0,"",H53/G53) | J53: =ROUND(G53*2.5,0) | K53: =ROUND(G53*3.5,0) | L53: =ROUND(G53*4,0) | M53: ACTIVE | N53: 3
A54: PELIGRO (<3.5) | B54: 35432871939597 | C54: ARETES H MINI MAILLON ROSE GOLD-WHITE | D54: Default Title | E54: HAIFENG | F54: 2026-02-05 | G54: 190.05 | H54: 487 | I54: =IF(G54=0,"",H54/G54) | J54: =ROUND(G54*2.5,0) | K54: =ROUND(G54*3.5,0) | L54: =ROUND(G54*4,0) | M54: ACTIVE | N54: 3
A55: PELIGRO (<3.5) | B55: 85887252166317 | C55: SUETER GREY CASHMERE | D55: L | E55: MOLLY | F55: 2025-10-10 | G55: 500.02 | H55: 1283.24 | I55: =IF(G55=0,"",H55/G55) | J55: =ROUND(G55*2.5,0) | K55: =ROUND(G55*3.5,0) | L55: =ROUND(G55*4,0) | M55: ACTIVE | N55: 0
A56: PELIGRO (<3.5) | B56: 85887252087757 | C56: SUETER BONE JW | D56: L | E56: MOLLY | F56: 2025-10-10 | G56: 500.02 | H56: 1283.24 | I56: =IF(G56=0,"",H56/G56) | J56: =ROUND(G56*2.5,0) | K56: =ROUND(G56*3.5,0) | L56: =ROUND(G56*4,0) | M56: ACTIVE | N56: 1
A57: PELIGRO (<3.5) | B57: 42834319871628 | C57: SANDALIAS DG | D57: 27cm | E57: ZOEY | F57: 2026-06-08 | G57: 980.46 | H57: 2534 | I57: =IF(G57=0,"",H57/G57) | J57: =ROUND(G57*2.5,0) | K57: =ROUND(G57*3.5,0) | L57: =ROUND(G57*4,0) | M57: ACTIVE | N57: 1
A58: PELIGRO (<3.5) | B58: 61744051068109 | C58: PULSERA CD GOLD CON ZIRCONIA | D58: Default Title | E58: ZOEY | F58: 2026-01-20 | G58: 468.57 | H58: 1218 | I58: =IF(G58=0,"",H58/G58) | J58: =ROUND(G58*2.5,0) | K58: =ROUND(G58*3.5,0) | L58: =ROUND(G58*4,0) | M58: ACTIVE | N58: 6
A59: PELIGRO (<3.5) | B59: 48915671144269 | C59: CAMISETA CD OBLIQUE BLACK | D59: M OVERSIZE | E59: ZOEY | F59: 2026-04-20 | G59: 691.44 | H59: 1799 | I59: =IF(G59=0,"",H59/G59) | J59: =ROUND(G59*2.5,0) | K59: =ROUND(G59*3.5,0) | L59: =ROUND(G59*4,0) | M59: ACTIVE | N59: 2
A60: PELIGRO (<3.5) | B60: 48915671011501 | C60: CAMISETA CD OBLIQUE BLACK | D60: L OVERSIZE | E60: ZOEY | F60: 2026-04-20 | G60: 691.44 | H60: 1799 | I60: =IF(G60=0,"",H60/G60) | J60: =ROUND(G60*2.5,0) | K60: =ROUND(G60*3.5,0) | L60: =ROUND(G60*4,0) | M60: ACTIVE | N60: 1
A61: PELIGRO (<3.5) | B61: 15565825325196 | C61: CARTERA GC BI-FOLD | D61: 9.5cm x 10cm | E61: ZOEY | F61: 2026-03-19 | G61: 464.08 | H61: 1208 | I61: =IF(G61=0,"",H61/G61) | J61: =ROUND(G61*2.5,0) | K61: =ROUND(G61*3.5,0) | L61: =ROUND(G61*4,0) | M61: ACTIVE | N61: 4
A62: PELIGRO (<3.5) | B62: 63794531345773 | C62: LENTES CD SIGNATURE B8U | E62: ZOEY | F62: 2026-03-02 | G62: 840.86 | H62: 2187 | I62: =IF(G62=0,"",H62/G62) | J62: =ROUND(G62*2.5,0) | K62: =ROUND(G62*3.5,0) | L62: =ROUND(G62*4,0) | M62: ACTIVE | N62: 1
A63: PELIGRO (<3.5) | B63: 23025461332941 | C63: TENIS H BOUNCING WHITE | D63: 42/8MX | E63: ZOEY | F63: 2026-05-15 | G63: 1590.28 | H63: 4139 | I63: =IF(G63=0,"",H63/G63) | J63: =ROUND(G63*2.5,0) | K63: =ROUND(G63*3.5,0) | L63: =ROUND(G63*4,0) | M63: ACTIVE | N63: 1
A64: PELIGRO (<3.5) | B64: 23025461724461 | C64: MOCASINES GC HORSEBIT | D64: 42/8MX | E64: ZOEY | F64: 2026-05-15 | G64: 1537.27 | H64: 3997 | I64: =IF(G64=0,"",H64/G64) | J64: =ROUND(G64*2.5,0) | K64: =ROUND(G64*3.5,0) | L64: =ROUND(G64*4,0) | M64: ACTIVE | N64: 1
A65: PELIGRO (<3.5) | B65: 23025461857229 | C65: MOCASINES GC HORSEBIT | D65: 44/9MX | E65: ZOEY | F65: 2026-05-15 | G65: 1537.27 | H65: 3997 | I65: =IF(G65=0,"",H65/G65) | J65: =ROUND(G65*2.5,0) | K65: =ROUND(G65*3.5,0) | L65: =ROUND(G65*4,0) | M65: ACTIVE | N65: 1
A66: PELIGRO (<3.5) | B66: 69645921049005 | C66: PULSERA YSL GOLD | D66: Default Title | E66: NANCY | F66: 2026-07-09 | G66: 145.95 | H66: 380 | I66: =IF(G66=0,"",H66/G66) | J66: =ROUND(G66*2.5,0) | K66: =ROUND(G66*3.5,0) | L66: =ROUND(G66*4,0) | M66: ACTIVE | N66: 0
A67: PELIGRO (<3.5) | B67: 61050601014957 | C67: LEGGINGS LLM BLACK | D67: 2M ,1L | E67: ZOEY | F67: 2026-05-15 | G67: 662.62 | H67: 1729 | I67: =IF(G67=0,"",H67/G67) | J67: =ROUND(G67*2.5,0) | K67: =ROUND(G67*3.5,0) | L67: =ROUND(G67*4,0) | M67: ACTIVE | N67: 4
A68: PELIGRO (<3.5) | B68: 39252671462093 | C68: LENTES GC 1SN BLACK | D68: Default Title | E68: CYNTHIA | F68: 2025-10-25 | G68: 943.27 | H68: 2461 | I68: =IF(G68=0,"",H68/G68) | J68: =ROUND(G68*2.5,0) | K68: =ROUND(G68*3.5,0) | L68: =ROUND(G68*4,0) | M68: ACTIVE | N68: 2
A69: PELIGRO (<3.5) | B69: 29736662528589 | C69: ANILLO OPEN HEART SILVER | D69: 7 | E69: HAIFENG | F69: 2026-02-05 | G69: 149.27 | H69: 389 | I69: =IF(G69=0,"",H69/G69) | J69: =ROUND(G69*2.5,0) | K69: =ROUND(G69*3.5,0) | L69: =ROUND(G69*4,0) | M69: ACTIVE | N69: 1
A70: PELIGRO (<3.5) | B70: 44504631084621 | C70: BOLSO C TILLY BROWN | D70: 15cm de alto x 19.5cm de largo x 7.5cm de ancho | E70: DINA DU | F70: 2025-10-21 | G70: 1177.45 | H70: 3076.23 | I70: =IF(G70=0,"",H70/G70) | J70: =ROUND(G70*2.5,0) | K70: =ROUND(G70*3.5,0) | L70: =ROUND(G70*4,0) | M70: ACTIVE | N70: 1
...

Sheet HAIFENG
A1: HISTORIAL DE PRECIOS — HAIFENG
A2: 13 orden(es) · costo unitario en USD · MXN = MEJOR × RESUMEN!B4 · * = dato del historial previo
A4: SKU | B4: PRODUCTO | C4: VARIANTE | D4: MATERIAL | E4: Sep 2025 01/09 | F4: Sep 2025 25/09 | G4: Oct 2025 22/10 | H4: Nov 2025 11/11 | I4: Dic 2025 03/12 | J4: Ene 2026 20/01 | K4: Feb 2026 05/02 | L4: Feb 2026 10/02 | M4: Mar 2026 11/03 | N4: Abr 2026 16/04 | O4: May 2026 06/05 | P4: May 2026 26/05 | Q4: Jun 2026 16/06 | R4: MEJOR (US) | S4: ÚLTIMA (US) | T4: MXN (mejor×TC) | U4: # ÓRD.
A5: 64085742311277 | B5: ANILLO ALLIANCE CON ZIRCONIA C | C5: 5 | F5: 2 | R5: =IF(COUNT(E5:Q5)=0,"",MIN(E5:Q5)) | S5: =IF(COUNT(E5:Q5)=0,"",LOOKUP(2,1/(E5:Q5<>""),E5:Q5)) | T5: =IF(R5="","",ROUND(R5*RESUMEN!$B$4,0)) | U5: =COUNT(E5:Q5)
A6: 64085742444045 | B6: ANILLO ALLIANCE CON ZIRCONIA C | C6: 6 | F6: 2 | R6: =IF(COUNT(E6:Q6)=0,"",MIN(E6:Q6)) | S6: =IF(COUNT(E6:Q6)=0,"",LOOKUP(2,1/(E6:Q6<>""),E6:Q6)) | T6: =IF(R6="","",ROUND(R6*RESUMEN!$B$4,0)) | U6: =COUNT(E6:Q6)
A7: 64085742576813 | B7: ANILLO ALLIANCE CON ZIRCONIA ROSE GOLD C | C7: 7 | D7: Stainless Stee | H7: 2 | I7: 2 | P7: 2 | R7: =IF(COUNT(E7:Q7)=0,"",MIN(E7:Q7)) | S7: =IF(COUNT(E7:Q7)=0,"",LOOKUP(2,1/(E7:Q7<>""),E7:Q7)) | T7: =IF(R7="","",ROUND(R7*RESUMEN!$B$4,0)) | U7: =COUNT(E7:Q7)
A8: 64085742794061 | B8: ANILLO ALLIANCE ROSE GOLD C | C8: 6 | F8: 2 | R8: =IF(COUNT(E8:Q8)=0,"",MIN(E8:Q8)) | S8: =IF(COUNT(E8:Q8)=0,"",LOOKUP(2,1/(E8:Q8<>""),E8:Q8)) | T8: =IF(R8="","",ROUND(R8*RESUMEN!$B$4,0)) | U8: =COUNT(E8:Q8)
A9: 64085742826829 | B9: ANILLO ALLIANCE ROSE GOLD C | C9: 7 | D9: Stainless Stee | P9: 2 | R9: =IF(COUNT(E9:Q9)=0,"",MIN(E9:Q9)) | S9: =IF(COUNT(E9:Q9)=0,"",LOOKUP(2,1/(E9:Q9<>""),E9:Q9)) | T9: =IF(R9="","",ROUND(R9*RESUMEN!$B$4,0)) | U9: =COUNT(E9:Q9)
A10: 66075791007693 | B10: ANILLO ALLIANCE SILVER C | C10: 7 | D10: Stainless Stee | H10: 2 | O10: 2 | R10: =IF(COUNT(E10:Q10)=0,"",MIN(E10:Q10)) | S10: =IF(COUNT(E10:Q10)=0,"",LOOKUP(2,1/(E10:Q10<>""),E10:Q10)) | T10: =IF(R10="","",ROUND(R10*RESUMEN!$B$4,0)) | U10: =COUNT(E10:Q10)
A11: 66075801140461 | B11: ANILLO ALLIANCE SILVER C | C11: 8 | H11: 2 | R11: =IF(COUNT(E11:Q11)=0,"",MIN(E11:Q11)) | S11: =IF(COUNT(E11:Q11)=0,"",LOOKUP(2,1/(E11:Q11<>""),E11:Q11)) | T11: =IF(R11="","",ROUND(R11*RESUMEN!$B$4,0)) | U11: =COUNT(E11:Q11)
A12: 66075801273229 | B12: ANILLO ALLIANCE SILVER C | C12: 9 | D12: Stainless stee | H12: 2 | I12: 2 | J12: 2 | N12: 2 | R12: =IF(COUNT(E12:Q12)=0,"",MIN(E12:Q12)) | S12: =IF(COUNT(E12:Q12)=0,"",LOOKUP(2,1/(E12:Q12<>""),E12:Q12)) | T12: =IF(R12="","",ROUND(R12*RESUMEN!$B$4,0)) | U12: =COUNT(E12:Q12)
A13: 67201533404653 | B13: ANILLO ANCHO TRUE T GOLD | C13: 6 | D13: Copper Alloy | Q13: 7 | R13: =IF(COUNT(E13:Q13)=0,"",MIN(E13:Q13)) | S13: =IF(COUNT(E13:Q13)=0,"",LOOKUP(2,1/(E13:Q13<>""),E13:Q13)) | T13: =IF(R13="","",ROUND(R13*RESUMEN!$B$4,0)) | U13: =COUNT(E13:Q13)
A14: 67201533537421 | B14: ANILLO ANCHO TRUE T GOLD | C14: 7 | E14: 7 | H14: 7 | I14: 7 | R14: =IF(COUNT(E14:Q14)=0,"",MIN(E14:Q14)) | S14: =IF(COUNT(E14:Q14)=0,"",LOOKUP(2,1/(E14:Q14<>""),E14:Q14)) | T14: =IF(R14="","",ROUND(R14*RESUMEN!$B$4,0)) | U14: =COUNT(E14:Q14)
A15: 67201533670189 | B15: ANILLO ANCHO TRUE T GOLD | C15: 8 | D15: Copper alloy | E15: 7 | I15: 7 | N15: 7 | R15: =IF(COUNT(E15:Q15)=0,"",MIN(E15:Q15)) | S15: =IF(COUNT(E15:Q15)=0,"",LOOKUP(2,1/(E15:Q15<>""),E15:Q15)) | T15: =IF(R15="","",ROUND(R15*RESUMEN!$B$4,0)) | U15: =COUNT(E15:Q15)
A16: 21605761269037 | B16: ANILLO BACK SOON T ROSE GOLD | C16: 5 | D16: Stainless stee | F16: 3 | N16: 3 | R16: =IF(COUNT(E16:Q16)=0,"",MIN(E16:Q16)) | S16: =IF(COUNT(E16:Q16)=0,"",LOOKUP(2,1/(E16:Q16<>""),E16:Q16)) | T16: =IF(R16="","",ROUND(R16*RESUMEN!$B$4,0)) | U16: =COUNT(E16:Q16)
A17: 21605771301805 | B17: ANILLO BACK SOON T ROSE GOLD | C17: 6 | D17: Stainless Stee | F17: 3 | M17: 3 | Q17: 3 | R17: =IF(COUNT(E17:Q17)=0,"",MIN(E17:Q17)) | S17: =IF(COUNT(E17:Q17)=0,"",LOOKUP(2,1/(E17:Q17<>""),E17:Q17)) | T17: =IF(R17="","",ROUND(R17*RESUMEN!$B$4,0)) | U17: =COUNT(E17:Q17)
A18: 21605771334573 | B18: ANILLO BACK SOON T ROSE GOLD | C18: 7 | H18: 3 | I18: 3 | R18: =IF(COUNT(E18:Q18)=0,"",MIN(E18:Q18)) | S18: =IF(COUNT(E18:Q18)=0,"",LOOKUP(2,1/(E18:Q18<>""),E18:Q18)) | T18: =IF(R18="","",ROUND(R18*RESUMEN!$B$4,0)) | U18: =COUNT(E18:Q18)
A19: ANDREA | B19: ANILLO BACK SOON T SILVER | D19: Stainless stee | Q19: 1.8 | R19: =IF(COUNT(E19:Q19)=0,"",MIN(E19:Q19)) | S19: =IF(COUNT(E19:Q19)=0,"",LOOKUP(2,1/(E19:Q19<>""),E19:Q19)) | T19: =IF(R19="","",ROUND(R19*RESUMEN!$B$4,0)) | U19: =COUNT(E19:Q19)
A20: 21605774283693 | B20: ANILLO BACK SOON T SILVER | C20: 6 | D20: Stainless Stee | F20: 3 | I20: 3 | J20: 3 | O20: 3 | P20: 3 | R20: =IF(COUNT(E20:Q20)=0,"",MIN(E20:Q20)) | S20: =IF(COUNT(E20:Q20)=0,"",LOOKUP(2,1/(E20:Q20<>""),E20:Q20)) | T20: =IF(R20="","",ROUND(R20*RESUMEN!$B$4,0)) | U20: =COUNT(E20:Q20)
A21: 21605774316461 | B21: ANILLO BACK SOON T SILVER | C21: 7 | D21: Stainless stee | H21: 3 | I21: 3 | J21: 3 | L21: 3 | N21: 3 | R21: =IF(COUNT(E21:Q21)=0,"",MIN(E21:Q21)) | S21: =IF(COUNT(E21:Q21)=0,"",LOOKUP(2,1/(E21:Q21<>""),E21:Q21)) | T21: =IF(R21="","",ROUND(R21*RESUMEN!$B$4,0)) | U21: =COUNT(E21:Q21)
A22: 21605774349229 | B22: ANILLO BACK SOON T SILVER | C22: 8 | D22: Stainless stee | F22: 3 | H22: 3 | I22: 3 | N22: 3 | R22: =IF(COUNT(E22:Q22)=0,"",MIN(E22:Q22)) | S22: =IF(COUNT(E22:Q22)=0,"",LOOKUP(2,1/(E22:Q22<>""),E22:Q22)) | T22: =IF(R22="","",ROUND(R22*RESUMEN!$B$4,0)) | U22: =COUNT(E22:Q22)
A23: 67201533776845 | B23: ANILLO BEAN CON ZIRCONIA GOLD | C23: 6 | D23: Copper alloy | H23: 5 | I23: 5 | J23: 5 | N23: 5 | R23: =IF(COUNT(E23:Q23)=0,"",MIN(E23:Q23)) | S23: =IF(COUNT(E23:Q23)=0,"",LOOKUP(2,1/(E23:Q23<>""),E23:Q23)) | T23: =IF(R23="","",ROUND(R23*RESUMEN!$B$4,0)) | U23: =COUNT(E23:Q23)
A24: 67201533809613 | B24: ANILLO BEAN CON ZIRCONIA GOLD | C24: 7 | D24: Copper alloy | F24: 5 | J24: 5 | L24: 5 | R24: =IF(COUNT(E24:Q24)=0,"",MIN(E24:Q24)) | S24: =IF(COUNT(E24:Q24)=0,"",LOOKUP(2,1/(E24:Q24<>""),E24:Q24)) | T24: =IF(R24="","",ROUND(R24*RESUMEN!$B$4,0)) | U24: =COUNT(E24:Q24)
A25: 67201533942381 | B25: ANILLO BEAN CON ZIRCONIA GOLD | C25: 8 | I25: 5 | R25: =IF(COUNT(E25:Q25)=0,"",MIN(E25:Q25)) | S25: =IF(COUNT(E25:Q25)=0,"",LOOKUP(2,1/(E25:Q25<>""),E25:Q25)) | T25: =IF(R25="","",ROUND(R25*RESUMEN!$B$4,0)) | U25: =COUNT(E25:Q25)
A26: 67201534287725 | B26: ANILLO BEAN T SILVER MINI | C26: 6 | D26: Copper alloy | I26: 5 | J26: 5 | L26: 5 | R26: =IF(COUNT(E26:Q26)=0,"",MIN(E26:Q26)) | S26: =IF(COUNT(E26:Q26)=0,"",LOOKUP(2,1/(E26:Q26<>""),E26:Q26)) | T26: =IF(R26="","",ROUND(R26*RESUMEN!$B$4,0)) | U26: =COUNT(E26:Q26)
A27: 654bd7ac2dee3 | B27: ANILLO BV 3 OROS-5 | C27: 5 | F27: 8 | R27: =IF(COUNT(E27:Q27)=0,"",MIN(E27:Q27)) | S27: =IF(COUNT(E27:Q27)=0,"",LOOKUP(2,1/(E27:Q27<>""),E27:Q27)) | T27: =IF(R27="","",ROUND(R27*RESUMEN!$B$4,0)) | U27: =COUNT(E27:Q27)
A28: 64e78e7b03ab1 | B28: ANILLO BV 3 OROS-8 | C28: 8 | F28: 8 | R28: =IF(COUNT(E28:Q28)=0,"",MIN(E28:Q28)) | S28: =IF(COUNT(E28:Q28)=0,"",LOOKUP(2,1/(E28:Q28<>""),E28:Q28)) | T28: =IF(R28="","",ROUND(R28*RESUMEN!$B$4,0)) | U28: =COUNT(E28:Q28)
A29: 64e78e7bb52a6 | B29: ANILLO BV 3 OROS-9 | C29: 9 | F29: 8 | R29: =IF(COUNT(E29:Q29)=0,"",MIN(E29:Q29)) | S29: =IF(COUNT(E29:Q29)=0,"",LOOKUP(2,1/(E29:Q29<>""),E29:Q29)) | T29: =IF(R29="","",ROUND(R29*RESUMEN!$B$4,0)) | U29: =COUNT(E29:Q29)
A30: 17964142179245 | B30: ANILLO BV ANISH KAPOOR | C30: 7 | O30: 8 | R30: =IF(COUNT(E30:Q30)=0,"",MIN(E30:Q30)) | S30: =IF(COUNT(E30:Q30)=0,"",LOOKUP(2,1/(E30:Q30<>""),E30:Q30)) | T30: =IF(R30="","",ROUND(R30*RESUMEN!$B$4,0)) | U30: =COUNT(E30:Q30)
A31: 40154173040301 | B31: ANILLO BV B.ZERO1 DELGADO SILVER | C31: 6 | K31: 7 | R31: =IF(COUNT(E31:Q31)=0,"",MIN(E31:Q31)) | S31: =IF(COUNT(E31:Q31)=0,"",LOOKUP(2,1/(E31:Q31<>""),E31:Q31)) | T31: =IF(R31="","",ROUND(R31*RESUMEN!$B$4,0)) | U31: =COUNT(E31:Q31)
A32: 40154173173069 | B32: ANILLO BV B.ZERO1 DELGADO SILVER | C32: 7 | K32: 7 | R32: =IF(COUNT(E32:Q32)=0,"",MIN(E32:Q32)) | S32: =IF(COUNT(E32:Q32)=0,"",LOOKUP(2,1/(E32:Q32<>""),E32:Q32)) | T32: =IF(R32="","",ROUND(R32*RESUMEN!$B$4,0)) | U32: =COUNT(E32:Q32)
A33: 66009451058221 | B33: ANILLO BV BROWN | C33: 6 | D33: Stainless stee | L33: 7 | R33: =IF(COUNT(E33:Q33)=0,"",MIN(E33:Q33)) | S33: =IF(COUNT(E33:Q33)=0,"",LOOKUP(2,1/(E33:Q33<>""),E33:Q33)) | T33: =IF(R33="","",ROUND(R33*RESUMEN!$B$4,0)) | U33: =COUNT(E33:Q33)
A34: 66009451058222 | B34: ANILLO BV BROWN | C34: 7 | D34: Stainless Stee | J34: 7 | L34: 7 | O34: 7 | R34: =IF(COUNT(E34:Q34)=0,"",MIN(E34:Q34)) | S34: =IF(COUNT(E34:Q34)=0,"",LOOKUP(2,1/(E34:Q34<>""),E34:Q34)) | T34: =IF(R34="","",ROUND(R34*RESUMEN!$B$4,0)) | U34: =COUNT(E34:Q34)
A35: 66009451058223 | B35: ANILLO BV BROWN | C35: 8 | D35: Stainless Stee | J35: 7 | L35: 7 | Q35: 7 | R35: =IF(COUNT(E35:Q35)=0,"",MIN(E35:Q35)) | S35: =IF(COUNT(E35:Q35)=0,"",LOOKUP(2,1/(E35:Q35<>""),E35:Q35)) | T35: =IF(R35="","",ROUND(R35*RESUMEN!$B$4,0)) | U35: =COUNT(E35:Q35)
A36: 6 | B36: ANILLO BV BROWN-6 | F36: 7 | R36: =IF(COUNT(E36:Q36)=0,"",MIN(E36:Q36)) | S36: =IF(COUNT(E36:Q36)=0,"",LOOKUP(2,1/(E36:Q36<>""),E36:Q36)) | T36: =IF(R36="","",ROUND(R36*RESUMEN!$B$4,0)) | U36: =COUNT(E36:Q36)
A37: 7 | B37: ANILLO BV BROWN-7 | F37: 7 | R37: =IF(COUNT(E37:Q37)=0,"",MIN(E37:Q37)) | S37: =IF(COUNT(E37:Q37)=0,"",LOOKUP(2,1/(E37:Q37<>""),E37:Q37)) | T37: =IF(R37="","",ROUND(R37*RESUMEN!$B$4,0)) | U37: =COUNT(E37:Q37)
A38: 8 | B38: ANILLO BV BROWN-8 | F38: 7 | R38: =IF(COUNT(E38:Q38)=0,"",MIN(E38:Q38)) | S38: =IF(COUNT(E38:Q38)=0,"",LOOKUP(2,1/(E38:Q38<>""),E38:Q38)) | T38: =IF(R38="","",ROUND(R38*RESUMEN!$B$4,0)) | U38: =COUNT(E38:Q38)
A39: 10956321024557 | B39: ANILLO BV BUMPS GOLD ZIRCONIAS | C39: 6 | D39: nan | F39: 10 | M39: 11 | R39: =IF(COUNT(E39:Q39)=0,"",MIN(E39:Q39)) | S39: =IF(COUNT(E39:Q39)=0,"",LOOKUP(2,1/(E39:Q39<>""),E39:Q39)) | T39: =IF(R39="","",ROUND(R39*RESUMEN!$B$4,0)) | U39: =COUNT(E39:Q39)
A40: 10956321157325 | B40: ANILLO BV BUMPS GOLD ZIRCONIAS | C40: 7 | D40: Stainless Stee | F40: 10 | L40: 11 | O40: 12 | R40: =IF(COUNT(E40:Q40)=0,"",MIN(E40:Q40)) | S40: =IF(COUNT(E40:Q40)=0,"",LOOKUP(2,1/(E40:Q40<>""),E40:Q40)) | T40: =IF(R40="","",ROUND(R40*RESUMEN!$B$4,0)) | U40: =COUNT(E40:Q40)
A41: 13667531088813 | B41: ANILLO BV BUMPS GOLD-BLACK | C41: 8 | D41: Stainless stee | F41: 9 | L41: 9 | R41: =IF(COUNT(E41:Q41)=0,"",MIN(E41:Q41)) | S41: =IF(COUNT(E41:Q41)=0,"",LOOKUP(2,1/(E41:Q41<>""),E41:Q41)) | T41: =IF(R41="","",ROUND(R41*RESUMEN!$B$4,0)) | U41: =COUNT(E41:Q41)
...

Sheet ZOEY
A1: HISTORIAL DE PRECIOS — ZOEY
A2: 11 orden(es) · costo unitario en USD · MXN = MEJOR × RESUMEN!B4 · * = dato del historial previo
A4: SKU | B4: PRODUCTO | C4: VARIANTE | D4: MATERIAL | E4: Sep 2025 01/09 | F4: Oct 2025 02/10 | G4: Oct 2025 25/10 | H4: Dic 2025 historial* | I4: Ene 2026 20/01 | J4: Feb 2026 16/02 | K4: Mar 2026 02/03 | L4: Mar 2026 19/03 | M4: Abr 2026 20/04 | N4: May 2026 15/05 | O4: Jun 2026 08/06 | P4: MEJOR (US) | Q4: ÚLTIMA (US) | R4: MXN (mejor×TC) | S4: # ÓRD.
A5: 67308101075309 | B5: ANILLO CD GOLD BLACK CON ZIRCONIA ANCHO | C5: 7 | D5: Brass + Zirconia | F5: 9 | P5: =IF(COUNT(E5:O5)=0,"",MIN(E5:O5)) | Q5: =IF(COUNT(E5:O5)=0,"",LOOKUP(2,1/(E5:O5<>""),E5:O5)) | R5: =IF(P5="","",ROUND(P5*RESUMEN!$B$4,0)) | S5: =COUNT(E5:O5)
A6: 72142921022125 | B6: ANILLO CD GOLD WHITE CON ZIRCONIA | C6: 6 | D6: Brass + Zirconia | F6: 9 | L6: 9 | N6: 9 | P6: =IF(COUNT(E6:O6)=0,"",MIN(E6:O6)) | Q6: =IF(COUNT(E6:O6)=0,"",LOOKUP(2,1/(E6:O6<>""),E6:O6)) | R6: =IF(P6="","",ROUND(P6*RESUMEN!$B$4,0)) | S6: =COUNT(E6:O6)
A7: 79684371047437 | B7: ANILLO GC BLONDIE ANCHO CON ZIRCONIA | C7: 8 | D7: Brass + Zirconia | F7: 9 | J7: 9 | K7: 9 | P7: =IF(COUNT(E7:O7)=0,"",MIN(E7:O7)) | Q7: =IF(COUNT(E7:O7)=0,"",LOOKUP(2,1/(E7:O7<>""),E7:O7)) | R7: =IF(P7="","",ROUND(P7*RESUMEN!$B$4,0)) | S7: =COUNT(E7:O7)
A8: 29502191036205 | B8: ANILLO LV LES GASTONS SILVER | C8: 8 | D8: Brass | F8: 9 | P8: =IF(COUNT(E8:O8)=0,"",MIN(E8:O8)) | Q8: =IF(COUNT(E8:O8)=0,"",LOOKUP(2,1/(E8:O8<>""),E8:O8)) | R8: =IF(P8="","",ROUND(P8*RESUMEN!$B$4,0)) | S8: =COUNT(E8:O8)
A9: 88201821024717 | B9: ANILLO LV SILVER MICROZIRCONIAS | C9: 8 | D9: Brass + Zirconia | F9: 9 | P9: =IF(COUNT(E9:O9)=0,"",MIN(E9:O9)) | Q9: =IF(COUNT(E9:O9)=0,"",LOOKUP(2,1/(E9:O9<>""),E9:O9)) | R9: =IF(P9="","",ROUND(P9*RESUMEN!$B$4,0)) | S9: =COUNT(E9:O9)
A10: 66593be00cc70 | B10: ANILLO PERLEE ROSEGOLD | C10: 7 | N10: 7 | P10: =IF(COUNT(E10:O10)=0,"",MIN(E10:O10)) | Q10: =IF(COUNT(E10:O10)=0,"",LOOKUP(2,1/(E10:O10<>""),E10:O10)) | R10: =IF(P10="","",ROUND(P10*RESUMEN!$B$4,0)) | S10: =COUNT(E10:O10)
A11: 15857685585804 | B11: ANILLO TRES AROS | C11: 6 | N11: 6 | P11: =IF(COUNT(E11:O11)=0,"",MIN(E11:O11)) | Q11: =IF(COUNT(E11:O11)=0,"",LOOKUP(2,1/(E11:O11<>""),E11:O11)) | R11: =IF(P11="","",ROUND(P11*RESUMEN!$B$4,0)) | S11: =COUNT(E11:O11)
A12: 56481488554124 | B12: ANILLO TRES AROS CON ZIRCONIA | C12: 6 | N12: 13 | P12: =IF(COUNT(E12:O12)=0,"",MIN(E12:O12)) | Q12: =IF(COUNT(E12:O12)=0,"",LOOKUP(2,1/(E12:O12<>""),E12:O12)) | R12: =IF(P12="","",ROUND(P12*RESUMEN!$B$4,0)) | S12: =COUNT(E12:O12)
A13: 56481485030668 | B13: ANILLO TRES AROS SILVER/BLACK | C13: 8 | N13: 6 | P13: =IF(COUNT(E13:O13)=0,"",MIN(E13:O13)) | Q13: =IF(COUNT(E13:O13)=0,"",LOOKUP(2,1/(E13:O13<>""),E13:O13)) | R13: =IF(P13="","",ROUND(P13*RESUMEN!$B$4,0)) | S13: =COUNT(E13:O13)
A14: 75249151006253 | B14: ARETES BV ZERO 1 GOLD CON ZIRCONIA | C14: Default Title | D14: Brass + Zirconia | F14: 9 | P14: =IF(COUNT(E14:O14)=0,"",MIN(E14:O14)) | Q14: =IF(COUNT(E14:O14)=0,"",LOOKUP(2,1/(E14:O14<>""),E14:O14)) | R14: =IF(P14="","",ROUND(P14*RESUMEN!$B$4,0)) | S14: =COUNT(E14:O14)
A15: 66148671022797 | B15: ARETES CD GOLD BLACK CON ZIRCONIA | C15: Default Title | D15: Brass + Zirconia | F15: 9 | J15: 9 | K15: 9 | M15: 9 | P15: =IF(COUNT(E15:O15)=0,"",MIN(E15:O15)) | Q15: =IF(COUNT(E15:O15)=0,"",LOOKUP(2,1/(E15:O15<>""),E15:O15)) | R15: =IF(P15="","",ROUND(P15*RESUMEN!$B$4,0)) | S15: =COUNT(E15:O15)
A16: 69612281066221 | B16: ARETES CD GOLD WHITE CON ZIRCONIA | C16: Default Title | D16: Brass + Zirconia | F16: 9 | J16: 9 | K16: 9 | N16: 9 | P16: =IF(COUNT(E16:O16)=0,"",MIN(E16:O16)) | Q16: =IF(COUNT(E16:O16)=0,"",LOOKUP(2,1/(E16:O16<>""),E16:O16)) | R16: =IF(P16="","",ROUND(P16*RESUMEN!$B$4,0)) | S16: =COUNT(E16:O16)
A17: 85409401017325 | B17: ARETES F OVAL GOLD CON ZIRCONIA | C17: Default Title | D17: Brass + Zirconia | F17: 8 | I17: 8 | J17: 8 | K17: 8 | M17: 8 | N17: 8 | P17: =IF(COUNT(E17:O17)=0,"",MIN(E17:O17)) | Q17: =IF(COUNT(E17:O17)=0,"",LOOKUP(2,1/(E17:O17<>""),E17:O17)) | R17: =IF(P17="","",ROUND(P17*RESUMEN!$B$4,0)) | S17: =COUNT(E17:O17)
A18: 83445961082989 | B18: ARETES GC MARMONT GOLD CON PERLA | C18: Default Title | D18: Brass + Zirconia | F18: 9 | O18: 8 | P18: =IF(COUNT(E18:O18)=0,"",MIN(E18:O18)) | Q18: =IF(COUNT(E18:O18)=0,"",LOOKUP(2,1/(E18:O18<>""),E18:O18)) | R18: =IF(P18="","",ROUND(P18*RESUMEN!$B$4,0)) | S18: =COUNT(E18:O18)
A19: 77275241042893 | B19: ARETES MM HEART GOLD WHITE | C19: 2cm | D19: Brass | F19: 8 | I19: 8 | L19: 8 | N19: 8 | O19: 8 | P19: =IF(COUNT(E19:O19)=0,"",MIN(E19:O19)) | Q19: =IF(COUNT(E19:O19)=0,"",LOOKUP(2,1/(E19:O19<>""),E19:O19)) | R19: =IF(P19="","",ROUND(P19*RESUMEN!$B$4,0)) | S19: =COUNT(E19:O19)
A20: 82310551082381 | B20: ARRACADAS F LOGO GOLD | C20: Default Title | D20: Brass | F20: 9 | O20: 9 | P20: =IF(COUNT(E20:O20)=0,"",MIN(E20:O20)) | Q20: =IF(COUNT(E20:O20)=0,"",LOOKUP(2,1/(E20:O20<>""),E20:O20)) | R20: =IF(P20="","",ROUND(P20*RESUMEN!$B$4,0)) | S20: =COUNT(E20:O20)
A21: 76327071018669 | B21: ARRACADAS SERPENTI VIPPER GOLD CON ZIRCONIA | C21: Default Title | D21: Brass + Zirconia | F21: 9 | J21: 9 | K21: 9 | L21: 9 | O21: 9 | P21: =IF(COUNT(E21:O21)=0,"",MIN(E21:O21)) | Q21: =IF(COUNT(E21:O21)=0,"",LOOKUP(2,1/(E21:O21<>""),E21:O21)) | R21: =IF(P21="","",ROUND(P21*RESUMEN!$B$4,0)) | S21: =COUNT(E21:O21)
A22: 93378831084685 | B22: BALLERINAS CC BEIGE BLACK | C22: 23cm | D22: Genuine leather | G22: 55 | I22: 55 | N22: 55 | P22: =IF(COUNT(E22:O22)=0,"",MIN(E22:O22)) | Q22: =IF(COUNT(E22:O22)=0,"",LOOKUP(2,1/(E22:O22<>""),E22:O22)) | R22: =IF(P22="","",ROUND(P22*RESUMEN!$B$4,0)) | S22: =COUNT(E22:O22)
A23: 93378841117453 | B23: BALLERINAS CC BEIGE BLACK | C23: 24-cm | D23: Genuine leather | G23: 55 | I23: 55 | M23: 55 | P23: =IF(COUNT(E23:O23)=0,"",MIN(E23:O23)) | Q23: =IF(COUNT(E23:O23)=0,"",LOOKUP(2,1/(E23:O23<>""),E23:O23)) | R23: =IF(P23="","",ROUND(P23*RESUMEN!$B$4,0)) | S23: =COUNT(E23:O23)
A24: 24780443041101 | B24: BALLERINAS CC COCO MARK | C24: 35/254MX | O24: 60 | P24: =IF(COUNT(E24:O24)=0,"",MIN(E24:O24)) | Q24: =IF(COUNT(E24:O24)=0,"",LOOKUP(2,1/(E24:O24<>""),E24:O24)) | R24: =IF(P24="","",ROUND(P24*RESUMEN!$B$4,0)) | S24: =COUNT(E24:O24)
A25: 24780442908333 | B25: BALLERINAS CC COCO MARK | C25: 38/25MX | O25: 60 | P25: =IF(COUNT(E25:O25)=0,"",MIN(E25:O25)) | Q25: =IF(COUNT(E25:O25)=0,"",LOOKUP(2,1/(E25:O25<>""),E25:O25)) | R25: =IF(P25="","",ROUND(P25*RESUMEN!$B$4,0)) | S25: =COUNT(E25:O25)
A26: 3378841221933 | B26: BALLERINAS LV BROWN CON INSIGNIAS | C26: 24CM | G26: 68 | P26: =IF(COUNT(E26:O26)=0,"",MIN(E26:O26)) | Q26: =IF(COUNT(E26:O26)=0,"",LOOKUP(2,1/(E26:O26<>""),E26:O26)) | R26: =IF(P26="","",ROUND(P26*RESUMEN!$B$4,0)) | S26: =COUNT(E26:O26)
A27: 93378841221933 | B27: BALLERINAS LV BROWN CON INSIGNIAS | C27: 24cm | D27: Genuine leather | I27: 68 | O27: 68 | P27: =IF(COUNT(E27:O27)=0,"",MIN(E27:O27)) | Q27: =IF(COUNT(E27:O27)=0,"",LOOKUP(2,1/(E27:O27<>""),E27:O27)) | R27: =IF(P27="","",ROUND(P27*RESUMEN!$B$4,0)) | S27: =COUNT(E27:O27)
A28: 93378841354701 | B28: BALLERINAS LV BROWN CON INSIGNIAS | C28: 25cm | D28: Genuine leather | G28: 68 | I28: 68 | O28: 68 | P28: =IF(COUNT(E28:O28)=0,"",MIN(E28:O28)) | Q28: =IF(COUNT(E28:O28)=0,"",LOOKUP(2,1/(E28:O28<>""),E28:O28)) | R28: =IF(P28="","",ROUND(P28*RESUMEN!$B$4,0)) | S28: =COUNT(E28:O28)
A29: 93378841495885 | B29: BALLERINAS MM BLACK CON ZIRCONIAS | C29: 24CM | G29: 72 | P29: =IF(COUNT(E29:O29)=0,"",MIN(E29:O29)) | Q29: =IF(COUNT(E29:O29)=0,"",LOOKUP(2,1/(E29:O29<>""),E29:O29)) | R29: =IF(P29="","",ROUND(P29*RESUMEN!$B$4,0)) | S29: =COUNT(E29:O29)
A30: 93378841508909 | B30: BALLERINAS PR BLACK CON LOGO | C30: 24cm | D30: Genuine leather | G30: 58 | I30: 58 | P30: =IF(COUNT(E30:O30)=0,"",MIN(E30:O30)) | Q30: =IF(COUNT(E30:O30)=0,"",LOOKUP(2,1/(E30:O30<>""),E30:O30)) | R30: =IF(P30="","",ROUND(P30*RESUMEN!$B$4,0)) | S30: =COUNT(E30:O30)
A31: 93378841641677 | B31: BALLERINAS PR BLACK CON LOGO | C31: 25-cm | D31: Genuine leather | G31: 58 | I31: 58 | M31: 58 | P31: =IF(COUNT(E31:O31)=0,"",MIN(E31:O31)) | Q31: =IF(COUNT(E31:O31)=0,"",LOOKUP(2,1/(E31:O31<>""),E31:O31)) | R31: =IF(P31="","",ROUND(P31*RESUMEN!$B$4,0)) | S31: =COUNT(E31:O31)
A32: 46740671064493 | B32: BOLSA DE DEPORTE BLACK | C32: Default Title | D32: Material: Spande | F32: 15 | I32: 40 | P32: =IF(COUNT(E32:O32)=0,"",MIN(E32:O32)) | Q32: =IF(COUNT(E32:O32)=0,"",LOOKUP(2,1/(E32:O32<>""),E32:O32)) | R32: =IF(P32="","",ROUND(P32*RESUMEN!$B$4,0)) | S32: =COUNT(E32:O32)
A33: 73626631067117 | B33: BOLSA DE MANO G GREEN | C33: Default Title | D33: Genuine leather | F33: 46 | I33: 35 | L33: 35 | O33: 35 | P33: =IF(COUNT(E33:O33)=0,"",MIN(E33:O33)) | Q33: =IF(COUNT(E33:O33)=0,"",LOOKUP(2,1/(E33:O33<>""),E33:O33)) | R33: =IF(P33="","",ROUND(P33*RESUMEN!$B$4,0)) | S33: =COUNT(E33:O33)
A34: 58450831080173 | B34: BOLSA DE RAQUETA LLM CREAM | C34: Default Title | D34: Bag Material: Ny | F34: 8 | I34: 30 | M34: 30 | P34: =IF(COUNT(E34:O34)=0,"",MIN(E34:O34)) | Q34: =IF(COUNT(E34:O34)=0,"",LOOKUP(2,1/(E34:O34<>""),E34:O34)) | R34: =IF(P34="","",ROUND(P34*RESUMEN!$B$4,0)) | S34: =COUNT(E34:O34)
A35: DANAHE | B35: BOLSA GC WHITE | O35: 21 | P35: =IF(COUNT(E35:O35)=0,"",MIN(E35:O35)) | Q35: =IF(COUNT(E35:O35)=0,"",LOOKUP(2,1/(E35:O35<>""),E35:O35)) | R35: =IF(P35="","",ROUND(P35*RESUMEN!$B$4,0)) | S35: =COUNT(E35:O35)
A36: 64e78f8c69235 | B36: BOLSA GC WHITE | C36: 22.5.cmx15cm | D36: Genuine leather | G36: 56 | M36: 56 | P36: =IF(COUNT(E36:O36)=0,"",MIN(E36:O36)) | Q36: =IF(COUNT(E36:O36)=0,"",LOOKUP(2,1/(E36:O36<>""),E36:O36)) | R36: =IF(P36="","",ROUND(P36*RESUMEN!$B$4,0)) | S36: =COUNT(E36:O36)
A37: 27168511089165 | B37: BOLSA GG SMALL BROWN | C37: Default Title | D37: Stainless steel | F37: 28 | I37: 46 | J37: 46 | K37: 46 | P37: =IF(COUNT(E37:O37)=0,"",MIN(E37:O37)) | Q37: =IF(COUNT(E37:O37)=0,"",LOOKUP(2,1/(E37:O37<>""),E37:O37)) | R37: =IF(P37="","",ROUND(P37*RESUMEN!$B$4,0)) | S37: =COUNT(E37:O37)
A38: 62571331097101 | B38: BOLSA LLM BLACK | C38: Default Title | D38: Genuine leather | F38: 35 | I38: 8 | M38: 8 | O38: 8 | P38: =IF(COUNT(E38:O38)=0,"",MIN(E38:O38)) | Q38: =IF(COUNT(E38:O38)=0,"",LOOKUP(2,1/(E38:O38<>""),E38:O38)) | R38: =IF(P38="","",ROUND(P38*RESUMEN!$B$4,0)) | S38: =COUNT(E38:O38)
A39: 52394691046605 | B39: BOLSA NANO NOÉ LV BROWN | C39: 13 cm de largo x 16 cm de alto x 10cm de ancho | I39: 20 | M39: 20 | P39: =IF(COUNT(E39:O39)=0,"",MIN(E39:O39)) | Q39: =IF(COUNT(E39:O39)=0,"",LOOKUP(2,1/(E39:O39<>""),E39:O39)) | R39: =IF(P39="","",ROUND(P39*RESUMEN!$B$4,0)) | S39: =COUNT(E39:O39)
A40: 64e78f2fafa3d | B40: BOLSA YSL WHITE | C40: 24cm x 15cm | D40: Genuine leather | H40: 52 | P40: =IF(COUNT(E40:O40)=0,"",MIN(E40:O40)) | Q40: =IF(COUNT(E40:O40)=0,"",LOOKUP(2,1/(E40:O40<>""),E40:O40)) | R40: =IF(P40="","",ROUND(P40*RESUMEN!$B$4,0)) | S40: =COUNT(E40:O40)
A41: 46281181071009 | B41: BOLSA YSL WHITE | C41: NUDE 24cm x 15cm | M41: 52 | P41: =IF(COUNT(E41:O41)=0,"",MIN(E41:O41)) | Q41: =IF(COUNT(E41:O41)=0,"",LOOKUP(2,1/(E41:O41<>""),E41:O41)) | R41: =IF(P41="","",ROUND(P41*RESUMEN!$B$4,0)) | S41: =COUNT(E41:O41)
...

Sheet CYNTHIA CAO
A1: HISTORIAL DE PRECIOS — CYNTHIA CAO
A2: 8 orden(es) · costo unitario en USD · MXN = MEJOR × RESUMEN!B4 · * = dato del historial previo
A4: SKU | B4: PRODUCTO | C4: VARIANTE | D4: MATERIAL | E4: Sep 2025 05/09 | F4: Oct 2025 25/10 | G4: Ene 2026 07/01 | H4: Feb 2026 18/02 | I4: Mar 2026 19/03 | J4: Abr 2026 27/04 | K4: May 2026 31/05 | L4: Jul 2026 CYN070726* | M4: MEJOR (US) | N4: ÚLTIMA (US) | O4: MXN (mejor×TC) | P4: # ÓRD. | Q4: MEJOR DESDE ABR ★
A5: 43897301288173 | B5: (Sin nombre) | C5: XGH493116 26cm w | D5: Genuine leather mi | G5: 63 | J5: 65 | L5: 63 | M5: =IF(COUNT(E5:L5)=0,"",MIN(E5:L5)) | N5: =IF(COUNT(E5:L5)=0,"",LOOKUP(2,1/(E5:L5<>""),E5:L5)) | O5: =IF(M5="","",ROUND(M5*RESUMEN!$B$4,0)) | P5: =COUNT(E5:L5) | Q5: =IF(COUNT(J5:L5)=0,"",MIN(J5:L5))
A6: 41889241640397 | B6: ANILLO CD ZIRCONIAS GOLD-BLACK | C6: 8 | F6: 9.5 | M6: =IF(COUNT(E6:L6)=0,"",MIN(E6:L6)) | N6: =IF(COUNT(E6:L6)=0,"",LOOKUP(2,1/(E6:L6<>""),E6:L6)) | O6: =IF(M6="","",ROUND(M6*RESUMEN!$B$4,0)) | P6: =COUNT(E6:L6) | Q6: =IF(COUNT(J6:L6)=0,"",MIN(J6:L6))
A7: 43047206256780 | B7: ANILLO LOCK GOLD-SILVER CON ZIRCONIAS | C7: 6 | D7: copper,zircon | G7: 11.8 | I7: 12.8 | J7: 12.8 | M7: =IF(COUNT(E7:L7)=0,"",MIN(E7:L7)) | N7: =IF(COUNT(E7:L7)=0,"",LOOKUP(2,1/(E7:L7<>""),E7:L7)) | O7: =IF(M7="","",ROUND(M7*RESUMEN!$B$4,0)) | P7: =COUNT(E7:L7) | Q7: =IF(COUNT(J7:L7)=0,"",MIN(J7:L7))
A8: 43047206289548 | B8: ANILLO LOCK GOLD-SILVER CON ZIRCONIAS | C8: 7 | D8: copper,zircon | F8: 12.8 | G8: 11.8 | K8: 12.8 | M8: =IF(COUNT(E8:L8)=0,"",MIN(E8:L8)) | N8: =IF(COUNT(E8:L8)=0,"",LOOKUP(2,1/(E8:L8<>""),E8:L8)) | O8: =IF(M8="","",ROUND(M8*RESUMEN!$B$4,0)) | P8: =COUNT(E8:L8) | Q8: =IF(COUNT(J8:L8)=0,"",MIN(J8:L8))
A9: 43047206682764 | B9: ANILLO LOCK ROSEGOLD-SILVER CON ZIRCONIAS | C9: 6 | D9: copper,zircon | G9: 11.8 | M9: =IF(COUNT(E9:L9)=0,"",MIN(E9:L9)) | N9: =IF(COUNT(E9:L9)=0,"",LOOKUP(2,1/(E9:L9<>""),E9:L9)) | O9: =IF(M9="","",ROUND(M9*RESUMEN!$B$4,0)) | P9: =COUNT(E9:L9) | Q9: =IF(COUNT(J9:L9)=0,"",MIN(J9:L9))
A10: 43047206748300 | B10: ANILLO LOCK ROSEGOLD-SILVER CON ZIRCONIAS | C10: 8 | D10: copper,zircon | G10: 11.8 | J10: 12.8 | M10: =IF(COUNT(E10:L10)=0,"",MIN(E10:L10)) | N10: =IF(COUNT(E10:L10)=0,"",LOOKUP(2,1/(E10:L10<>""),E10:L10)) | O10: =IF(M10="","",ROUND(M10*RESUMEN!$B$4,0)) | P10: =COUNT(E10:L10) | Q10: =IF(COUNT(J10:L10)=0,"",MIN(J10:L10))
A11: 39252671264941 | B11: ANILLO LV LETTER GOLD | C11: 7 | D11: stainless steel | F11: 5.28 | H11: 5.28 | I11: 5.28 | M11: =IF(COUNT(E11:L11)=0,"",MIN(E11:L11)) | N11: =IF(COUNT(E11:L11)=0,"",LOOKUP(2,1/(E11:L11<>""),E11:L11)) | O11: =IF(M11="","",ROUND(M11*RESUMEN!$B$4,0)) | P11: =COUNT(E11:L11) | Q11: =IF(COUNT(J11:L11)=0,"",MIN(J11:L11))
A12: 39252671397709 | B12: ANILLO LV LETTER GOLD | C12: 8 | D12: copper | F12: 5.28 | I12: 5.28 | M12: =IF(COUNT(E12:L12)=0,"",MIN(E12:L12)) | N12: =IF(COUNT(E12:L12)=0,"",LOOKUP(2,1/(E12:L12<>""),E12:L12)) | O12: =IF(M12="","",ROUND(M12*RESUMEN!$B$4,0)) | P12: =COUNT(E12:L12) | Q12: =IF(COUNT(J12:L12)=0,"",MIN(J12:L12))
A13: 39252671092621 | B13: ANILLO LV LETTER SILVER | C13: 7 | D13: stainless steel | F13: 5.28 | H13: 5.28 | M13: =IF(COUNT(E13:L13)=0,"",MIN(E13:L13)) | N13: =IF(COUNT(E13:L13)=0,"",LOOKUP(2,1/(E13:L13<>""),E13:L13)) | O13: =IF(M13="","",ROUND(M13*RESUMEN!$B$4,0)) | P13: =COUNT(E13:L13) | Q13: =IF(COUNT(J13:L13)=0,"",MIN(J13:L13))
A14: 39252671125389 | B14: ANILLO LV LETTER SILVER | C14: 8 | F14: 5.28 | M14: =IF(COUNT(E14:L14)=0,"",MIN(E14:L14)) | N14: =IF(COUNT(E14:L14)=0,"",LOOKUP(2,1/(E14:L14<>""),E14:L14)) | O14: =IF(M14="","",ROUND(M14*RESUMEN!$B$4,0)) | P14: =COUNT(E14:L14) | Q14: =IF(COUNT(J14:L14)=0,"",MIN(J14:L14))
A15: 43047228014732 | B15: ANILLO ONE T SILVER CON ZIRCONIA | C15: 6 | D15: copper | E15: 9.8 | G15: 9.8 | K15: 9.8 | M15: =IF(COUNT(E15:L15)=0,"",MIN(E15:L15)) | N15: =IF(COUNT(E15:L15)=0,"",LOOKUP(2,1/(E15:L15<>""),E15:L15)) | O15: =IF(M15="","",ROUND(M15*RESUMEN!$B$4,0)) | P15: =COUNT(E15:L15) | Q15: =IF(COUNT(J15:L15)=0,"",MIN(J15:L15))
A16: 43047228047500 | B16: ANILLO ONE T SILVER CON ZIRCONIA | C16: 7 | E16: 9.8 | M16: =IF(COUNT(E16:L16)=0,"",MIN(E16:L16)) | N16: =IF(COUNT(E16:L16)=0,"",LOOKUP(2,1/(E16:L16<>""),E16:L16)) | O16: =IF(M16="","",ROUND(M16*RESUMEN!$B$4,0)) | P16: =COUNT(E16:L16) | Q16: =IF(COUNT(J16:L16)=0,"",MIN(J16:L16))
A17: 43728112129132 | B17: ANILLO P SHINNY FLOWER | C17: 6 | D17: copper,zircon | F17: 2.6 | I17: 2.6 | M17: =IF(COUNT(E17:L17)=0,"",MIN(E17:L17)) | N17: =IF(COUNT(E17:L17)=0,"",LOOKUP(2,1/(E17:L17<>""),E17:L17)) | O17: =IF(M17="","",ROUND(M17*RESUMEN!$B$4,0)) | P17: =COUNT(E17:L17) | Q17: =IF(COUNT(J17:L17)=0,"",MIN(J17:L17))
A18: 43078594756748 | B18: ANILLO P SHINNY FLOWER | C18: 7 | D18: copper,zircon | F18: 2.6 | G18: 2.6 | L18: 2.6 | M18: =IF(COUNT(E18:L18)=0,"",MIN(E18:L18)) | N18: =IF(COUNT(E18:L18)=0,"",LOOKUP(2,1/(E18:L18<>""),E18:L18)) | O18: =IF(M18="","",ROUND(M18*RESUMEN!$B$4,0)) | P18: =COUNT(E18:L18) | Q18: =IF(COUNT(J18:L18)=0,"",MIN(J18:L18))
A19: 43078594789516 | B19: ANILLO P SHINNY FLOWER | C19: 8 | D19: copper,zircon | H19: 2.6 | I19: 2.6 | M19: =IF(COUNT(E19:L19)=0,"",MIN(E19:L19)) | N19: =IF(COUNT(E19:L19)=0,"",LOOKUP(2,1/(E19:L19<>""),E19:L19)) | O19: =IF(M19="","",ROUND(M19*RESUMEN!$B$4,0)) | P19: =COUNT(E19:L19) | Q19: =IF(COUNT(J19:L19)=0,"",MIN(J19:L19))
A20: 43728112856684 | B20: ANILLO P STARS | C20: 6 | D20: copper | I20: 1.7 | M20: =IF(COUNT(E20:L20)=0,"",MIN(E20:L20)) | N20: =IF(COUNT(E20:L20)=0,"",LOOKUP(2,1/(E20:L20<>""),E20:L20)) | O20: =IF(M20="","",ROUND(M20*RESUMEN!$B$4,0)) | P20: =COUNT(E20:L20) | Q20: =IF(COUNT(J20:L20)=0,"",MIN(J20:L20))
A21: 43071835930764 | B21: ANILLO P STARS | C21: 7 | D21: copper | I21: 1.7 | M21: =IF(COUNT(E21:L21)=0,"",MIN(E21:L21)) | N21: =IF(COUNT(E21:L21)=0,"",LOOKUP(2,1/(E21:L21<>""),E21:L21)) | O21: =IF(M21="","",ROUND(M21*RESUMEN!$B$4,0)) | P21: =COUNT(E21:L21) | Q21: =IF(COUNT(J21:L21)=0,"",MIN(J21:L21))
A22: 43071835963532 | B22: ANILLO P STARS | C22: 8 | D22: copper | H22: 1.7 | K22: 1.7 | M22: =IF(COUNT(E22:L22)=0,"",MIN(E22:L22)) | N22: =IF(COUNT(E22:L22)=0,"",LOOKUP(2,1/(E22:L22<>""),E22:L22)) | O22: =IF(M22="","",ROUND(M22*RESUMEN!$B$4,0)) | P22: =COUNT(E22:L22) | Q22: =IF(COUNT(J22:L22)=0,"",MIN(J22:L22))
A23: 81836202265453 | B23: ANILLO P STARS | C23: 9 | D23: copper | K23: 1.7 | M23: =IF(COUNT(E23:L23)=0,"",MIN(E23:L23)) | N23: =IF(COUNT(E23:L23)=0,"",LOOKUP(2,1/(E23:L23<>""),E23:L23)) | O23: =IF(M23="","",ROUND(M23*RESUMEN!$B$4,0)) | P23: =COUNT(E23:L23) | Q23: =IF(COUNT(J23:L23)=0,"",MIN(J23:L23))
A24: 43728071296588 | B24: ANILLO SERPENTI LISO GOLD | C24: XGN gold | D24: copper | F24: 6.9 | J24: 6.8 | L24: 6.9 | M24: =IF(COUNT(E24:L24)=0,"",MIN(E24:L24)) | N24: =IF(COUNT(E24:L24)=0,"",LOOKUP(2,1/(E24:L24<>""),E24:L24)) | O24: =IF(M24="","",ROUND(M24*RESUMEN!$B$4,0)) | P24: =COUNT(E24:L24) | Q24: =IF(COUNT(J24:L24)=0,"",MIN(J24:L24))
A25: 43728071182284 | B25: ANILLO SERPENTI LISO SILVER | C25: AJUSTABLE | D25: copper | I25: 6.8 | J25: 6.8 | K25: 6.8 | M25: =IF(COUNT(E25:L25)=0,"",MIN(E25:L25)) | N25: =IF(COUNT(E25:L25)=0,"",LOOKUP(2,1/(E25:L25<>""),E25:L25)) | O25: =IF(M25="","",ROUND(M25*RESUMEN!$B$4,0)) | P25: =COUNT(E25:L25) | Q25: =IF(COUNT(J25:L25)=0,"",MIN(J25:L25))
A26: 38332091054029 | B26: ANILLO T EDGE SILVER | C26: 6 | D26: copper,zircon | G26: 10.8 | K26: 10.8 | M26: =IF(COUNT(E26:L26)=0,"",MIN(E26:L26)) | N26: =IF(COUNT(E26:L26)=0,"",LOOKUP(2,1/(E26:L26<>""),E26:L26)) | O26: =IF(M26="","",ROUND(M26*RESUMEN!$B$4,0)) | P26: =COUNT(E26:L26) | Q26: =IF(COUNT(J26:L26)=0,"",MIN(J26:L26))
A27: 38332091186797 | B27: ANILLO T EDGE SILVER | C27: XGX249-004 7# | D27: copper,zircon | F27: 10.8 | G27: 10.8 | J27: 10.8 | L27: 10.8 | M27: =IF(COUNT(E27:L27)=0,"",MIN(E27:L27)) | N27: =IF(COUNT(E27:L27)=0,"",LOOKUP(2,1/(E27:L27<>""),E27:L27)) | O27: =IF(M27="","",ROUND(M27*RESUMEN!$B$4,0)) | P27: =COUNT(E27:L27) | Q27: =IF(COUNT(J27:L27)=0,"",MIN(J27:L27))
A28: 34876761335341 | B28: ANILLO T LOVESTRUCK SILVER-ROSE GOLD | C28: 6 | D28: copper | F28: 8.8 | G28: 8.8 | I28: 8.8 | J28: 8.8 | M28: =IF(COUNT(E28:L28)=0,"",MIN(E28:L28)) | N28: =IF(COUNT(E28:L28)=0,"",LOOKUP(2,1/(E28:L28<>""),E28:L28)) | O28: =IF(M28="","",ROUND(M28*RESUMEN!$B$4,0)) | P28: =COUNT(E28:L28) | Q28: =IF(COUNT(J28:L28)=0,"",MIN(J28:L28))
A29: 34876761468109 | B29: ANILLO T LOVESTRUCK SILVER-ROSE GOLD | C29: 7 | D29: copper | G29: 8.8 | J29: 8.8 | M29: =IF(COUNT(E29:L29)=0,"",MIN(E29:L29)) | N29: =IF(COUNT(E29:L29)=0,"",LOOKUP(2,1/(E29:L29<>""),E29:L29)) | O29: =IF(M29="","",ROUND(M29*RESUMEN!$B$4,0)) | P29: =COUNT(E29:L29) | Q29: =IF(COUNT(J29:L29)=0,"",MIN(J29:L29))
A30: 41648081090125 | B30: ANILLO T LOVESTRUCK SILVER-ROSE GOLD | C30: 8 | J30: 8.8 | M30: =IF(COUNT(E30:L30)=0,"",MIN(E30:L30)) | N30: =IF(COUNT(E30:L30)=0,"",LOOKUP(2,1/(E30:L30<>""),E30:L30)) | O30: =IF(M30="","",ROUND(M30*RESUMEN!$B$4,0)) | P30: =COUNT(E30:L30) | Q30: =IF(COUNT(J30:L30)=0,"",MIN(J30:L30))
A31: 41889241279949 | B31: ANILLO T V SILVER | C31: 7 | D31: copper | F31: 9.8 | I31: 9.8 | M31: =IF(COUNT(E31:L31)=0,"",MIN(E31:L31)) | N31: =IF(COUNT(E31:L31)=0,"",LOOKUP(2,1/(E31:L31<>""),E31:L31)) | O31: =IF(M31="","",ROUND(M31*RESUMEN!$B$4,0)) | P31: =COUNT(E31:L31) | Q31: =IF(COUNT(J31:L31)=0,"",MIN(J31:L31))
A32: 41889241312717 | B32: ANILLO T V SILVER | C32: 8 | D32: copper,zircon | F32: 9.8 | I32: 9.8 | M32: =IF(COUNT(E32:L32)=0,"",MIN(E32:L32)) | N32: =IF(COUNT(E32:L32)=0,"",LOOKUP(2,1/(E32:L32<>""),E32:L32)) | O32: =IF(M32="","",ROUND(M32*RESUMEN!$B$4,0)) | P32: =COUNT(E32:L32) | Q32: =IF(COUNT(J32:L32)=0,"",MIN(J32:L32))
A33: 41889241445485 | B33: ANILLO T V SILVER | C33: 9 | D33: copper,zircon | F33: 9.8 | I33: 9.8 | M33: =IF(COUNT(E33:L33)=0,"",MIN(E33:L33)) | N33: =IF(COUNT(E33:L33)=0,"",LOOKUP(2,1/(E33:L33<>""),E33:L33)) | O33: =IF(M33="","",ROUND(M33*RESUMEN!$B$4,0)) | P33: =COUNT(E33:L33) | Q33: =IF(COUNT(J33:L33)=0,"",MIN(J33:L33))
A34: 665bb4c20b268 | B34: ANILLO V GOLD | C34: AJUSTABLE | D34: copper | K34: 6.8 | M34: =IF(COUNT(E34:L34)=0,"",MIN(E34:L34)) | N34: =IF(COUNT(E34:L34)=0,"",LOOKUP(2,1/(E34:L34<>""),E34:L34)) | O34: =IF(M34="","",ROUND(M34*RESUMEN!$B$4,0)) | P34: =COUNT(E34:L34) | Q34: =IF(COUNT(J34:L34)=0,"",MIN(J34:L34))
A35: 15711172030349 | B35: ARETES BEAN GOLD T | C35: Default Title | D35: copper | E35: 8 | F35: 8 | H35: 7.5 | I35: 8 | K35: 8.8 | M35: =IF(COUNT(E35:L35)=0,"",MIN(E35:L35)) | N35: =IF(COUNT(E35:L35)=0,"",LOOKUP(2,1/(E35:L35<>""),E35:L35)) | O35: =IF(M35="","",ROUND(M35*RESUMEN!$B$4,0)) | P35: =COUNT(E35:L35) | Q35: =IF(COUNT(J35:L35)=0,"",MIN(J35:L35))
A36: 62101481140653 | B36: ARETES BEAN SILVER T | C36: Default Title | D36: copper | E36: 8 | F36: 8 | H36: 7.5 | J36: 8 | K36: 8 | M36: =IF(COUNT(E36:L36)=0,"",MIN(E36:L36)) | N36: =IF(COUNT(E36:L36)=0,"",LOOKUP(2,1/(E36:L36<>""),E36:L36)) | O36: =IF(M36="","",ROUND(M36*RESUMEN!$B$4,0)) | P36: =COUNT(E36:L36) | Q36: =IF(COUNT(J36:L36)=0,"",MIN(J36:L36))
A37: 64e78d3bae5c1 | B37: ARETES BLOSSOM STAR GOLD | D37: copper | E37: 6.8 | G37: 6.8 | M37: =IF(COUNT(E37:L37)=0,"",MIN(E37:L37)) | N37: =IF(COUNT(E37:L37)=0,"",LOOKUP(2,1/(E37:L37<>""),E37:L37)) | O37: =IF(M37="","",ROUND(M37*RESUMEN!$B$4,0)) | P37: =COUNT(E37:L37) | Q37: =IF(COUNT(J37:L37)=0,"",MIN(J37:L37))
A38: 94792221051565 | B38: ARETES BLOSSOM STAR GOLD | C38: REGULAR | D38: copper | H38: 6.8 | K38: 6.8 | L38: 6.8 | M38: =IF(COUNT(E38:L38)=0,"",MIN(E38:L38)) | N38: =IF(COUNT(E38:L38)=0,"",LOOKUP(2,1/(E38:L38<>""),E38:L38)) | O38: =IF(M38="","",ROUND(M38*RESUMEN!$B$4,0)) | P38: =COUNT(E38:L38) | Q38: =IF(COUNT(J38:L38)=0,"",MIN(J38:L38))
A39: 64e78d3baafe7 | B39: ARETES BLOSSOM STAR ROSE GOLD | C39: white flower ros | D39: copper | E39: 6.8 | G39: 6.8 | H39: 6.8 | J39: 6.8 | L39: 6.8 | M39: =IF(COUNT(E39:L39)=0,"",MIN(E39:L39)) | N39: =IF(COUNT(E39:L39)=0,"",LOOKUP(2,1/(E39:L39<>""),E39:L39)) | O39: =IF(M39="","",ROUND(M39*RESUMEN!$B$4,0)) | P39: =COUNT(E39:L39) | Q39: =IF(COUNT(J39:L39)=0,"",MIN(J39:L39))
A40: 64e78d3c1c538 | B40: ARETES BLOSSOM STAR SILVER | C40: Default Title | D40: copper | E40: 6.8 | G40: 6.8 | I40: 6.8 | J40: 6.8 | M40: =IF(COUNT(E40:L40)=0,"",MIN(E40:L40)) | N40: =IF(COUNT(E40:L40)=0,"",LOOKUP(2,1/(E40:L40<>""),E40:L40)) | O40: =IF(M40="","",ROUND(M40*RESUMEN!$B$4,0)) | P40: =COUNT(E40:L40) | Q40: =IF(COUNT(J40:L40)=0,"",MIN(J40:L40))
A41: 665bb4e06b7c8 | B41: ARETES CC DORADO | C41: Regular | D41: stainless steel | E41: 2 | F41: 2 | H41: 2 | K41: 2 | M41: =IF(COUNT(E41:L41)=0,"",MIN(E41:L41)) | N41: =IF(COUNT(E41:L41)=0,"",LOOKUP(2,1/(E41:L41<>""),E41:L41)) | O41: =IF(M41="","",ROUND(M41*RESUMEN!$B$4,0)) | P41: =COUNT(E41:L41) | Q41: =IF(COUNT(J41:L41)=0,"",MIN(J41:L41))
...

Sheet NANCY VIP
A1: HISTORIAL DE PRECIOS — NANCY VIP
A2: 7 orden(es) · costo unitario en USD · MXN = MEJOR × RESUMEN!B4 · * = dato del historial previo
A4: SKU | B4: PRODUCTO | C4: VARIANTE | D4: MATERIAL | E4: Sep 2025 06/09 | F4: Dic 2025 03/12 | G4: Mar 2026 01/03 | H4: Abr 2026 01/04 | I4: May 2026 08/05 | J4: May 2026 31/05 | K4: Jul 2026 09/07 | L4: MEJOR (US) | M4: ÚLTIMA (US) | N4: MXN (mejor×TC) | O4: # ÓRD.
A5: 42981628018828 | B5: ANILLO BLOSSOM STAR ROSEGOLD | C5: Regular | E5: 4.99 | H5: 2.3 | I5: 5.59 | L5: =IF(COUNT(E5:K5)=0,"",MIN(E5:K5)) | M5: =IF(COUNT(E5:K5)=0,"",LOOKUP(2,1/(E5:K5<>""),E5:K5)) | N5: =IF(L5="","",ROUND(L5*RESUMEN!$B$4,0)) | O5: =COUNT(E5:K5)
A6: 71036863389452 | B6: ANILLO BV CON UNA ZIRCONIA GOLD | C6: 7 | D6: stainless steel | J6: 3.99 | L6: =IF(COUNT(E6:K6)=0,"",MIN(E6:K6)) | M6: =IF(COUNT(E6:K6)=0,"",LOOKUP(2,1/(E6:K6<>""),E6:K6)) | N6: =IF(L6="","",ROUND(L6*RESUMEN!$B$4,0)) | O6: =COUNT(E6:K6)
A7: 71036863422220 | B7: ANILLO BV CON UNA ZIRCONIA GOLD | C7: 8 | I7: 3.99 | L7: =IF(COUNT(E7:K7)=0,"",MIN(E7:K7)) | M7: =IF(COUNT(E7:K7)=0,"",LOOKUP(2,1/(E7:K7<>""),E7:K7)) | N7: =IF(L7="","",ROUND(L7*RESUMEN!$B$4,0)) | O7: =COUNT(E7:K7)
A8: 62745763277677 | B8: ANILLO C CLASH ONYX | C8: 6 | D8: brass | J8: 10.89 | L8: =IF(COUNT(E8:K8)=0,"",MIN(E8:K8)) | M8: =IF(COUNT(E8:K8)=0,"",LOOKUP(2,1/(E8:K8<>""),E8:K8)) | N8: =IF(L8="","",ROUND(L8*RESUMEN!$B$4,0)) | O8: =COUNT(E8:K8)
A9: 62745763310445 | B9: ANILLO C CLASH ONYX | C9: 7 | D9: brass | J9: 10.89 | L9: =IF(COUNT(E9:K9)=0,"",MIN(E9:K9)) | M9: =IF(COUNT(E9:K9)=0,"",LOOKUP(2,1/(E9:K9<>""),E9:K9)) | N9: =IF(L9="","",ROUND(L9*RESUMEN!$B$4,0)) | O9: =COUNT(E9:K9)
A10: 58980702033101 | B10: ANILLO CC CAMELIA ROSE GOLD | C10: 6 | D10: brass | J10: 10.59 | L10: =IF(COUNT(E10:K10)=0,"",MIN(E10:K10)) | M10: =IF(COUNT(E10:K10)=0,"",LOOKUP(2,1/(E10:K10<>""),E10:K10)) | N10: =IF(L10="","",ROUND(L10*RESUMEN!$B$4,0)) | O10: =COUNT(E10:K10)
A11: 58980702165869 | B11: ANILLO CC CAMELIA ROSE GOLD | C11: 7 | D11: brass | J11: 10.59 | L11: =IF(COUNT(E11:K11)=0,"",MIN(E11:K11)) | M11: =IF(COUNT(E11:K11)=0,"",LOOKUP(2,1/(E11:K11<>""),E11:K11)) | N11: =IF(L11="","",ROUND(L11*RESUMEN!$B$4,0)) | O11: =COUNT(E11:K11)
A12: 58980701834797 | B12: ANILLO CC COCO SLIM SILVER | C12: 6 | D12: brass | J12: 7.39 | L12: =IF(COUNT(E12:K12)=0,"",MIN(E12:K12)) | M12: =IF(COUNT(E12:K12)=0,"",LOOKUP(2,1/(E12:K12<>""),E12:K12)) | N12: =IF(L12="","",ROUND(L12*RESUMEN!$B$4,0)) | O12: =COUNT(E12:K12)
A13: 58980701967565 | B13: ANILLO CC COCO SLIM SILVER | C13: 7 | D13: brass | J13: 7.39 | L13: =IF(COUNT(E13:K13)=0,"",MIN(E13:K13)) | M13: =IF(COUNT(E13:K13)=0,"",LOOKUP(2,1/(E13:K13<>""),E13:K13)) | N13: =IF(L13="","",ROUND(L13*RESUMEN!$B$4,0)) | O13: =COUNT(E13:K13)
A14: 58980701641581 | B14: ANILLO CC COCO ZIRCONIA GOLD | C14: Default Title | D14: brass | J14: 6.69 | L14: =IF(COUNT(E14:K14)=0,"",MIN(E14:K14)) | M14: =IF(COUNT(E14:K14)=0,"",LOOKUP(2,1/(E14:K14<>""),E14:K14)) | N14: =IF(L14="","",ROUND(L14*RESUMEN!$B$4,0)) | O14: =COUNT(E14:K14)
A15: 58980701543277 | B15: ANILLO CC COCO ZIRCONIA ROSE GOLD | C15: Default Title | D15: brass | J15: 6.69 | L15: =IF(COUNT(E15:K15)=0,"",MIN(E15:K15)) | M15: =IF(COUNT(E15:K15)=0,"",LOOKUP(2,1/(E15:K15<>""),E15:K15)) | N15: =IF(L15="","",ROUND(L15*RESUMEN!$B$4,0)) | O15: =COUNT(E15:K15)
A16: 58980701738189 | B16: ANILLO CC COCO ZIRCONIA SILVER | C16: Default Title | D16: brass | J16: 6.69 | L16: =IF(COUNT(E16:K16)=0,"",MIN(E16:K16)) | M16: =IF(COUNT(E16:K16)=0,"",LOOKUP(2,1/(E16:K16<>""),E16:K16)) | N16: =IF(L16="","",ROUND(L16*RESUMEN!$B$4,0)) | O16: =COUNT(E16:K16)
A17: 58980702231405 | B17: ANILLO CC ETERNAL N5 | C17: 6 | D17: brass | J17: 6.69 | L17: =IF(COUNT(E17:K17)=0,"",MIN(E17:K17)) | M17: =IF(COUNT(E17:K17)=0,"",LOOKUP(2,1/(E17:K17<>""),E17:K17)) | N17: =IF(L17="","",ROUND(L17*RESUMEN!$B$4,0)) | O17: =COUNT(E17:K17)
A18: 58980702364173 | B18: ANILLO CC ETERNAL N5 | C18: 7 | D18: brass | J18: 6.69 | L18: =IF(COUNT(E18:K18)=0,"",MIN(E18:K18)) | M18: =IF(COUNT(E18:K18)=0,"",LOOKUP(2,1/(E18:K18<>""),E18:K18)) | N18: =IF(L18="","",ROUND(L18*RESUMEN!$B$4,0)) | O18: =COUNT(E18:K18)
A19: 80464311068525 | B19: ANILLO CD REVOLUTION | C19: 6 | D19: brass | H19: 2.8 | J19: 4.99 | L19: =IF(COUNT(E19:K19)=0,"",MIN(E19:K19)) | M19: =IF(COUNT(E19:K19)=0,"",LOOKUP(2,1/(E19:K19<>""),E19:K19)) | N19: =IF(L19="","",ROUND(L19*RESUMEN!$B$4,0)) | O19: =COUNT(E19:K19)
A20: 42951547486348 | B20: ANILLO CD REVOLUTION | C20: 8 | E20: 3.49 | I20: 5.59 | L20: =IF(COUNT(E20:K20)=0,"",MIN(E20:K20)) | M20: =IF(COUNT(E20:K20)=0,"",LOOKUP(2,1/(E20:K20<>""),E20:K20)) | N20: =IF(L20="","",ROUND(L20*RESUMEN!$B$4,0)) | O20: =COUNT(E20:K20)
A21: 56481462558348 | B21: ANILLO ECROU SILVER | C21: 6 | D21: brass | J21: 3.29 | L21: =IF(COUNT(E21:K21)=0,"",MIN(E21:K21)) | M21: =IF(COUNT(E21:K21)=0,"",LOOKUP(2,1/(E21:K21<>""),E21:K21)) | N21: =IF(L21="","",ROUND(L21*RESUMEN!$B$4,0)) | O21: =COUNT(E21:K21)
A22: 56481462591116 | B22: ANILLO ECROU SILVER | C22: 7 | D22: brass | G22: 3.29 | H22: 3.29 | L22: =IF(COUNT(E22:K22)=0,"",MIN(E22:K22)) | M22: =IF(COUNT(E22:K22)=0,"",LOOKUP(2,1/(E22:K22<>""),E22:K22)) | N22: =IF(L22="","",ROUND(L22*RESUMEN!$B$4,0)) | O22: =COUNT(E22:K22)
A23: 56481462623884 | B23: ANILLO ECROU SILVER | C23: 8 | D23: brass | F23: 3.29 | H23: 3.29 | L23: =IF(COUNT(E23:K23)=0,"",MIN(E23:K23)) | M23: =IF(COUNT(E23:K23)=0,"",LOOKUP(2,1/(E23:K23<>""),E23:K23)) | N23: =IF(L23="","",ROUND(L23*RESUMEN!$B$4,0)) | O23: =COUNT(E23:K23)
A24: 42981601575052 | B24: ANILLO ESSENTIAL V PERLE | C24: Default Title | E24: 4.99 | K24: 5.59 | L24: =IF(COUNT(E24:K24)=0,"",MIN(E24:K24)) | M24: =IF(COUNT(E24:K24)=0,"",LOOKUP(2,1/(E24:K24<>""),E24:K24)) | N24: =IF(L24="","",ROUND(L24*RESUMEN!$B$4,0)) | O24: =COUNT(E24:K24)
A25: 66593a9c168cf | B25: ANILLO KNOT GOLD | C25: 6 | D25: brass | F25: 5.99 | G25: 5.59 | H25: 5.59 | I25: 5.59 | K25: 4.99 | L25: =IF(COUNT(E25:K25)=0,"",MIN(E25:K25)) | M25: =IF(COUNT(E25:K25)=0,"",LOOKUP(2,1/(E25:K25<>""),E25:K25)) | N25: =IF(L25="","",ROUND(L25*RESUMEN!$B$4,0)) | O25: =COUNT(E25:K25)
A26: 66593a9cc1aaa | B26: ANILLO KNOT GOLD | C26: 7 | D26: brass | F26: 0 | G26: 5.59 | H26: 5.59 | I26: 5.59 | J26: 5.59 | L26: =IF(COUNT(E26:K26)=0,"",MIN(E26:K26)) | M26: =IF(COUNT(E26:K26)=0,"",LOOKUP(2,1/(E26:K26<>""),E26:K26)) | N26: =IF(L26="","",ROUND(L26*RESUMEN!$B$4,0)) | O26: =COUNT(E26:K26)
A27: 2653027325964 | B27: ANILLO KNOT GOLD | C27: 8 | G27: 5.59 | I27: 5.59 | K27: 4.99 | L27: =IF(COUNT(E27:K27)=0,"",MIN(E27:K27)) | M27: =IF(COUNT(E27:K27)=0,"",LOOKUP(2,1/(E27:K27<>""),E27:K27)) | N27: =IF(L27="","",ROUND(L27*RESUMEN!$B$4,0)) | O27: =COUNT(E27:K27)
A28: 62745761965261 | B28: ANILLO LOVE GOLD CON MICROZIRCONIAS Y ZIRCONIAS | C28: 6 | D28: stainless steel | J28: 5.99 | L28: =IF(COUNT(E28:K28)=0,"",MIN(E28:K28)) | M28: =IF(COUNT(E28:K28)=0,"",LOOKUP(2,1/(E28:K28<>""),E28:K28)) | N28: =IF(L28="","",ROUND(L28*RESUMEN!$B$4,0)) | O28: =COUNT(E28:K28)
A29: 62745762098029 | B29: ANILLO LOVE GOLD CON MICROZIRCONIAS Y ZIRCONIAS | C29: 7 | D29: stainless steel | J29: 5.99 | L29: =IF(COUNT(E29:K29)=0,"",MIN(E29:K29)) | M29: =IF(COUNT(E29:K29)=0,"",LOOKUP(2,1/(E29:K29<>""),E29:K29)) | N29: =IF(L29="","",ROUND(L29*RESUMEN!$B$4,0)) | O29: =COUNT(E29:K29)
A30: 62745762555085 | B30: ANILLO LOVE ROSE GOLD CON MICROZIRCONIAS | C30: 6 | D30: stainless steel | J30: 5.39 | L30: =IF(COUNT(E30:K30)=0,"",MIN(E30:K30)) | M30: =IF(COUNT(E30:K30)=0,"",LOOKUP(2,1/(E30:K30<>""),E30:K30)) | N30: =IF(L30="","",ROUND(L30*RESUMEN!$B$4,0)) | O30: =COUNT(E30:K30)
A31: 62745762687853 | B31: ANILLO LOVE ROSE GOLD CON MICROZIRCONIAS | C31: 7 | D31: stainless steel | J31: 5.39 | L31: =IF(COUNT(E31:K31)=0,"",MIN(E31:K31)) | M31: =IF(COUNT(E31:K31)=0,"",LOOKUP(2,1/(E31:K31<>""),E31:K31)) | N31: =IF(L31="","",ROUND(L31*RESUMEN!$B$4,0)) | O31: =COUNT(E31:K31)
A32: 62745762125709 | B32: ANILLO LOVE ROSE GOLD CON MICROZIRCONIAS Y ZIRCONIAS | C32: 6 | D32: stainless steel | J32: 5.99 | L32: =IF(COUNT(E32:K32)=0,"",MIN(E32:K32)) | M32: =IF(COUNT(E32:K32)=0,"",LOOKUP(2,1/(E32:K32<>""),E32:K32)) | N32: =IF(L32="","",ROUND(L32*RESUMEN!$B$4,0)) | O32: =COUNT(E32:K32)
A33: 62745762258477 | B33: ANILLO LOVE ROSE GOLD CON MICROZIRCONIAS Y ZIRCONIAS | C33: 7 | D33: stainless steel | J33: 5.99 | L33: =IF(COUNT(E33:K33)=0,"",MIN(E33:K33)) | M33: =IF(COUNT(E33:K33)=0,"",LOOKUP(2,1/(E33:K33<>""),E33:K33)) | N33: =IF(L33="","",ROUND(L33*RESUMEN!$B$4,0)) | O33: =COUNT(E33:K33)
A34: 62745762329101 | B34: ANILLO LOVE SILVER CON MICROZIRCONIAS Y ZIRCONIAS | C34: 6 | D34: stainless steel | J34: 5.99 | L34: =IF(COUNT(E34:K34)=0,"",MIN(E34:K34)) | M34: =IF(COUNT(E34:K34)=0,"",LOOKUP(2,1/(E34:K34<>""),E34:K34)) | N34: =IF(L34="","",ROUND(L34*RESUMEN!$B$4,0)) | O34: =COUNT(E34:K34)
A35: 62745762461869 | B35: ANILLO LOVE SILVER CON MICROZIRCONIAS Y ZIRCONIAS | C35: 7 | D35: stainless steel | J35: 5.99 | L35: =IF(COUNT(E35:K35)=0,"",MIN(E35:K35)) | M35: =IF(COUNT(E35:K35)=0,"",LOOKUP(2,1/(E35:K35<>""),E35:K35)) | N35: =IF(L35="","",ROUND(L35*RESUMEN!$B$4,0)) | O35: =COUNT(E35:K35)
A36: 42981580832908 | B36: ANILLO LV VOLT MULTI | C36: Default Title | G36: 5.59 | L36: =IF(COUNT(E36:K36)=0,"",MIN(E36:K36)) | M36: =IF(COUNT(E36:K36)=0,"",LOOKUP(2,1/(E36:K36<>""),E36:K36)) | N36: =IF(L36="","",ROUND(L36*RESUMEN!$B$4,0)) | O36: =COUNT(E36:K36)
A37: 42981773246604 | B37: ANILLO PANTHERE GOLD | C37: Regular | D37: brass | F37: 5.59 | G37: 5.59 | J37: 5.59 | K37: 7.29 | L37: =IF(COUNT(E37:K37)=0,"",MIN(E37:K37)) | M37: =IF(COUNT(E37:K37)=0,"",LOOKUP(2,1/(E37:K37<>""),E37:K37)) | N37: =IF(L37="","",ROUND(L37*RESUMEN!$B$4,0)) | O37: =COUNT(E37:K37)
A38: 42981806637196 | B38: ANILLO PANTHERE SILVER | C38: Default Title | D38: brass | H38: 5.59 | I38: 5.59 | L38: =IF(COUNT(E38:K38)=0,"",MIN(E38:K38)) | M38: =IF(COUNT(E38:K38)=0,"",LOOKUP(2,1/(E38:K38<>""),E38:K38)) | N38: =IF(L38="","",ROUND(L38*RESUMEN!$B$4,0)) | O38: =COUNT(E38:K38)
A39: 66593bd6d7885 | B39: ANILLO PERLEE GOLD | C39: 6 | I39: 5.59 | L39: =IF(COUNT(E39:K39)=0,"",MIN(E39:K39)) | M39: =IF(COUNT(E39:K39)=0,"",LOOKUP(2,1/(E39:K39<>""),E39:K39)) | N39: =IF(L39="","",ROUND(L39*RESUMEN!$B$4,0)) | O39: =COUNT(E39:K39)
A40: 66593bd77de70 | B40: ANILLO PERLEE GOLD | C40: 7 | D40: brass | G40: 5.59 | H40: 5.59 | L40: =IF(COUNT(E40:K40)=0,"",MIN(E40:K40)) | M40: =IF(COUNT(E40:K40)=0,"",LOOKUP(2,1/(E40:K40<>""),E40:K40)) | N40: =IF(L40="","",ROUND(L40*RESUMEN!$B$4,0)) | O40: =COUNT(E40:K40)
A41: 66593be00cc70 | B41: ANILLO PERLEE ROSEGOLD | C41: 7 | F41: 5.59 | I41: 5.59 | L41: =IF(COUNT(E41:K41)=0,"",MIN(E41:K41)) | M41: =IF(COUNT(E41:K41)=0,"",LOOKUP(2,1/(E41:K41<>""),E41:K41)) | N41: =IF(L41="","",ROUND(L41*RESUMEN!$B$4,0)) | O41: =COUNT(E41:K41)
...

Sheet DINA DU
A1: HISTORIAL DE PRECIOS — DINA DU
A2: 5 orden(es) · costo unitario en USD · MXN = MEJOR × RESUMEN!B4 · * = dato del historial previo
A4: SKU | B4: PRODUCTO | C4: VARIANTE | D4: MATERIAL | E4: Dic 2024 ord.1046* | F4: Ene 2025 ord.1046* | G4: Oct 2025 21/10 | H4: Feb 2026 06/02 | I4: Abr 2026 27/04 | J4: MEJOR (US) | K4: ÚLTIMA (US) | L4: MXN (mejor×TC) | M4: # ÓRD.
A5: ⚠️ 17 | B5: 2-M | F5: 16 | J5: =IF(COUNT(E5:I5)=0,"",MIN(E5:I5)) | K5: =IF(COUNT(E5:I5)=0,"",LOOKUP(2,1/(E5:I5<>""),E5:I5)) | L5: =IF(J5="","",ROUND(J5*RESUMEN!$B$4,0)) | M5: =COUNT(E5:I5)
A6: 66593bcfaca6f | B6: ANILLO MM | C6: AJUSTABLE | H6: 2.79 | I6: 2.79 | J6: =IF(COUNT(E6:I6)=0,"",MIN(E6:I6)) | K6: =IF(COUNT(E6:I6)=0,"",LOOKUP(2,1/(E6:I6<>""),E6:I6)) | L6: =IF(J6="","",ROUND(J6*RESUMEN!$B$4,0)) | M6: =COUNT(E6:I6)
A7: 648cc5b58feaa | B7: ARETES MM COLGANTE | C7: Default Title | D7: stianless steel | G7: 2.39 | I7: 2.39 | J7: =IF(COUNT(E7:I7)=0,"",MIN(E7:I7)) | K7: =IF(COUNT(E7:I7)=0,"",LOOKUP(2,1/(E7:I7<>""),E7:I7)) | L7: =IF(J7="","",ROUND(J7*RESUMEN!$B$4,0)) | M7: =COUNT(E7:I7)
A8: 654bdbdb26372 | B8: BOLSA CC WHITE | C8: 17cmx24cm | I8: 18 | J8: =IF(COUNT(E8:I8)=0,"",MIN(E8:I8)) | K8: =IF(COUNT(E8:I8)=0,"",LOOKUP(2,1/(E8:I8<>""),E8:I8)) | L8: =IF(J8="","",ROUND(J8*RESUMEN!$B$4,0)) | M8: =COUNT(E8:I8)
A9: 94956736687244 | B9: BOLSA MINI POCHETTE LV | C9: 9cm de alto x 15cm de largo x 3cm de ancho | H9: 22 | I9: 22 | J9: =IF(COUNT(E9:I9)=0,"",MIN(E9:I9)) | K9: =IF(COUNT(E9:I9)=0,"",LOOKUP(2,1/(E9:I9<>""),E9:I9)) | L9: =IF(J9="","",ROUND(J9*RESUMEN!$B$4,0)) | M9: =COUNT(E9:I9)
A10: 43124008910988 | B10: BOLSO C CLAUDE | C10: 13.5cm de alto x 22cm de largo x 5cm de ancho | D10: Lambskin leather | G10: 45 | H10: 45 | J10: =IF(COUNT(E10:I10)=0,"",MIN(E10:I10)) | K10: =IF(COUNT(E10:I10)=0,"",LOOKUP(2,1/(E10:I10<>""),E10:I10)) | L10: =IF(J10="","",ROUND(J10*RESUMEN!$B$4,0)) | M10: =COUNT(E10:I10)
A11: 85367152250157 | B11: BOLSO C NINO BLACK | C11: BLACK/GOLD | H11: 45 | J11: =IF(COUNT(E11:I11)=0,"",MIN(E11:I11)) | K11: =IF(COUNT(E11:I11)=0,"",LOOKUP(2,1/(E11:I11<>""),E11:I11)) | L11: =IF(J11="","",ROUND(J11*RESUMEN!$B$4,0)) | M11: =COUNT(E11:I11)
