Workbook

Sheet COSTO PROMEDIO x SKU
A1: SKU | B1: PRODUCTO | C1: VARIANTE | D1: PROVEEDOR(ES) | E1: No. DE COMPRAS | F1: PIEZAS COMPRADAS | G1: PRIMERA COMPRA | H1: ÚLTIMA COMPRA | I1: COSTO PROMEDIO PONDERADO (MXN) | J1: COSTO PROMEDIO SIMPLE (MXN) | K1: COSTO MÍNIMO | L1: COSTO MÁXIMO | M1: ÚLTIMO COSTO | N1: VARIACIÓN 1er vs ÚLTIMO | O1: ROAS 3 SUGERIDO | P1: ROAS 3.5 SUGERIDO | Q1: ROAS 4 SUGERIDO | R1: PRECIO EN SHOPIFY HOY | S1: STOCK HOY | T1: ESTATUS SHOPIFY | U1: ROAS REAL HOY | V1: SEMÁFORO
A2: 10065591041229 | B2: TRAJE DE BAÑO COMPLETO TRIOMPHE | C2: M | D2: ZOEY | E2: =COUNTIF('DETALLE CRONOLÓGICO'!$A$2:$A$4919,$A2) | F2: =SUMIFS('DETALLE CRONOLÓGICO'!$I$2:$I$4919,'DETALLE CRONOLÓGICO'!$A$2:$A$4919,$A2) | G2: =INDEX('DETALLE CRONOLÓGICO'!$D$2:$D$4919,MATCH($A2,'DETALLE CRONOLÓGICO'!$A$2:$A$4919,0)) | H2: =INDEX('DETALLE CRONOLÓGICO'!$D$2:$D$4919,MATCH($A2,'DETALLE CRONOLÓGICO'!$A$2:$A$4919,0)+$E2-1) | I2: =IFERROR(SUMIFS('DETALLE CRONOLÓGICO'!$L$2:$L$4919,'DETALLE CRONOLÓGICO'!$A$2:$A$4919,$A2)/$F2,"") | J2: =IFERROR(SUMIFS('DETALLE CRONOLÓGICO'!$K$2:$K$4919,'DETALLE CRONOLÓGICO'!$A$2:$A$4919,$A2)/$E2,"") | K2: =_xlfn.MINIFS('DETALLE CRONOLÓGICO'!$K$2:$K$4919,'DETALLE CRONOLÓGICO'!$A$2:$A$4919,$A2) | L2: =_xlfn.MAXIFS('DETALLE CRONOLÓGICO'!$K$2:$K$4919,'DETALLE CRONOLÓGICO'!$A$2:$A$4919,$A2) | M2: =INDEX('DETALLE CRONOLÓGICO'!$K$2:$K$4919,MATCH($A2,'DETALLE CRONOLÓGICO'!$A$2:$A$4919,0)+$E2-1) | N2: =IFERROR($M2/INDEX('DETALLE CRONOLÓGICO'!$K$2:$K$4919,MATCH($A2,'DETALLE CRONOLÓGICO'!$A$2:$A$4919,0))-1,"") | O2: =IFERROR($I2*3,"") | P2: =IFERROR($I2*3.5,"") | Q2: =IFERROR($I2*4,"") | R2: 2499 | S2: 3 | T2: active | V2: SIN PRECIO
A3: 10065591106765 | B3: TRAJE DE BAÑO C TRIOMPHE ALL BLACK | C3: M | D3: ZOEY | E3: =COUNTIF('DETALLE CRONOLÓGICO'!$A$2:$A$4919,$A3) | F3: =SUMIFS('DETALLE CRONOLÓGICO'!$I$2:$I$4919,'DETALLE CRONOLÓGICO'!$A$2:$A$4919,$A3) | G3: =INDEX('DETALLE CRONOLÓGICO'!$D$2:$D$4919,MATCH($A3,'DETALLE CRONOLÓGICO'!$A$2:$A$4919,0)) | H3: =INDEX('DETALLE CRONOLÓGICO'!$D$2:$D$4919,MATCH($A3,'DETALLE CRONOLÓGICO'!$A$2:$A$4919,0)+$E3-1) | I3: =IFERROR(SUMIFS('DETALLE CRONOLÓGICO'!$L$2:$L$4919,'DETALLE CRONOLÓGICO'!$A$2:$A$4919,$A3)/$F3,"") | J3: =IFERROR(SUMIFS('DETALLE CRONOLÓGICO'!$K$2:$K$4919,'DETALLE CRONOLÓGICO'!$A$2:$A$4919,$A3)/$E3,"") | K3: =_xlfn.MINIFS('DETALLE CRONOLÓGICO'!$K$2:$K$4919,'DETALLE CRONOLÓGICO'!$A$2:$A$4919,$A3) | L3: =_xlfn.MAXIFS('DETALLE CRONOLÓGICO'!$K$2:$K$4919,'DETALLE CRONOLÓGICO'!$A$2:$A$4919,$A3) | M3: =INDEX('DETALLE CRONOLÓGICO'!$K$2:$K$4919,MATCH($A3,'DETALLE CRONOLÓGICO'!$A$2:$A$4919,0)+$E3-1) | N3: =IFERROR($M3/INDEX('DETALLE CRONOLÓGICO'!$K$2:$K$4919,MATCH($A3,'DETALLE CRONOLÓGICO'!$A$2:$A$4919,0))-1,"") | O3: =IFERROR($I3*3,"") | P3: =IFERROR($I3*3.5,"") | Q3: =IFERROR($I3*4,"") | R3: 2579 | S3: 2 | T3: active | V3: SIN PRECIO
A4: 10065591251949 | B4: TRAJE DE BAÑO GC PINK | C4: M | D4: ZOEY | E4: =COUNTIF('DETALLE CRONOLÓGICO'!$A$2:$A$4919,$A4) | F4: =SUMIFS('DETALLE CRONOLÓGICO'!$I$2:$I$4919,'DETALLE CRONOLÓGICO'!$A$2:$A$4919,$A4) | G4: =INDEX('DETALLE CRONOLÓGICO'!$D$2:$D$4919,MATCH($A4,'DETALLE CRONOLÓGICO'!$A$2:$A$4919,0)) | H4: =INDEX('DETALLE CRONOLÓGICO'!$D$2:$D$4919,MATCH($A4,'DETALLE CRONOLÓGICO'!$A$2:$A$4919,0)+$E4-1) | I4: =IFERROR(SUMIFS('DETALLE CRONOLÓGICO'!$L$2:$L$4919,'DETALLE CRONOLÓGICO'!$A$2:$A$4919,$A4)/$F4,"") | J4: =IFERROR(SUMIFS('DETALLE CRONOLÓGICO'!$K$2:$K$4919,'DETALLE CRONOLÓGICO'!$A$2:$A$4919,$A4)/$E4,"") | K4: =_xlfn.MINIFS('DETALLE CRONOLÓGICO'!$K$2:$K$4919,'DETALLE CRONOLÓGICO'!$A$2:$A$4919,$A4) | L4: =_xlfn.MAXIFS('DETALLE CRONOLÓGICO'!$K$2:$K$4919,'DETALLE CRONOLÓGICO'!$A$2:$A$4919,$A4) | M4: =INDEX('DETALLE CRONOLÓGICO'!$K$2:$K$4919,MATCH($A4,'DETALLE CRONOLÓGICO'!$A$2:$A$4919,0)+$E4-1) | N4: =IFERROR($M4/INDEX('DETALLE CRONOLÓGICO'!$K$2:$K$4919,MATCH($A4,'DETALLE CRONOLÓGICO'!$A$2:$A$4919,0))-1,"") | O4: =IFERROR($I4*3,"") | P4: =IFERROR($I4*3.5,"") | Q4: =IFERROR($I4*4,"") | R4: 2579 | S4: 2 | T4: active | V4: SIN PRECIO
A5: 10065591348557 | B5: TRAJE DE BAÑO COMPLETO CD | C5: M | D5: ZOEY | E5: =COUNTIF('DETALLE CRONOLÓGICO'!$A$2:$A$4919,$A5) | F5: =SUMIFS('DETALLE CRONOLÓGICO'!$I$2:$I$4919,'DETALLE CRONOLÓGICO'!$A$2:$A$4919,$A5) | G5: =INDEX('DETALLE CRONOLÓGICO'!$D$2:$D$4919,MATCH($A5,'DETALLE CRONOLÓGICO'!$A$2:$A$4919,0)) | H5: =INDEX('DETALLE CRONOLÓGICO'!$D$2:$D$4919,MATCH($A5,'DETALLE CRONOLÓGICO'!$A$2:$A$4919,0)+$E5-1) | I5: =IFERROR(SUMIFS('DETALLE CRONOLÓGICO'!$L$2:$L$4919,'DETALLE CRONOLÓGICO'!$A$2:$A$4919,$A5)/$F5,"") | J5: =IFERROR(SUMIFS('DETALLE CRONOLÓGICO'!$K$2:$K$4919,'DETALLE CRONOLÓGICO'!$A$2:$A$4919,$A5)/$E5,"") | K5: =_xlfn.MINIFS('DETALLE CRONOLÓGICO'!$K$2:$K$4919,'DETALLE CRONOLÓGICO'!$A$2:$A$4919,$A5) | L5: =_xlfn.MAXIFS('DETALLE CRONOLÓGICO'!$K$2:$K$4919,'DETALLE CRONOLÓGICO'!$A$2:$A$4919,$A5) | M5: =INDEX('DETALLE CRONOLÓGICO'!$K$2:$K$4919,MATCH($A5,'DETALLE CRONOLÓGICO'!$A$2:$A$4919,0)+$E5-1) | N5: =IFERROR($M5/INDEX('DETALLE CRONOLÓGICO'!$K$2:$K$4919,MATCH($A5,'DETALLE CRONOLÓGICO'!$A$2:$A$4919,0))-1,"") | O5: =IFERROR($I5*3,"") | P5: =IFERROR($I5*3.5,"") | Q5: =IFERROR($I5*4,"") | R5: 2579 | S5: 0 | T5: active | V5: SIN PRECIO
A6: 10132411046285 | B6: SANDALIAS CD DIORACT BLACK | C6: 38/25mx | D6: DINA DU | E6: =COUNTIF('DETALLE CRONOLÓGICO'!$A$2:$A$4919,$A6) | F6: =SUMIFS('DETALLE CRONOLÓGICO'!$I$2:$I$4919,'DETALLE CRONOLÓGICO'!$A$2:$A$4919,$A6) | G6: =INDEX('DETALLE CRONOLÓGICO'!$D$2:$D$4919,MATCH($A6,'DETALLE CRONOLÓGICO'!$A$2:$A$4919,0)) | H6: =INDEX('DETALLE CRONOLÓGICO'!$D$2:$D$4919,MATCH($A6,'DETALLE CRONOLÓGICO'!$A$2:$A$4919,0)+$E6-1) | I6: =IFERROR(SUMIFS('DETALLE CRONOLÓGICO'!$L$2:$L$4919,'DETALLE CRONOLÓGICO'!$A$2:$A$4919,$A6)/$F6,"") | J6: =IFERROR(SUMIFS('DETALLE CRONOLÓGICO'!$K$2:$K$4919,'DETALLE CRONOLÓGICO'!$A$2:$A$4919,$A6)/$E6,"") | K6: =_xlfn.MINIFS('DETALLE CRONOLÓGICO'!$K$2:$K$4919,'DETALLE CRONOLÓGICO'!$A$2:$A$4919,$A6) | L6: =_xlfn.MAXIFS('DETALLE CRONOLÓGICO'!$K$2:$K$4919,'DETALLE CRONOLÓGICO'!$A$2:$A$4919,$A6) | M6: =INDEX('DETALLE CRONOLÓGICO'!$K$2:$K$4919,MATCH($A6,'DETALLE CRONOLÓGICO'!$A$2:$A$4919,0)+$E6-1) | N6: =IFERROR($M6/INDEX('DETALLE CRONOLÓGICO'!$K$2:$K$4919,MATCH($A6,'DETALLE CRONOLÓGICO'!$A$2:$A$4919,0))-1,"") | O6: =IFERROR($I6*3,"") | P6: =IFERROR($I6*3.5,"") | Q6: =IFERROR($I6*4,"") | R6: 3789 | S6: 0 | T6: active | V6: SIN PRECIO
A7: 10132411116909 | B7: BOLSO CD SADDLE ALL BLACK | C7: Default Title | D7: DINA DU | E7: =COUNTIF('DETALLE CRONOLÓGICO'!$A$2:$A$4919,$A7) | F7: =SUMIFS('DETALLE CRONOLÓGICO'!$I$2:$I$4919,'DETALLE CRONOLÓGICO'!$A$2:$A$4919,$A7) | G7: =INDEX('DETALLE CRONOLÓGICO'!$D$2:$D$4919,MATCH($A7,'DETALLE CRONOLÓGICO'!$A$2:$A$4919,0)) | H7: =INDEX('DETALLE CRONOLÓGICO'!$D$2:$D$4919,MATCH($A7,'DETALLE CRONOLÓGICO'!$A$2:$A$4919,0)+$E7-1) | I7: =IFERROR(SUMIFS('DETALLE CRONOLÓGICO'!$L$2:$L$4919,'DETALLE CRONOLÓGICO'!$A$2:$A$4919,$A7)/$F7,"") | J7: =IFERROR(SUMIFS('DETALLE CRONOLÓGICO'!$K$2:$K$4919,'DETALLE CRONOLÓGICO'!$A$2:$A$4919,$A7)/$E7,"") | K7: =_xlfn.MINIFS('DETALLE CRONOLÓGICO'!$K$2:$K$4919,'DETALLE CRONOLÓGICO'!$A$2:$A$4919,$A7) | L7: =_xlfn.MAXIFS('DETALLE CRONOLÓGICO'!$K$2:$K$4919,'DETALLE CRONOLÓGICO'!$A$2:$A$4919,$A7) | M7: =INDEX('DETALLE CRONOLÓGICO'!$K$2:$K$4919,MATCH($A7,'DETALLE CRONOLÓGICO'!$A$2:$A$4919,0)+$E7-1) | N7: =IFERROR($M7/INDEX('DETALLE CRONOLÓGICO'!$K$2:$K$4919,MATCH($A7,'DETALLE CRONOLÓGICO'!$A$2:$A$4919,0))-1,"") | O7: =IFERROR($I7*3,"") | P7: =IFERROR($I7*3.5,"") | Q7: =IFERROR($I7*4,"") | R7: 5999 | S7: 1 | T7: active | V7: SIN PRECIO
A8: 10132411251373 | B8: BOLSO CD BOW BURGUNDY | C8: Default Title | D8: DINA DU | E8: =COUNTIF('DETALLE CRONOLÓGICO'!$A$2:$A$4919,$A8) | F8: =SUMIFS('DETALLE CRONOLÓGICO'!$I$2:$I$4919,'DETALLE CRONOLÓGICO'!$A$2:$A$4919,$A8) | G8: =INDEX('DETALLE CRONOLÓGICO'!$D$2:$D$4919,MATCH($A8,'DETALLE CRONOLÓGICO'!$A$2:$A$4919,0)) | H8: =INDEX('DETALLE CRONOLÓGICO'!$D$2:$D$4919,MATCH($A8,'DETALLE CRONOLÓGICO'!$A$2:$A$4919,0)+$E8-1) | I8: =IFERROR(SUMIFS('DETALLE CRONOLÓGICO'!$L$2:$L$4919,'DETALLE CRONOLÓGICO'!$A$2:$A$4919,$A8)/$F8,"") | J8: =IFERROR(SUMIFS('DETALLE CRONOLÓGICO'!$K$2:$K$4919,'DETALLE CRONOLÓGICO'!$A$2:$A$4919,$A8)/$E8,"") | K8: =_xlfn.MINIFS('DETALLE CRONOLÓGICO'!$K$2:$K$4919,'DETALLE CRONOLÓGICO'!$A$2:$A$4919,$A8) | L8: =_xlfn.MAXIFS('DETALLE CRONOLÓGICO'!$K$2:$K$4919,'DETALLE CRONOLÓGICO'!$A$2:$A$4919,$A8) | M8: =INDEX('DETALLE CRONOLÓGICO'!$K$2:$K$4919,MATCH($A8,'DETALLE CRONOLÓGICO'!$A$2:$A$4919,0)+$E8-1) | N8: =IFERROR($M8/INDEX('DETALLE CRONOLÓGICO'!$K$2:$K$4919,MATCH($A8,'DETALLE CRONOLÓGICO'!$A$2:$A$4919,0))-1,"") | O8: =IFERROR($I8*3,"") | P8: =IFERROR($I8*3.5,"") | Q8: =IFERROR($I8*4,"") | R8: 6720.51 | S8: 1 | T8: active | V8: SIN PRECIO
A9: 10132411318605 | B9: BOLSO CD BOW BLACK | C9: Default Title | D9: DINA DU | E9: =COUNTIF('DETALLE CRONOLÓGICO'!$A$2:$A$4919,$A9) | F9: =SUMIFS('DETALLE CRONOLÓGICO'!$I$2:$I$4919,'DETALLE CRONOLÓGICO'!$A$2:$A$4919,$A9) | G9: =INDEX('DETALLE CRONOLÓGICO'!$D$2:$D$4919,MATCH($A9,'DETALLE CRONOLÓGICO'!$A$2:$A$4919,0)) | H9: =INDEX('DETALLE CRONOLÓGICO'!$D$2:$D$4919,MATCH($A9,'DETALLE CRONOLÓGICO'!$A$2:$A$4919,0)+$E9-1) | I9: =IFERROR(SUMIFS('DETALLE CRONOLÓGICO'!$L$2:$L$4919,'DETALLE CRONOLÓGICO'!$A$2:$A$4919,$A9)/$F9,"") | J9: =IFERROR(SUMIFS('DETALLE CRONOLÓGICO'!$K$2:$K$4919,'DETALLE CRONOLÓGICO'!$A$2:$A$4919,$A9)/$E9,"") | K9: =_xlfn.MINIFS('DETALLE CRONOLÓGICO'!$K$2:$K$4919,'DETALLE CRONOLÓGICO'!$A$2:$A$4919,$A9) | L9: =_xlfn.MAXIFS('DETALLE CRONOLÓGICO'!$K$2:$K$4919,'DETALLE CRONOLÓGICO'!$A$2:$A$4919,$A9) | M9: =INDEX('DETALLE CRONOLÓGICO'!$K$2:$K$4919,MATCH($A9,'DETALLE CRONOLÓGICO'!$A$2:$A$4919,0)+$E9-1) | N9: =IFERROR($M9/INDEX('DETALLE CRONOLÓGICO'!$K$2:$K$4919,MATCH($A9,'DETALLE CRONOLÓGICO'!$A$2:$A$4919,0))-1,"") | O9: =IFERROR($I9*3,"") | P9: =IFERROR($I9*3.5,"") | Q9: =IFERROR($I9*4,"") | R9: 6720.51 | S9: 0 | T9: active | V9: SIN PRECIO
A10: 10132411463245 | B10: GORRO F LOGOS | C10: Default Title | D10: DINA DU | E10: =COUNTIF('DETALLE CRONOLÓGICO'!$A$2:$A$4919,$A10) | F10: =SUMIFS('DETALLE CRONOLÓGICO'!$I$2:$I$4919,'DETALLE CRONOLÓGICO'!$A$2:$A$4919,$A10) | G10: =INDEX('DETALLE CRONOLÓGICO'!$D$2:$D$4919,MATCH($A10,'DETALLE CRONOLÓGICO'!$A$2:$A$4919,0)) | H10: =INDEX('DETALLE CRONOLÓGICO'!$D$2:$D$4919,MATCH($A10,'DETALLE CRONOLÓGICO'!$A$2:$A$4919,0)+$E10-1) | I10: =IFERROR(SUMIFS('DETALLE CRONOLÓGICO'!$L$2:$L$4919,'DETALLE CRONOLÓGICO'!$A$2:$A$4919,$A10)/$F10,"") | J10: =IFERROR(SUMIFS('DETALLE CRONOLÓGICO'!$K$2:$K$4919,'DETALLE CRONOLÓGICO'!$A$2:$A$4919,$A10)/$E10,"") | K10: =_xlfn.MINIFS('DETALLE CRONOLÓGICO'!$K$2:$K$4919,'DETALLE CRONOLÓGICO'!$A$2:$A$4919,$A10) | L10: =_xlfn.MAXIFS('DETALLE CRONOLÓGICO'!$K$2:$K$4919,'DETALLE CRONOLÓGICO'!$A$2:$A$4919,$A10) | M10: =INDEX('DETALLE CRONOLÓGICO'!$K$2:$K$4919,MATCH($A10,'DETALLE CRONOLÓGICO'!$A$2:$A$4919,0)+$E10-1) | N10: =IFERROR($M10/INDEX('DETALLE CRONOLÓGICO'!$K$2:$K$4919,MATCH($A10,'DETALLE CRONOLÓGICO'!$A$2:$A$4919,0))-1,"") | O10: =IFERROR($I10*3,"") | P10: =IFERROR($I10*3.5,"") | Q10: =IFERROR($I10*4,"") | R10: 1089 | S10: 0 | T10: active | V10: SIN PRECIO
A11: 10132411501101 | B11: CARTERA F GRAPHY WHITE | C11: Default Title | D11: DINA DU | E11: =COUNTIF('DETALLE CRONOLÓGICO'!$A$2:$A$4919,$A11) | F11: =SUMIFS('DETALLE CRONOLÓGICO'!$I$2:$I$4919,'DETALLE CRONOLÓGICO'!$A$2:$A$4919,$A11) | G11: =INDEX('DETALLE CRONOLÓGICO'!$D$2:$D$4919,MATCH($A11,'DETALLE CRONOLÓGICO'!$A$2:$A$4919,0)) | H11: =INDEX('DETALLE CRONOLÓGICO'!$D$2:$D$4919,MATCH($A11,'DETALLE CRONOLÓGICO'!$A$2:$A$4919,0)+$E11-1) | I11: =IFERROR(SUMIFS('DETALLE CRONOLÓGICO'!$L$2:$L$4919,'DETALLE CRONOLÓGICO'!$A$2:$A$4919,$A11)/$F11,"") | J11: =IFERROR(SUMIFS('DETALLE CRONOLÓGICO'!$K$2:$K$4919,'DETALLE CRONOLÓGICO'!$A$2:$A$4919,$A11)/$E11,"") | K11: =_xlfn.MINIFS('DETALLE CRONOLÓGICO'!$K$2:$K$4919,'DETALLE CRONOLÓGICO'!$A$2:$A$4919,$A11) | L11: =_xlfn.MAXIFS('DETALLE CRONOLÓGICO'!$K$2:$K$4919,'DETALLE CRONOLÓGICO'!$A$2:$A$4919,$A11) | M11: =INDEX('DETALLE CRONOLÓGICO'!$K$2:$K$4919,MATCH($A11,'DETALLE CRONOLÓGICO'!$A$2:$A$4919,0)+$E11-1) | N11: =IFERROR($M11/INDEX('DETALLE CRONOLÓGICO'!$K$2:$K$4919,MATCH($A11,'DETALLE CRONOLÓGICO'!$A$2:$A$4919,0))-1,"") | O11: =IFERROR($I11*3,"") | P11: =IFERROR($I11*3.5,"") | Q11: =IFERROR($I11*4,"") | R11: 4300 | S11: 2 | T11: active | V11: SIN PRECIO
A12: 10132411606189 | B12: CARTERA F BAGUETTE MINI | C12: Default Title | D12: DINA DU | E12: =COUNTIF('DETALLE CRONOLÓGICO'!$A$2:$A$4919,$A12) | F12: =SUMIFS('DETALLE CRONOLÓGICO'!$I$2:$I$4919,'DETALLE CRONOLÓGICO'!$A$2:$A$4919,$A12) | G12: =INDEX('DETALLE CRONOLÓGICO'!$D$2:$D$4919,MATCH($A12,'DETALLE CRONOLÓGICO'!$A$2:$A$4919,0)) | H12: =INDEX('DETALLE CRONOLÓGICO'!$D$2:$D$4919,MATCH($A12,'DETALLE CRONOLÓGICO'!$A$2:$A$4919,0)+$E12-1) | I12: =IFERROR(SUMIFS('DETALLE CRONOLÓGICO'!$L$2:$L$4919,'DETALLE CRONOLÓGICO'!$A$2:$A$4919,$A12)/$F12,"") | J12: =IFERROR(SUMIFS('DETALLE CRONOLÓGICO'!$K$2:$K$4919,'DETALLE CRONOLÓGICO'!$A$2:$A$4919,$A12)/$E12,"") | K12: =_xlfn.MINIFS('DETALLE CRONOLÓGICO'!$K$2:$K$4919,'DETALLE CRONOLÓGICO'!$A$2:$A$4919,$A12) | L12: =_xlfn.MAXIFS('DETALLE CRONOLÓGICO'!$K$2:$K$4919,'DETALLE CRONOLÓGICO'!$A$2:$A$4919,$A12) | M12: =INDEX('DETALLE CRONOLÓGICO'!$K$2:$K$4919,MATCH($A12,'DETALLE CRONOLÓGICO'!$A$2:$A$4919,0)+$E12-1) | N12: =IFERROR($M12/INDEX('DETALLE CRONOLÓGICO'!$K$2:$K$4919,MATCH($A12,'DETALLE CRONOLÓGICO'!$A$2:$A$4919,0))-1,"") | O12: =IFERROR($I12*3,"") | P12: =IFERROR($I12*3.5,"") | Q12: =IFERROR($I12*4,"") | R12: 6500 | S12: 0 | T12: active | V12: SIN PRECIO
A13: 10132411776813 | B13: BOLSO F GRAPHY LOGOS | C13: Default Title | D13: DINA DU | E13: =COUNTIF('DETALLE CRONOLÓGICO'!$A$2:$A$4919,$A13) | F13: =SUMIFS('DETALLE CRONOLÓGICO'!$I$2:$I$4919,'DETALLE CRONOLÓGICO'!$A$2:$A$4919,$A13) | G13: =INDEX('DETALLE CRONOLÓGICO'!$D$2:$D$4919,MATCH($A13,'DETALLE CRONOLÓGICO'!$A$2:$A$4919,0)) | H13: =INDEX('DETALLE CRONOLÓGICO'!$D$2:$D$4919,MATCH($A13,'DETALLE CRONOLÓGICO'!$A$2:$A$4919,0)+$E13-1) | I13: =IFERROR(SUMIFS('DETALLE CRONOLÓGICO'!$L$2:$L$4919,'DETALLE CRONOLÓGICO'!$A$2:$A$4919,$A13)/$F13,"") | J13: =IFERROR(SUMIFS('DETALLE CRONOLÓGICO'!$K$2:$K$4919,'DETALLE CRONOLÓGICO'!$A$2:$A$4919,$A13)/$E13,"") | K13: =_xlfn.MINIFS('DETALLE CRONOLÓGICO'!$K$2:$K$4919,'DETALLE CRONOLÓGICO'!$A$2:$A$4919,$A13) | L13: =_xlfn.MAXIFS('DETALLE CRONOLÓGICO'!$K$2:$K$4919,'DETALLE CRONOLÓGICO'!$A$2:$A$4919,$A13) | M13: =INDEX('DETALLE CRONOLÓGICO'!$K$2:$K$4919,MATCH($A13,'DETALLE CRONOLÓGICO'!$A$2:$A$4919,0)+$E13-1) | N13: =IFERROR($M13/INDEX('DETALLE CRONOLÓGICO'!$K$2:$K$4919,MATCH($A13,'DETALLE CRONOLÓGICO'!$A$2:$A$4919,0))-1,"") | O13: =IFERROR($I13*3,"") | P13: =IFERROR($I13*3.5,"") | Q13: =IFERROR($I13*4,"") | R13: 7383.1 | S13: 2 | T13: active | V13: SIN PRECIO
... A19: 10956321157325 | B19: ANILLO BV BUMPS GOLD ZIRCONIAS | C19: 7 | D19: HAIFENG | E19: =COUNTIF('DETALLE CRONOLÓGICO'!$A$2:$A$4919,$A19) | F19: =SUMIFS('DETALLE CRONOLÓGICO'!$I$2:$I$4919,'DETALLE CRONOLÓGICO'!$A$2:$A$4919,$A19) | G19: =INDEX('DETALLE CRONOLÓGICO'!$D$2:$D$4919,MATCH($A19,'DETALLE CRONOLÓGICO'!$A$2:$A$4919,0)) | H19: =INDEX('DETALLE CRONOLÓGICO'!$D$2:$D$4919,MATCH($A19,'DETALLE CRONOLÓGICO'!$A$2:$A$4919,0)+$E19-1) | I19: =IFERROR(SUMIFS('DETALLE CRONOLÓGICO'!$L$2:$L$4919,'DETALLE CRONOLÓGICO'!$A$2:$A$4919,$A19)/$F19,"") | J19: =IFERROR(SUMIFS('DETALLE CRONOLÓGICO'!$K$2:$K$4919,'DETALLE CRONOLÓGICO'!$A$2:$A$4919,$A19)/$E19,"") | K19: =_xlfn.MINIFS('DETALLE CRONOLÓGICO'!$K$2:$K$4919,'DETALLE CRONOLÓGICO'!$A$2:$A$4919,$A19) | L19: =_xlfn.MAXIFS('DETALLE CRONOLÓGICO'!$K$2:$K$4919,'DETALLE CRONOLÓGICO'!$A$2:$A$4919,$A19) | M19: =INDEX('DETALLE CRONOLÓGICO'!$K$2:$K$4919,MATCH($A19,'DETALLE CRONOLÓGICO'!$A$2:$A$4919,0)+$E19-1) | N19: =IFERROR($M19/INDEX('DETALLE CRONOLÓGICO'!$K$2:$K$4919,MATCH($A19,'DETALLE CRONOLÓGICO'!$A$2:$A$4919,0))-1,"") | O19: =IFERROR($I19*3,"") | P19: =IFERROR($I19*3.5,"") | Q19: =IFERROR($I19*4,"") | R19: 999 | S19: 2 | T19: active | V19: SIN PRECIO
A20: 10956321291309 | B20: ANILLO BV BUMPS SILVER ZIRCONIAS-6 | C20: 6 | D20: HAIFENG | E20: =COUNTIF('DETALLE CRONOLÓGICO'!$A$2:$A$4919,$A20) | F20: =SUMIFS('DETALLE CRONOLÓGICO'!$I$2:$I$4919,'DETALLE CRONOLÓGICO'!$A$2:$A$4919,$A20) | G20: =INDEX('DETALLE CRONOLÓGICO'!$D$2:$D$4919,MATCH($A20,'DETALLE CRONOLÓGICO'!$A$2:$A$4919,0)) | H20: =INDEX('DETALLE CRONOLÓGICO'!$D$2:$D$4919,MATCH($A20,'DETALLE CRONOLÓGICO'!$A$2:$A$4919,0)+$E20-1) | I20: =IFERROR(SUMIFS('DETALLE CRONOLÓGICO'!$L$2:$L$4919,'DETALLE CRONOLÓGICO'!$A$2:$A$4919,$A20)/$F20,"") | J20: =IFERROR(SUMIFS('DETALLE CRONOLÓGICO'!$K$2:$K$4919,'DETALLE CRONOLÓGICO'!$A$2:$A$4919,$A20)/$E20,"") | K20: =_xlfn.MINIFS('DETALLE CRONOLÓGICO'!$K$2:$K$4919,'DETALLE CRONOLÓGICO'!$A$2:$A$4919,$A20) | L20: =_xlfn.MAXIFS('DETALLE CRONOLÓGICO'!$K$2:$K$4919,'DETALLE CRONOLÓGICO'!$A$2:$A$4919,$A20) | M20: =INDEX('DETALLE CRONOLÓGICO'!$K$2:$K$4919,MATCH($A20,'DETALLE CRONOLÓGICO'!$A$2:$A$4919,0)+$E20-1) | N20: =IFERROR($M20/INDEX('DETALLE CRONOLÓGICO'!$K$2:$K$4919,MATCH($A20,'DETALLE CRONOLÓGICO'!$A$2:$A$4919,0))-1,"") | O20: =IFERROR($I20*3,"") | P20: =IFERROR($I20*3.5,"") | Q20: =IFERROR($I20*4,"") | R20: 850 | S20: 1 | T20: active | V20: SIN PRECIO
A21: 10956321324077 | B21: ANILLO BV BUMPS SILVER ZIRCONIAS | C21: 7 | D21: HAIFENG | E21: =COUNTIF('DETALLE CRONOLÓGICO'!$A$2:$A$4919,$A21) | F21: =SUMIFS('DETALLE CRONOLÓGICO'!$I$2:$I$4919,'DETALLE CRONOLÓGICO'!$A$2:$A$4919,$A21) | G21: =INDEX('DETALLE CRONOLÓGICO'!$D$2:$D$4919,MATCH($A21,'DETALLE CRONOLÓGICO'!$A$2:$A$4919,0)) | H21: =INDEX('DETALLE CRONOLÓGICO'!$D$2:$D$4919,MATCH($A21,'DETALLE CRONOLÓGICO'!$A$2:$A$4919,0)+$E21-1) | I21: =IFERROR(SUMIFS('DETALLE CRONOLÓGICO'!$L$2:$L$4919,'DETALLE CRONOLÓGICO'!$A$2:$A$4919,$A21)/$F21,"") | J21: =IFERROR(SUMIFS('DETALLE CRONOLÓGICO'!$K$2:$K$4919,'DETALLE CRONOLÓGICO'!$A$2:$A$4919,$A21)/$E21,"") | K21: =_xlfn.MINIFS('DETALLE CRONOLÓGICO'!$K$2:$K$4919,'DETALLE CRONOLÓGICO'!$A$2:$A$4919,$A21) | L21: =_xlfn.MAXIFS('DETALLE CRONOLÓGICO'!$K$2:$K$4919,'DETALLE CRONOLÓGICO'!$A$2:$A$4919,$A21) | M21: =INDEX('DETALLE CRONOLÓGICO'!$K$2:$K$4919,MATCH($A21,'DETALLE CRONOLÓGICO'!$A$2:$A$4919,0)+$E21-1) | N21: =IFERROR($M21/INDEX('DETALLE CRONOLÓGICO'!$K$2:$K$4919,MATCH($A21,'DETALLE CRONOLÓGICO'!$A$2:$A$4919,0))-1,"") | O21: =IFERROR($I21*3,"") | P21: =IFERROR($I21*3.5,"") | Q21: =IFERROR($I21*4,"") | R21: 850 | S21: 1 | T21: active | V21: SIN PRECIO
A22: 11078751761037 | B22: COLLAR C GOLD ZIRCONIAS | C22: Default Title | D22: HAIFENG | E22: =COUNTIF('DETALLE CRONOLÓGICO'!$A$2:$A$4919,$A22) | F22: =SUMIFS('DETALLE CRONOLÓGICO'!$I$2:$I$4919,'DETALLE CRONOLÓGICO'!$A$2:$A$4919,$A22) | G22: =INDEX('DETALLE CRONOLÓGICO'!$D$2:$D$4919,MATCH($A22,'DETALLE CRONOLÓGICO'!$A$2:$A$4919,0)) | H22: =INDEX('DETALLE CRONOLÓGICO'!$D$2:$D$4919,MATCH($A22,'DETALLE CRONOLÓGICO'!$A$2:$A$4919,0)+$E22-1) | I22: =IFERROR(SUMIFS('DETALLE CRONOLÓGICO'!$L$2:$L$4919,'DETALLE CRONOLÓGICO'!$A$2:$A$4919,$A22)/$F22,"") | J22: =IFERROR(SUMIFS('DETALLE CRONOLÓGICO'!$K$2:$K$4919,'DETALLE CRONOLÓGICO'!$A$2:$A$4919,$A22)/$E22,"") | K22: =_xlfn.MINIFS('DETALLE CRONOLÓGICO'!$K$2:$K$4919,'DETALLE CRONOLÓGICO'!$A$2:$A$4919,$A22) | L22: =_xlfn.MAXIFS('DETALLE CRONOLÓGICO'!$K$2:$K$4919,'DETALLE CRONOLÓGICO'!$A$2:$A$4919,$A22) | M22: =INDEX('DETALLE CRONOLÓGICO'!$K$2:$K$4919,MATCH($A22,'DETALLE CRONOLÓGICO'!$A$2:$A$4919,0)+$E22-1) | N22: =IFERROR($M22/INDEX('DETALLE CRONOLÓGICO'!$K$2:$K$4919,MATCH($A22,'DETALLE CRONOLÓGICO'!$A$2:$A$4919,0))-1,"") | O22: =IFERROR($I22*3,"") | P22: =IFERROR($I22*3.5,"") | Q22: =IFERROR($I22*4,"") | R22: 550 | S22: 12 | T22: active | V22: SIN PRECIO
A23: 11078751910221 | B23: ARETES C GOLD ZIRCONIAS | C23: Default Title | D23: HAIFENG | E23: =COUNTIF('DETALLE CRONOLÓGICO'!$A$2:$A$4919,$A23) | F23: =SUMIFS('DETALLE CRONOLÓGICO'!$I$2:$I$4919,'DETALLE CRONOLÓGICO'!$A$2:$A$4919,$A23) | G23: =INDEX('DETALLE CRONOLÓGICO'!$D$2:$D$4919,MATCH($A23,'DETALLE CRONOLÓGICO'!$A$2:$A$4919,0)) | H23: =INDEX('DETALLE CRONOLÓGICO'!$D$2:$D$4919,MATCH($A23,'DETALLE CRONOLÓGICO'!$A$2:$A$4919,0)+$E23-1) | I23: =IFERROR(SUMIFS('DETALLE CRONOLÓGICO'!$L$2:$L$4919,'DETALLE CRONOLÓGICO'!$A$2:$A$4919,$A23)/$F23,"") | J23: =IFERROR(SUMIFS('DETALLE CRONOLÓGICO'!$K$2:$K$4919,'DETALLE CRONOLÓGICO'!$A$2:$A$4919,$A23)/$E23,"") | K23: =_xlfn.MINIFS('DETALLE CRONOLÓGICO'!$K$2:$K$4919,'DETALLE CRONOLÓGICO'!$A$2:$A$4919,$A23) | L23: =_xlfn.MAXIFS('DETALLE CRONOLÓGICO'!$K$2:$K$4919,'DETALLE CRONOLÓGICO'!$A$2:$A$4919,$A23) | M23: =INDEX('DETALLE CRONOLÓGICO'!$K$2:$K$4919,MATCH($A23,'DETALLE CRONOLÓGICO'!$A$2:$A$4919,0)+$E23-1) | N23: =IFERROR($M23/INDEX('DETALLE CRONOLÓGICO'!$K$2:$K$4919,MATCH($A23,'DETALLE CRONOLÓGICO'!$A$2:$A$4919,0))-1,"") | O23: =IFERROR($I23*3,"") | P23: =IFERROR($I23*3.5,"") | Q23: =IFERROR($I23*4,"") | R23: 575 | S23: 7 | T23: active | V23: SIN PRECIO
A24: 11078752382541 | B24: ARETES C GOLD PEARL | C24: Default Title | D24: HAIFENG | E24: =COUNTIF('DETALLE CRONOLÓGICO'!$A$2:$A$4919,$A24) | F24: =SUMIFS('DETALLE CRONOLÓGICO'!$I$2:$I$4919,'DETALLE CRONOLÓGICO'!$A$2:$A$4919,$A24) | G24: =INDEX('DETALLE CRONOLÓGICO'!$D$2:$D$4919,MATCH($A24,'DETALLE CRONOLÓGICO'!$A$2:$A$4919,0)) | H24: =INDEX('DETALLE CRONOLÓGICO'!$D$2:$D$4919,MATCH($A24,'DETALLE CRONOLÓGICO'!$A$2:$A$4919,0)+$E24-1) | I24: =IFERROR(SUMIFS('DETALLE CRONOLÓGICO'!$L$2:$L$4919,'DETALLE CRONOLÓGICO'!$A$2:$A$4919,$A24)/$F24,"") | J24: =IFERROR(SUMIFS('DETALLE CRONOLÓGICO'!$K$2:$K$4919,'DETALLE CRONOLÓGICO'!$A$2:$A$4919,$A24)/$E24,"") | K24: =_xlfn.MINIFS('DETALLE CRONOLÓGICO'!$K$2:$K$4919,'DETALLE CRONOLÓGICO'!$A$2:$A$4919,$A24) | L24: =_xlfn.MAXIFS('DETALLE CRONOLÓGICO'!$K$2:$K$4919,'DETALLE CRONOLÓGICO'!$A$2:$A$4919,$A24) | M24: =INDEX('DETALLE CRONOLÓGICO'!$K$2:$K$4919,MATCH($A24,'DETALLE CRONOLÓGICO'!$A$2:$A$4919,0)+$E24-1) | N24: =IFERROR($M24/INDEX('DETALLE CRONOLÓGICO'!$K$2:$K$4919,MATCH($A24,'DETALLE CRONOLÓGICO'!$A$2:$A$4919,0))-1,"") | O24: =IFERROR($I24*3,"") | P24: =IFERROR($I24*3.5,"") | Q24: =IFERROR($I24*4,"") | R24: 499 | S24: 6 | T24: active | V24: SIN PRECIO
A25: 11453671120077 | B25: ARETES FR GOLD ONE PEARL | C25: PRODUCTO NUEVO | D25: HAIFENG | E25: =COUNTIF('DETALLE CRONOLÓGICO'!$A$2:$A$4919,$A25) | F25: =SUMIFS('DETALLE CRONOLÓGICO'!$I$2:$I$4919,'DETALLE CRONOLÓGICO'!$A$2:$A$4919,$A25) | G25: =INDEX('DETALLE CRONOLÓGICO'!$D$2:$D$4919,MATCH($A25,'DETALLE CRONOLÓGICO'!$A$2:$A$4919,0)) | H25: =INDEX('DETALLE CRONOLÓGICO'!$D$2:$D$4919,MATCH($A25,'DETALLE CRONOLÓGICO'!$A$2:$A$4919,0)+$E25-1) | I25: =IFERROR(SUMIFS('DETALLE CRONOLÓGICO'!$L$2:$L$4919,'DETALLE CRONOLÓGICO'!$A$2:$A$4919,$A25)/$F25,"") | J25: =IFERROR(SUMIFS('DETALLE CRONOLÓGICO'!$K$2:$K$4919,'DETALLE CRONOLÓGICO'!$A$2:$A$4919,$A25)/$E25,"") | K25: =_xlfn.MINIFS('DETALLE CRONOLÓGICO'!$K$2:$K$4919,'DETALLE CRONOLÓGICO'!$A$2:$A$4919,$A25) | L25: =_xlfn.MAXIFS('DETALLE CRONOLÓGICO'!$K$2:$K$4919,'DETALLE CRONOLÓGICO'!$A$2:$A$4919,$A25) | M25: =INDEX('DETALLE CRONOLÓGICO'!$K$2:$K$4919,MATCH($A25,'DETALLE CRONOLÓGICO'!$A$2:$A$4919,0)+$E25-1) | N25: =IFERROR($M25/INDEX('DETALLE CRONOLÓGICO'!$K$2:$K$4919,MATCH($A25,'DETALLE CRONOLÓGICO'!$A$2:$A$4919,0))-1,"") | O25: =IFERROR($I25*3,"") | P25: =IFERROR($I25*3.5,"") | Q25: =IFERROR($I25*4,"") | R25: 499 | S25: 0 | T25: draft | V25: SIN PRECIO
A26: 11915813184811 | B26: LENTES DE SOL MM BROWN | C26: Default Title | D26: CYNTHIA | E26: =COUNTIF('DETALLE CRONOLÓGICO'!$A$2:$A$4919,$A26) | F26: =SUMIFS('DETALLE CRONOLÓGICO'!$I$2:$I$4919,'DETALLE CRONOLÓGICO'!$A$2:$A$4919,$A26) | G26: =INDEX('DETALLE CRONOLÓGICO'!$D$2:$D$4919,MATCH($A26,'DETALLE CRONOLÓGICO'!$A$2:$A$4919,0)) | H26: =INDEX('DETALLE CRONOLÓGICO'!$D$2:$D$4919,MATCH($A26,'DETALLE CRONOLÓGICO'!$A$2:$A$4919,0)+$E26-1) | I26: =IFERROR(SUMIFS('DETALLE CRONOLÓGICO'!$L$2:$L$4919,'DETALLE CRONOLÓGICO'!$A$2:$A$4919,$A26)/$F26,"") | J26: =IFERROR(SUMIFS('DETALLE CRONOLÓGICO'!$K$2:$K$4919,'DETALLE CRONOLÓGICO'!$A$2:$A$4919,$A26)/$E26,"") | K26: =_xlfn.MINIFS('DETALLE CRONOLÓGICO'!$K$2:$K$4919,'DETALLE CRONOLÓGICO'!$A$2:$A$4919,$A26) | L26: =_xlfn.MAXIFS('DETALLE CRONOLÓGICO'!$K$2:$K$4919,'DETALLE CRONOLÓGICO'!$A$2:$A$4919,$A26) | M26: =INDEX('DETALLE CRONOLÓGICO'!$K$2:$K$4919,MATCH($A26,'DETALLE CRONOLÓGICO'!$A$2:$A$4919,0)+$E26-1) | N26: =IFERROR($M26/INDEX('DETALLE CRONOLÓGICO'!$K$2:$K$4919,MATCH($A26,'DETALLE CRONOLÓGICO'!$A$2:$A$4919,0))-1,"") | O26: =IFERROR($I26*3,"") | P26: =IFERROR($I26*3.5,"") | Q26: =IFERROR($I26*4,"") | R26: 2730 | S26: 4 | T26: active | V26: SIN PRECIO
A27: 11915820343339 | B27: LENTES MM HAVANA | C27: Default Title | D27: CYNTHIA | E27: =COUNTIF('DETALLE CRONOLÓGICO'!$A$2:$A$4919,$A27) | F27: =SUMIFS('DETALLE CRONOLÓGICO'!$I$2:$I$4919,'DETALLE CRONOLÓGICO'!$A$2:$A$4919,$A27) | G27: =INDEX('DETALLE CRONOLÓGICO'!$D$2:$D$4919,MATCH($A27,'DETALLE CRONOLÓGICO'!$A$2:$A$4919,0)) | H27: =INDEX('DETALLE CRONOLÓGICO'!$D$2:$D$4919,MATCH($A27,'DETALLE CRONOLÓGICO'!$A$2:$A$4919,0)+$E27-1) | I27: =IFERROR(SUMIFS('DETALLE CRONOLÓGICO'!$L$2:$L$4919,'DETALLE CRONOLÓGICO'!$A$2:$A$4919,$A27)/$F27,"") | J27: =IFERROR(SUMIFS('DETALLE CRONOLÓGICO'!$K$2:$K$4919,'DETALLE CRONOLÓGICO'!$A$2:$A$4919,$A27)/$E27,"") | K27: =_xlfn.MINIFS('DETALLE CRONOLÓGICO'!$K$2:$K$4919,'DETALLE CRONOLÓGICO'!$A$2:$A$4919,$A27) | L27: =_xlfn.MAXIFS('DETALLE CRONOLÓGICO'!$K$2:$K$4919,'DETALLE CRONOLÓGICO'!$A$2:$A$4919,$A27) | M27: =INDEX('DETALLE CRONOLÓGICO'!$K$2:$K$4919,MATCH($A27,'DETALLE CRONOLÓGICO'!$A$2:$A$4919,0)+$E27-1) | N27: =IFERROR($M27/INDEX('DETALLE CRONOLÓGICO'!$K$2:$K$4919,MATCH($A27,'DETALLE CRONOLÓGICO'!$A$2:$A$4919,0))-1,"") | O27: =IFERROR($I27*3,"") | P27: =IFERROR($I27*3.5,"") | Q27: =IFERROR($I27*4,"") | R27: 2899 | S27: 1 | T27: active | V27: SIN PRECIO
A28: 11915825730987 | B28: TRAJE DE BAÑO C | C28: M | D28: CYNTHIA | E28: =COUNTIF('DETALLE CRONOLÓGICO'!$A$2:$A$4919,$A28) | F28: =SUMIFS('DETALLE CRONOLÓGICO'!$I$2:$I$4919,'DETALLE CRONOLÓGICO'!$A$2:$A$4919,$A28) | G28: =INDEX('DETALLE CRONOLÓGICO'!$D$2:$D$4919,MATCH($A28,'DETALLE CRONOLÓGICO'!$A$2:$A$4919,0)) | H28: =INDEX('DETALLE CRONOLÓGICO'!$D$2:$D$4919,MATCH($A28,'DETALLE CRONOLÓGICO'!$A$2:$A$4919,0)+$E28-1) | I28: =IFERROR(SUMIFS('DETALLE CRONOLÓGICO'!$L$2:$L$4919,'DETALLE CRONOLÓGICO'!$A$2:$A$4919,$A28)/$F28,"") | J28: =IFERROR(SUMIFS('DETALLE CRONOLÓGICO'!$K$2:$K$4919,'DETALLE CRONOLÓGICO'!$A$2:$A$4919,$A28)/$E28,"") | K28: =_xlfn.MINIFS('DETALLE CRONOLÓGICO'!$K$2:$K$4919,'DETALLE CRONOLÓGICO'!$A$2:$A$4919,$A28) | L28: =_xlfn.MAXIFS('DETALLE CRONOLÓGICO'!$K$2:$K$4919,'DETALLE CRONOLÓGICO'!$A$2:$A$4919,$A28) | M28: =INDEX('DETALLE CRONOLÓGICO'!$K$2:$K$4919,MATCH($A28,'DETALLE CRONOLÓGICO'!$A$2:$A$4919,0)+$E28-1) | N28: =IFERROR($M28/INDEX('DETALLE CRONOLÓGICO'!$K$2:$K$4919,MATCH($A28,'DETALLE CRONOLÓGICO'!$A$2:$A$4919,0))-1,"") | O28: =IFERROR($I28*3,"") | P28: =IFERROR($I28*3.5,"") | Q28: =IFERROR($I28*4,"") | T28: YA NO EXISTE EN SHOPIFY | V28: SIN PRECIO
A29: 11915825763755 | B29: TRAJE DE BAÑO C | C29: L | D29: CYNTHIA | E29: =COUNTIF('DETALLE CRONOLÓGICO'!$A$2:$A$4919,$A29) | F29: =SUMIFS('DETALLE CRONOLÓGICO'!$I$2:$I$4919,'DETALLE CRONOLÓGICO'!$A$2:$A$4919,$A29) | G29: =INDEX('DETALLE CRONOLÓGICO'!$D$2:$D$4919,MATCH($A29,'DETALLE CRONOLÓGICO'!$A$2:$A$4919,0)) | H29: =INDEX('DETALLE CRONOLÓGICO'!$D$2:$D$4919,MATCH($A29,'DETALLE CRONOLÓGICO'!$A$2:$A$4919,0)+$E29-1) | I29: =IFERROR(SUMIFS('DETALLE CRONOLÓGICO'!$L$2:$L$4919,'DETALLE CRONOLÓGICO'!$A$2:$A$4919,$A29)/$F29,"") | J29: =IFERROR(SUMIFS('DETALLE CRONOLÓGICO'!$K$2:$K$4919,'DETALLE CRONOLÓGICO'!$A$2:$A$4919,$A29)/$E29,"") | K29: =_xlfn.MINIFS('DETALLE CRONOLÓGICO'!$K$2:$K$4919,'DETALLE CRONOLÓGICO'!$A$2:$A$4919,$A29) | L29: =_xlfn.MAXIFS('DETALLE CRONOLÓGICO'!$K$2:$K$4919,'DETALLE CRONOLÓGICO'!$A$2:$A$4919,$A29) | M29: =INDEX('DETALLE CRONOLÓGICO'!$K$2:$K$4919,MATCH($A29,'DETALLE CRONOLÓGICO'!$A$2:$A$4919,0)+$E29-1) | N29: =IFERROR($M29/INDEX('DETALLE CRONOLÓGICO'!$K$2:$K$4919,MATCH($A29,'DETALLE CRONOLÓGICO'!$A$2:$A$4919,0))-1,"") | O29: =IFERROR($I29*3,"") | P29: =IFERROR($I29*3.5,"") | Q29: =IFERROR($I29*4,"") | R29: 1099 | S29: 0 | T29: active | V29: SIN PRECIO
A30: 11915826071979 | B30: LENTES LV EVIDENCE | C30: HIGH QUALITY | D30: CYNTHIA | E30: =COUNTIF('DETALLE CRONOLÓGICO'!$A$2:$A$4919,$A30) | F30: =SUMIFS('DETALLE CRONOLÓGICO'!$I$2:$I$4919,'DETALLE CRONOLÓGICO'!$A$2:$A$4919,$A30) | G30: =INDEX('DETALLE CRONOLÓGICO'!$D$2:$D$4919,MATCH($A30,'DETALLE CRONOLÓGICO'!$A$2:$A$4919,0)) | H30: =INDEX('DETALLE CRONOLÓGICO'!$D$2:$D$4919,MATCH($A30,'DETALLE CRONOLÓGICO'!$A$2:$A$4919,0)+$E30-1) | I30: =IFERROR(SUMIFS('DETALLE CRONOLÓGICO'!$L$2:$L$4919,'DETALLE CRONOLÓGICO'!$A$2:$A$4919,$A30)/$F30,"") | J30: =IFERROR(SUMIFS('DETALLE CRONOLÓGICO'!$K$2:$K$4919,'DETALLE CRONOLÓGICO'!$A$2:$A$4919,$A30)/$E30,"") | K30: =_xlfn.MINIFS('DETALLE CRONOLÓGICO'!$K$2:$K$4919,'DETALLE CRONOLÓGICO'!$A$2:$A$4919,$A30) | L30: =_xlfn.MAXIFS('DETALLE CRONOLÓGICO'!$K$2:$K$4919,'DETALLE CRONOLÓGICO'!$A$2:$A$4919,$A30) | M30: =INDEX('DETALLE CRONOLÓGICO'!$K$2:$K$4919,MATCH($A30,'DETALLE CRONOLÓGICO'!$A$2:$A$4919,0)+$E30-1) | N30: =IFERROR($M30/INDEX('DETALLE CRONOLÓGICO'!$K$2:$K$4919,MATCH($A30,'DETALLE CRONOLÓGICO'!$A$2:$A$4919,0))-1,"") | O30: =IFERROR($I30*3,"") | P30: =IFERROR($I30*3.5,"") | Q30: =IFERROR($I30*4,"") | R30: 955 | S30: 1 | T30: active | V30: SIN PRECIO
A31: 11915828032299 | B31: BOLSO DE VIAJE G BOWLING 55 GREEN | C31: Default Title | D31: CYNTHIA | E31: =COUNTIF('DETALLE CRONOLÓGICO'!$A$2:$A$4919,$A31) | F31: =SUMIFS('DETALLE CRONOLÓGICO'!$I$2:$I$4919,'DETALLE CRONOLÓGICO'!$A$2:$A$4919,$A31) | G31: =INDEX('DETALLE CRONOLÓGICO'!$D$2:$D$4919,MATCH($A31,'DETALLE CRONOLÓGICO'!$A$2:$A$4919,0)) | H31: =INDEX('DETALLE CRONOLÓGICO'!$D$2:$D$4919,MATCH($A31,'DETALLE CRONOLÓGICO'!$A$2:$A$4919,0)+$E31-1) | I31: =IFERROR(SUMIFS('DETALLE CRONOLÓGICO'!$L$2:$L$4919,'DETALLE CRONOLÓGICO'!$A$2:$A$4919,$A31)/$F31,"") | J31: =IFERROR(SUMIFS('DETALLE CRONOLÓGICO'!$K$2:$K$4919,'DETALLE CRONOLÓGICO'!$A$2:$A$4919,$A31)/$E31,"") | K31: =_xlfn.MINIFS('DETALLE CRONOLÓGICO'!$K$2:$K$4919,'DETALLE CRONOLÓGICO'!$A$2:$A$4919,$A31) | L31: =_xlfn.MAXIFS('DETALLE CRONOLÓGICO'!$K$2:$K$4919,'DETALLE CRONOLÓGICO'!$A$2:$A$4919,$A31) | M31: =INDEX('DETALLE CRONOLÓGICO'!$K$2:$K$4919,MATCH($A31,'DETALLE CRONOLÓGICO'!$A$2:$A$4919,0)+$E31-1) | N31: =IFERROR($M31/INDEX('DETALLE CRONOLÓGICO'!$K$2:$K$4919,MATCH($A31,'DETALLE CRONOLÓGICO'!$A$2:$A$4919,0))-1,"") | O31: =IFERROR($I31*3,"") | P31: =IFERROR($I31*3.5,"") | Q31: =IFERROR($I31*4,"") | R31: 7999 | S31: 3 | T31: active | V31: SIN PRECIO
A32: 11915828105387 | B32: TRAJE DE BAÑO V | C32: M | D32: CYNTHIA | E32: =COUNTIF('DETALLE CRONOLÓGICO'!$A$2:$A$4919,$A32) | F32: =SUMIFS('DETALLE CRONOLÓGICO'!$I$2:$I$4919,'DETALLE CRONOLÓGICO'!$A$2:$A$4919,$A32) | G32: =INDEX('DETALLE CRONOLÓGICO'!$D$2:$D$4919,MATCH($A32,'DETALLE CRONOLÓGICO'!$A$2:$A$4919,0)) | H32: =INDEX('DETALLE CRONOLÓGICO'!$D$2:$D$4919,MATCH($A32,'DETALLE CRONOLÓGICO'!$A$2:$A$4919,0)+$E32-1) | I32: =IFERROR(SUMIFS('DETALLE CRONOLÓGICO'!$L$2:$L$4919,'DETALLE CRONOLÓGICO'!$A$2:$A$4919,$A32)/$F32,"") | J32: =IFERROR(SUMIFS('DETALLE CRONOLÓGICO'!$K$2:$K$4919,'DETALLE CRONOLÓGICO'!$A$2:$A$4919,$A32)/$E32,"") | K32: =_xlfn.MINIFS('DETALLE CRONOLÓGICO'!$K$2:$K$4919,'DETALLE CRONOLÓGICO'!$A$2:$A$4919,$A32) | L32: =_xlfn.MAXIFS('DETALLE CRONOLÓGICO'!$K$2:$K$4919,'DETALLE CRONOLÓGICO'!$A$2:$A$4919,$A32) | M32: =INDEX('DETALLE CRONOLÓGICO'!$K$2:$K$4919,MATCH($A32,'DETALLE CRONOLÓGICO'!$A$2:$A$4919,0)+$E32-1) | N32: =IFERROR($M32/INDEX('DETALLE CRONOLÓGICO'!$K$2:$K$4919,MATCH($A32,'DETALLE CRONOLÓGICO'!$A$2:$A$4919,0))-1,"") | O32: =IFERROR($I32*3,"") | P32: =IFERROR($I32*3.5,"") | Q32: =IFERROR($I32*4,"") | R32: 1149 | S32: 0 | T32: active | V32: SIN PRECIO
A33: 11915828138155 | B33: TRAJE DE BAÑO V | C33: L | D33: CYNTHIA | E33: =COUNTIF('DETALLE CRONOLÓGICO'!$A$2:$A$4919,$A33) | F33: =SUMIFS('DETALLE CRONOLÓGICO'!$I$2:$I$4919,'DETALLE CRONOLÓGICO'!$A$2:$A$4919,$A33) | G33: =INDEX('DETALLE CRONOLÓGICO'!$D$2:$D$4919,MATCH($A33,'DETALLE CRONOLÓGICO'!$A$2:$A$4919,0)) | H33: =INDEX('DETALLE CRONOLÓGICO'!$D$2:$D$4919,MATCH($A33,'DETALLE CRONOLÓGICO'!$A$2:$A$4919,0)+$E33-1) | I33: =IFERROR(SUMIFS('DETALLE CRONOLÓGICO'!$L$2:$L$4919,'DETALLE CRONOLÓGICO'!$A$2:$A$4919,$A33)/$F33,"") | J33: =IFERROR(SUMIFS('DETALLE CRONOLÓGICO'!$K$2:$K$4919,'DETALLE CRONOLÓGICO'!$A$2:$A$4919,$A33)/$E33,"") | K33: =_xlfn.MINIFS('DETALLE CRONOLÓGICO'!$K$2:$K$4919,'DETALLE CRONOLÓGICO'!$A$2:$A$4919,$A33) | L33: =_xlfn.MAXIFS('DETALLE CRONOLÓGICO'!$K$2:$K$4919,'DETALLE CRONOLÓGICO'!$A$2:$A$4919,$A33) | M33: =INDEX('DETALLE CRONOLÓGICO'!$K$2:$K$4919,MATCH($A33,'DETALLE CRONOLÓGICO'!$A$2:$A$4919,0)+$E33-1) | N33: =IFERROR($M33/INDEX('DETALLE CRONOLÓGICO'!$K$2:$K$4919,MATCH($A33,'DETALLE CRONOLÓGICO'!$A$2:$A$4919,0))-1,"") | O33: =IFERROR($I33*3,"") | P33: =IFERROR($I33*3.5,"") | Q33: =IFERROR($I33*4,"") | R33: 1149 | S33: 6 | T33: active | V33: SIN PRECIO
A34: 11966951169965 | B34: PULSERA DE CUENTAS CON INSIGNIA DE CORAZÓN BLUE | C34: 20 cm | D34: HAIFENG | E34: =COUNTIF('DETALLE CRONOLÓGICO'!$A$2:$A$4919,$A34) | F34: =SUMIFS('DETALLE CRONOLÓGICO'!$I$2:$I$4919,'DETALLE CRONOLÓGICO'!$A$2:$A$4919,$A34) | G34: =INDEX('DETALLE CRONOLÓGICO'!$D$2:$D$4919,MATCH($A34,'DETALLE CRONOLÓGICO'!$A$2:$A$4919,0)) | H34: =INDEX('DETALLE CRONOLÓGICO'!$D$2:$D$4919,MATCH($A34,'DETALLE CRONOLÓGICO'!$A$2:$A$4919,0)+$E34-1) | I34: =IFERROR(SUMIFS('DETALLE CRONOLÓGICO'!$L$2:$L$4919,'DETALLE CRONOLÓGICO'!$A$2:$A$4919,$A34)/$F34,"") | J34: =IFERROR(SUMIFS('DETALLE CRONOLÓGICO'!$K$2:$K$4919,'DETALLE CRONOLÓGICO'!$A$2:$A$4919,$A34)/$E34,"") | K34: =_xlfn.MINIFS('DETALLE CRONOLÓGICO'!$K$2:$K$4919,'DETALLE CRONOLÓGICO'!$A$2:$A$4919,$A34) | L34: =_xlfn.MAXIFS('DETALLE CRONOLÓGICO'!$K$2:$K$4919,'DETALLE CRONOLÓGICO'!$A$2:$A$4919,$A34) | M34: =INDEX('DETALLE CRONOLÓGICO'!$K$2:$K$4919,MATCH($A34,'DETALLE CRONOLÓGICO'!$A$2:$A$4919,0)+$E34-1) | N34: =IFERROR($M34/INDEX('DETALLE CRONOLÓGICO'!$K$2:$K$4919,MATCH($A34,'DETALLE CRONOLÓGICO'!$A$2:$A$4919,0))-1,"") | O34: =IFERROR($I34*3,"") | P34: =IFERROR($I34*3.5,"") | Q34: =IFERROR($I34*4,"") | R34: 550 | S34: 2 | T34: active | V34: SIN PRECIO
A35: 12314361063501 | B35: ANILLO F DOBLE GOLD | C35: AJUSTABLE | D35: HAIFENG | E35: =COUNTIF('DETALLE CRONOLÓGICO'!$A$2:$A$4919,$A35) | F35: =SUMIFS('DETALLE CRONOLÓGICO'!$I$2:$I$4919,'DETALLE CRONOLÓGICO'!$A$2:$A$4919,$A35) | G35: =INDEX('DETALLE CRONOLÓGICO'!$D$2:$D$4919,MATCH($A35,'DETALLE CRONOLÓGICO'!$A$2:$A$4919,0)) | H35: =INDEX('DETALLE CRONOLÓGICO'!$D$2:$D$4919,MATCH($A35,'DETALLE CRONOLÓGICO'!$A$2:$A$4919,0)+$E35-1) | I35: =IFERROR(SUMIFS('DETALLE CRONOLÓGICO'!$L$2:$L$4919,'DETALLE CRONOLÓGICO'!$A$2:$A$4919,$A35)/$F35,"") | J35: =IFERROR(SUMIFS('DETALLE CRONOLÓGICO'!$K$2:$K$4919,'DETALLE CRONOLÓGICO'!$A$2:$A$4919,$A35)/$E35,"") | K35: =_xlfn.MINIFS('DETALLE CRONOLÓGICO'!$K$2:$K$4919,'DETALLE CRONOLÓGICO'!$A$2:$A$4919,$A35) | L35: =_xlfn.MAXIFS('DETALLE CRONOLÓGICO'!$K$2:$K$4919,'DETALLE CRONOLÓGICO'!$A$2:$A$4919,$A35) | M35: =INDEX('DETALLE CRONOLÓGICO'!$K$2:$K$4919,MATCH($A35,'DETALLE CRONOLÓGICO'!$A$2:$A$4919,0)+$E35-1) | N35: =IFERROR($M35/INDEX('DETALLE CRONOLÓGICO'!$K$2:$K$4919,MATCH($A35,'DETALLE CRONOLÓGICO'!$A$2:$A$4919,0))-1,"") | O35: =IFERROR($I35*3,"") | P35: =IFERROR($I35*3.5,"") | Q35: =IFERROR($I35*4,"") | R35: 620 | S35: 0 | T35: active | V35: SIN PRECIO
A36: 12314361226797 | B36: ARRACADAS COLGANTES F ZIRCONIA | C36: Default Title | D36: HAIFENG | E36: =COUNTIF('DETALLE CRONOLÓGICO'!$A$2:$A$4919,$A36) | F36: =SUMIFS('DETALLE CRONOLÓGICO'!$I$2:$I$4919,'DETALLE CRONOLÓGICO'!$A$2:$A$4919,$A36) | G36: =INDEX('DETALLE CRONOLÓGICO'!$D$2:$D$4919,MATCH($A36,'DETALLE CRONOLÓGICO'!$A$2:$A$4919,0)) | H36: =INDEX('DETALLE CRONOLÓGICO'!$D$2:$D$4919,MATCH($A36,'DETALLE CRONOLÓGICO'!$A$2:$A$4919,0)+$E36-1) | I36: =IFERROR(SUMIFS('DETALLE CRONOLÓGICO'!$L$2:$L$4919,'DETALLE CRONOLÓGICO'!$A$2:$A$4919,$A36)/$F36,"") | J36: =IFERROR(SUMIFS('DETALLE CRONOLÓGICO'!$K$2:$K$4919,'DETALLE CRONOLÓGICO'!$A$2:$A$4919,$A36)/$E36,"") | K36: =_xlfn.MINIFS('DETALLE CRONOLÓGICO'!$K$2:$K$4919,'DETALLE CRONOLÓGICO'!$A$2:$A$4919,$A36) | L36: =_xlfn.MAXIFS('DETALLE CRONOLÓGICO'!$K$2:$K$4919,'DETALLE CRONOLÓGICO'!$A$2:$A$4919,$A36) | M36: =INDEX('DETALLE CRONOLÓGICO'!$K$2:$K$4919,MATCH($A36,'DETALLE CRONOLÓGICO'!$A$2:$A$4919,0)+$E36-1) | N36: =IFERROR($M36/INDEX('DETALLE CRONOLÓGICO'!$K$2:$K$4919,MATCH($A36,'DETALLE CRONOLÓGICO'!$A$2:$A$4919,0))-1,"") | O36: =IFERROR($I36*3,"") | P36: =IFERROR($I36*3.5,"") | Q36: =IFERROR($I36*4,"") | R36: 670 | S36: 1 | T36: active | V36: SIN PRECIO
A37: 12314361364653 | B37: ARETES F GOLD PEARL | C37: Default Title | D37: HAIFENG | E37: =COUNTIF('DETALLE CRONOLÓGICO'!$A$2:$A$4919,$A37) | F37: =SUMIFS('DETALLE CRONOLÓGICO'!$I$2:$I$4919,'DETALLE CRONOLÓGICO'!$A$2:$A$4919,$A37) | G37: =INDEX('DETALLE CRONOLÓGICO'!$D$2:$D$4919,MATCH($A37,'DETALLE CRONOLÓGICO'!$A$2:$A$4919,0)) | H37: =INDEX('DETALLE CRONOLÓGICO'!$D$2:$D$4919,MATCH($A37,'DETALLE CRONOLÓGICO'!$A$2:$A$4919,0)+$E37-1) | I37: =IFERROR(SUMIFS('DETALLE CRONOLÓGICO'!$L$2:$L$4919,'DETALLE CRONOLÓGICO'!$A$2:$A$4919,$A37)/$F37,"") | J37: =IFERROR(SUMIFS('DETALLE CRONOLÓGICO'!$K$2:$K$4919,'DETALLE CRONOLÓGICO'!$A$2:$A$4919,$A37)/$E37,"") | K37: =_xlfn.MINIFS('DETALLE CRONOLÓGICO'!$K$2:$K$4919,'DETALLE CRONOLÓGICO'!$A$2:$A$4919,$A37) | L37: =_xlfn.MAXIFS('DETALLE CRONOLÓGICO'!$K$2:$K$4919,'DETALLE CRONOLÓGICO'!$A$2:$A$4919,$A37) | M37: =INDEX('DETALLE CRONOLÓGICO'!$K$2:$K$4919,MATCH($A37,'DETALLE CRONOLÓGICO'!$A$2:$A$4919,0)+$E37-1) | N37: =IFERROR($M37/INDEX('DETALLE CRONOLÓGICO'!$K$2:$K$4919,MATCH($A37,'DETALLE CRONOLÓGICO'!$A$2:$A$4919,0))-1,"") | O37: =IFERROR($I37*3,"") | P37: =IFERROR($I37*3.5,"") | Q37: =IFERROR($I37*4,"") | R37: 699 | S37: 4 | T37: active | V37: SIN PRECIO
A38: 12314361469741 | B38: ARETES F FILO GOLD | C38: Default Title | D38: HAIFENG | E38: =COUNTIF('DETALLE CRONOLÓGICO'!$A$2:$A$4919,$A38) | F38: =SUMIFS('DETALLE CRONOLÓGICO'!$I$2:$I$4919,'DETALLE CRONOLÓGICO'!$A$2:$A$4919,$A38) | G38: =INDEX('DETALLE CRONOLÓGICO'!$D$2:$D$4919,MATCH($A38,'DETALLE CRONOLÓGICO'!$A$2:$A$4919,0)) | H38: =INDEX('DETALLE CRONOLÓGICO'!$D$2:$D$4919,MATCH($A38,'DETALLE CRONOLÓGICO'!$A$2:$A$4919,0)+$E38-1) | I38: =IFERROR(SUMIFS('DETALLE CRONOLÓGICO'!$L$2:$L$4919,'DETALLE CRONOLÓGICO'!$A$2:$A$4919,$A38)/$F38,"") | J38: =IFERROR(SUMIFS('DETALLE CRONOLÓGICO'!$K$2:$K$4919,'DETALLE CRONOLÓGICO'!$A$2:$A$4919,$A38)/$E38,"") | K38: =_xlfn.MINIFS('DETALLE CRONOLÓGICO'!$K$2:$K$4919,'DETALLE CRONOLÓGICO'!$A$2:$A$4919,$A38) | L38: =_xlfn.MAXIFS('DETALLE CRONOLÓGICO'!$K$2:$K$4919,'DETALLE CRONOLÓGICO'!$A$2:$A$4919,$A38) | M38: =INDEX('DETALLE CRONOLÓGICO'!$K$2:$K$4919,MATCH($A38,'DETALLE CRONOLÓGICO'!$A$2:$A$4919,0)+$E38-1) | N38: =IFERROR($M38/INDEX('DETALLE CRONOLÓGICO'!$K$2:$K$4919,MATCH($A38,'DETALLE CRONOLÓGICO'!$A$2:$A$4919,0))-1,"") | O38: =IFERROR($I38*3,"") | P38: =IFERROR($I38*3.5,"") | Q38: =IFERROR($I38*4,"") | R38: 699 | S38: 2 | T38: active | V38: SIN PRECIO
A39: 12314361504205 | B39: ANILLO F SILVER ZIRCONIAS | C39: 8 | D39: HAIFENG | E39: =COUNTIF('DETALLE CRONOLÓGICO'!$A$2:$A$4919,$A39) | F39: =SUMIFS('DETALLE CRONOLÓGICO'!$I$2:$I$4919,'DETALLE CRONOLÓGICO'!$A$2:$A$4919,$A39) | G39: =INDEX('DETALLE CRONOLÓGICO'!$D$2:$D$4919,MATCH($A39,'DETALLE CRONOLÓGICO'!$A$2:$A$4919,0)) | H39: =INDEX('DETALLE CRONOLÓGICO'!$D$2:$D$4919,MATCH($A39,'DETALLE CRONOLÓGICO'!$A$2:$A$4919,0)+$E39-1) | I39: =IFERROR(SUMIFS('DETALLE CRONOLÓGICO'!$L$2:$L$4919,'DETALLE CRONOLÓGICO'!$A$2:$A$4919,$A39)/$F39,"") | J39: =IFERROR(SUMIFS('DETALLE CRONOLÓGICO'!$K$2:$K$4919,'DETALLE CRONOLÓGICO'!$A$2:$A$4919,$A39)/$E39,"") | K39: =_xlfn.MINIFS('DETALLE CRONOLÓGICO'!$K$2:$K$4919,'DETALLE CRONOLÓGICO'!$A$2:$A$4919,$A39) | L39: =_xlfn.MAXIFS('DETALLE CRONOLÓGICO'!$K$2:$K$4919,'DETALLE CRONOLÓGICO'!$A$2:$A$4919,$A39) | M39: =INDEX('DETALLE CRONOLÓGICO'!$K$2:$K$4919,MATCH($A39,'DETALLE CRONOLÓGICO'!$A$2:$A$4919,0)+$E39-1) | N39: =IFERROR($M39/INDEX('DETALLE CRONOLÓGICO'!$K$2:$K$4919,MATCH($A39,'DETALLE CRONOLÓGICO'!$A$2:$A$4919,0))-1,"") | O39: =IFERROR($I39*3,"") | P39: =IFERROR($I39*3.5,"") | Q39: =IFERROR($I39*4,"") | R39: 404 | S39: 1 | T39: active | V39: SIN PRECIO
A40: 12314361636973 | B40: ANILLO F SILVER ZIRCONIAS | C40: 9 | D40: HAIFENG | E40: =COUNTIF('DETALLE CRONOLÓGICO'!$A$2:$A$4919,$A40) | F40: =SUMIFS('DETALLE CRONOLÓGICO'!$I$2:$I$4919,'DETALLE CRONOLÓGICO'!$A$2:$A$4919,$A40) | G40: =INDEX('DETALLE CRONOLÓGICO'!$D$2:$D$4919,MATCH($A40,'DETALLE CRONOLÓGICO'!$A$2:$A$4919,0)) | H40: =INDEX('DETALLE CRONOLÓGICO'!$D$2:$D$4919,MATCH($A40,'DETALLE CRONOLÓGICO'!$A$2:$A$4919,0)+$E40-1) | I40: =IFERROR(SUMIFS('DETALLE CRONOLÓGICO'!$L$2:$L$4919,'DETALLE CRONOLÓGICO'!$A$2:$A$4919,$A40)/$F40,"") | J40: =IFERROR(SUMIFS('DETALLE CRONOLÓGICO'!$K$2:$K$4919,'DETALLE CRONOLÓGICO'!$A$2:$A$4919,$A40)/$E40,"") | K40: =_xlfn.MINIFS('DETALLE CRONOLÓGICO'!$K$2:$K$4919,'DETALLE CRONOLÓGICO'!$A$2:$A$4919,$A40) | L40: =_xlfn.MAXIFS('DETALLE CRONOLÓGICO'!$K$2:$K$4919,'DETALLE CRONOLÓGICO'!$A$2:$A$4919,$A40) | M40: =INDEX('DETALLE CRONOLÓGICO'!$K$2:$K$4919,MATCH($A40,'DETALLE CRONOLÓGICO'!$A$2:$A$4919,0)+$E40-1) | N40: =IFERROR($M40/INDEX('DETALLE CRONOLÓGICO'!$K$2:$K$4919,MATCH($A40,'DETALLE CRONOLÓGICO'!$A$2:$A$4919,0))-1,"") | O40: =IFERROR($I40*3,"") | P40: =IFERROR($I40*3.5,"") | Q40: =IFERROR($I40*4,"") | R40: 374 | S40: 2 | T40: active | V40: SIN PRECIO
A41: 12314361740365 | B41: COLLAR F GOLD ZIRCONIAS | C41: Default Title | D41: HAIFENG | E41: =COUNTIF('DETALLE CRONOLÓGICO'!$A$2:$A$4919,$A41) | F41: =SUMIFS('DETALLE CRONOLÓGICO'!$I$2:$I$4919,'DETALLE CRONOLÓGICO'!$A$2:$A$4919,$A41) | G41: =INDEX('DETALLE CRONOLÓGICO'!$D$2:$D$4919,MATCH($A41,'DETALLE CRONOLÓGICO'!$A$2:$A$4919,0)) | H41: =INDEX('DETALLE CRONOLÓGICO'!$D$2:$D$4919,MATCH($A41,'DETALLE CRONOLÓGICO'!$A$2:$A$4919,0)+$E41-1) | I41: =IFERROR(SUMIFS('DETALLE CRONOLÓGICO'!$L$2:$L$4919,'DETALLE CRONOLÓGICO'!$A$2:$A$4919,$A41)/$F41,"") | J41: =IFERROR(SUMIFS('DETALLE CRONOLÓGICO'!$K$2:$K$4919,'DETALLE CRONOLÓGICO'!$A$2:$A$4919,$A41)/$E41,"") | K41: =_xlfn.MINIFS('DETALLE CRONOLÓGICO'!$K$2:$K$4919,'DETALLE CRONOLÓGICO'!$A$2:$A$4919,$A41) | L41: =_xlfn.MAXIFS('DETALLE CRONOLÓGICO'!$K$2:$K$4919,'DETALLE CRONOLÓGICO'!$A$2:$A$4919,$A41) | M41: =INDEX('DETALLE CRONOLÓGICO'!$K$2:$K$4919,MATCH($A41,'DETALLE CRONOLÓGICO'!$A$2:$A$4919,0)+$E41-1) | N41: =IFERROR($M41/INDEX('DETALLE CRONOLÓGICO'!$K$2:$K$4919,MATCH($A41,'DETALLE CRONOLÓGICO'!$A$2:$A$4919,0))-1,"") | O41: =IFERROR($I41*3,"") | P41: =IFERROR($I41*3.5,"") | Q41: =IFERROR($I41*4,"") | R41: 660 | S41: 5 | T41: active | V41: SIN PRECIO
A42: 12314361978221 | B42: ARETES F SILVER ZIRCONIAS | C42: Default Title | D42: HAIFENG | E42: =COUNTIF('DETALLE CRONOLÓGICO'!$A$2:$A$4919,$A42) | F42: =SUMIFS('DETALLE CRONOLÓGICO'!$I$2:$I$4919,'DETALLE CRONOLÓGICO'!$A$2:$A$4919,$A42) | G42: =INDEX('DETALLE CRONOLÓGICO'!$D$2:$D$4919,MATCH($A42,'DETALLE CRONOLÓGICO'!$A$2:$A$4919,0)) | H42: =INDEX('DETALLE CRONOLÓGICO'!$D$2:$D$4919,MATCH($A42,'DETALLE CRONOLÓGICO'!$A$2:$A$4919,0)+$E42-1) | I42: =IFERROR(SUMIFS('DETALLE CRONOLÓGICO'!$L$2:$L$4919,'DETALLE CRONOLÓGICO'!$A$2:$A$4919,$A42)/$F42,"") | J42: =IFERROR(SUMIFS('DETALLE CRONOLÓGICO'!$K$2:$K$4919,'DETALLE CRONOLÓGICO'!$A$2:$A$4919,$A42)/$E42,"") | K42: =_xlfn.MINIFS('DETALLE CRONOLÓGICO'!$K$2:$K$4919,'DETALLE CRONOLÓGICO'!$A$2:$A$4919,$A42) | L42: =_xlfn.MAXIFS('DETALLE CRONOLÓGICO'!$K$2:$K$4919,'DETALLE CRONOLÓGICO'!$A$2:$A$4919,$A42) | M42: =INDEX('DETALLE CRONOLÓGICO'!$K$2:$K$4919,MATCH($A42,'DETALLE CRONOLÓGICO'!$A$2:$A$4919,0)+$E42-1) | N42: =IFERROR($M42/INDEX('DETALLE CRONOLÓGICO'!$K$2:$K$4919,MATCH($A42,'DETALLE CRONOLÓGICO'!$A$2:$A$4919,0))-1,"") | O42: =IFERROR($I42*3,"") | P42: =IFERROR($I42*3.5,"") | Q42: =IFERROR($I42*4,"") | R42: 580 | S42: 3 | T42: active | V42: SIN PRECIO
A43: 12314362081613 | B43: ARETES F GOLD ZIRCONIAS | C43: Default Title | D43: HAIFENG | E43: =COUNTIF('DETALLE CRONOLÓGICO'!$A$2:$A$4919,$A43) | F43: =SUMIFS('DETALLE CRONOLÓGICO'!$I$2:$I$4919,'DETALLE CRONOLÓGICO'!$A$2:$A$4919,$A43) | G43: =INDEX('DETALLE CRONOLÓGICO'!$D$2:$D$4919,MATCH($A43,'DETALLE CRONOLÓGICO'!$A$2:$A$4919,0)) | H43: =INDEX('DETALLE CRONOLÓGICO'!$D$2:$D$4919,MATCH($A43,'DETALLE CRONOLÓGICO'!$A$2:$A$4919,0)+$E43-1) | I43: =IFERROR(SUMIFS('DETALLE CRONOLÓGICO'!$L$2:$L$4919,'DETALLE CRONOLÓGICO'!$A$2:$A$4919,$A43)/$F43,"") | J43: =IFERROR(SUMIFS('DETALLE CRONOLÓGICO'!$K$2:$K$4919,'DETALLE CRONOLÓGICO'!$A$2:$A$4919,$A43)/$E43,"") | K43: =_xlfn.MINIFS('DETALLE CRONOLÓGICO'!$K$2:$K$4919,'DETALLE CRONOLÓGICO'!$A$2:$A$4919,$A43) | L43: =_xlfn.MAXIFS('DETALLE CRONOLÓGICO'!$K$2:$K$4919,'DETALLE CRONOLÓGICO'!$A$2:$A$4919,$A43) | M43: =INDEX('DETALLE CRONOLÓGICO'!$K$2:$K$4919,MATCH($A43,'DETALLE CRONOLÓGICO'!$A$2:$A$4919,0)+$E43-1) | N43: =IFERROR($M43/INDEX('DETALLE CRONOLÓGICO'!$K$2:$K$4919,MATCH($A43,'DETALLE CRONOLÓGICO'!$A$2:$A$4919,0))-1,"") | O43: =IFERROR($I43*3,"") | P43: =IFERROR($I43*3.5,"") | Q43: =IFERROR($I43*4,"") | R43: 580 | S43: 2 | T43: active | V43: SIN PRECIO
A44: 12314362119469 | B44: PULSERA F O'LOCK GOLD | C44: Default Title | D44: HAIFENG | E44: =COUNTIF('DETALLE CRONOLÓGICO'!$A$2:$A$4919,$A44) | F44: =SUMIFS('DETALLE CRONOLÓGICO'!$I$2:$I$4919,'DETALLE CRONOLÓGICO'!$A$2:$A$4919,$A44) | G44: =INDEX('DETALLE CRONOLÓGICO'!$D$2:$D$4919,MATCH($A44,'DETALLE CRONOLÓGICO'!$A$2:$A$4919,0)) | H44: =INDEX('DETALLE CRONOLÓGICO'!$D$2:$D$4919,MATCH($A44,'DETALLE CRONOLÓGICO'!$A$2:$A$4919,0)+$E44-1) | I44: =IFERROR(SUMIFS('DETALLE CRONOLÓGICO'!$L$2:$L$4919,'DETALLE CRONOLÓGICO'!$A$2:$A$4919,$A44)/$F44,"") | J44: =IFERROR(SUMIFS('DETALLE CRONOLÓGICO'!$K$2:$K$4919,'DETALLE CRONOLÓGICO'!$A$2:$A$4919,$A44)/$E44,"") | K44: =_xlfn.MINIFS('DETALLE CRONOLÓGICO'!$K$2:$K$4919,'DETALLE CRONOLÓGICO'!$A$2:$A$4919,$A44) | L44: =_xlfn.MAXIFS('DETALLE CRONOLÓGICO'!$K$2:$K$4919,'DETALLE CRONOLÓGICO'!$A$2:$A$4919,$A44) | M44: =INDEX('DETALLE CRONOLÓGICO'!$K$2:$K$4919,MATCH($A44,'DETALLE CRONOLÓGICO'!$A$2:$A$4919,0)+$E44-1) | N44: =IFERROR($M44/INDEX('DETALLE CRONOLÓGICO'!$K$2:$K$4919,MATCH($A44,'DETALLE CRONOLÓGICO'!$A$2:$A$4919,0))-1,"") | O44: =IFERROR($I44*3,"") | P44: =IFERROR($I44*3.5,"") | Q44: =IFERROR($I44*4,"") | R44: 580 | S44: 3 | T44: active | V44: SIN PRECIO
A45: 12314362492941 | B45: ARETES F GOLD | C45: Default Title | D45: HAIFENG | E45: =COUNTIF('DETALLE CRONOLÓGICO'!$A$2:$A$4919,$A45) | F45: =SUMIFS('DETALLE CRONOLÓGICO'!$I$2:$I$4919,'DETALLE CRONOLÓGICO'!$A$2:$A$4919,$A45) | G45: =INDEX('DETALLE CRONOLÓGICO'!$D$2:$D$4919,MATCH($A45,'DETALLE CRONOLÓGICO'!$A$2:$A$4919,0)) | H45: =INDEX('DETALLE CRONOLÓGICO'!$D$2:$D$4919,MATCH($A45,'DETALLE CRONOLÓGICO'!$A$2:$A$4919,0)+$E45-1) | I45: =IFERROR(SUMIFS('DETALLE CRONOLÓGICO'!$L$2:$L$4919,'DETALLE CRONOLÓGICO'!$A$2:$A$4919,$A45)/$F45,"") | J45: =IFERROR(SUMIFS('DETALLE CRONOLÓGICO'!$K$2:$K$4919,'DETALLE CRONOLÓGICO'!$A$2:$A$4919,$A45)/$E45,"") | K45: =_xlfn.MINIFS('DETALLE CRONOLÓGICO'!$K$2:$K$4919,'DETALLE CRONOLÓGICO'!$A$2:$A$4919,$A45) | L45: =_xlfn.MAXIFS('DETALLE CRONOLÓGICO'!$K$2:$K$4919,'DETALLE CRONOLÓGICO'!$A$2:$A$4919,$A45) | M45: =INDEX('DETALLE CRONOLÓGICO'!$K$2:$K$4919,MATCH($A45,'DETALLE CRONOLÓGICO'!$A$2:$A$4919,0)+$E45-1) | N45: =IFERROR($M45/INDEX('DETALLE CRONOLÓGICO'!$K$2:$K$4919,MATCH($A45,'DETALLE CRONOLÓGICO'!$A$2:$A$4919,0))-1,"") | O45: =IFERROR($I45*3,"") | P45: =IFERROR($I45*3.5,"") | Q45: =IFERROR($I45*4,"") | R45: 499 | S45: 4 | T45: active | V45: SIN PRECIO
...

Sheet DETALLE CRONOLÓGICO
A1: SKU | B1: PRODUCTO | C1: VARIANTE | D1: FECHA | E1: AÑO | F1: MES | G1: PROVEEDOR | H1: ORDEN DE COMPRA | I1: PIEZAS | J1: COSTO UNIT USD | K1: COSTO UNIT TOTAL MXN | L1: COSTO x PIEZAS (MXN) | M1: ROAS 4 DE ESA ORDEN | N1: PRECIO QUE TENÍA EN ESA ORDEN
A2: 10065591041229 | B2: TRAJE DE BAÑO COMPLETO TRIOMPHE | C2: M | D2: 19/03/2026 | E2: 2026 | F2: MARZO | G2: ZOEY | H2: ZOEY 19/03/2026 | I2: 2 | J2: 25 | K2: 644.55124 | L2: =I2*K2 | M2: =K2*4 | N2: 2499
A3: 10065591041229 | B3: TRAJE DE BAÑO COMPLETO TRIOMPHE | C3: M | D3: 08/06/2026 | E3: 2026 | F3: JUNIO | G3: ZOEY | H3: ZOEY 08/06/2026 | I3: 2 | J3: 25 | K3: 612.78591 | L3: =I3*K3 | M3: =K3*4 | N3: 2499
A4: 10065591106765 | B4: TRAJE DE BAÑO C TRIOMPHE ALL BLACK | C4: M | D4: 19/03/2026 | E4: 2026 | F4: MARZO | G4: ZOEY | H4: ZOEY 19/03/2026 | I4: 2 | J4: 25 | K4: 644.55124 | L4: =I4*K4 | M4: =K4*4 | N4: 2579
A5: 10065591251949 | B5: TRAJE DE BAÑO GC PINK | C5: M | D5: 19/03/2026 | E5: 2026 | F5: MARZO | G5: ZOEY | H5: ZOEY 19/03/2026 | I5: 2 | J5: 25 | K5: 644.55124 | L5: =I5*K5 | M5: =K5*4 | N5: 2579
A6: 10065591348557 | B6: TRAJE DE BAÑO COMPLETO CD | C6: M | D6: 19/03/2026 | E6: 2026 | F6: MARZO | G6: ZOEY | H6: ZOEY 19/03/2026 | I6: 2 | J6: 25 | K6: 644.55124 | L6: =I6*K6 | M6: =K6*4 | N6: 2579
A7: 10132411046285 | B7: SANDALIAS CD DIORACT BLACK | C7: 38/25mx | D7: 27/04/2026 | E7: 2026 | F7: ABRIL | G7: DINA DU | H7: DINA DU 27/04/2026 | I7: 2 | J7: 35 | K7: 946.55095 | L7: =I7*K7 | M7: =K7*4 | N7: 3789
A8: 10132411116909 | B8: BOLSO CD SADDLE ALL BLACK | C8: Default Title | D8: 27/04/2026 | E8: 2026 | F8: ABRIL | G8: DINA DU | H8: DINA DU 27/04/2026 | I8: 2 | J8: 63 | K8: 1703.7917 | L8: =I8*K8 | M8: =K8*4 | N8: 5999
A9: 10132411251373 | B9: BOLSO CD BOW BURGUNDY | C9: Default Title | D9: 27/04/2026 | E9: 2026 | F9: ABRIL | G9: DINA DU | H9: DINA DU 27/04/2026 | I9: 3 | J9: 71 | K9: 1920.1462 | L9: =I9*K9 | M9: =K9*4 | N9: 6720.51
A10: 10132411318605 | B10: BOLSO CD BOW BLACK | C10: Default Title | D10: 27/04/2026 | E10: 2026 | F10: ABRIL | G10: DINA DU | H10: DINA DU 27/04/2026 | I10: 3 | J10: 71 | K10: 1920.1462 | L10: =I10*K10 | M10: =K10*4 | N10: 6720.51
A11: 10132411463245 | B11: GORRO F LOGOS | C11: Default Title | D11: 27/04/2026 | E11: 2026 | F11: ABRIL | G11: DINA DU | H11: DINA DU 27/04/2026 | I11: 2 | J11: 10 | K11: 270.44313 | L11: =I11*K11 | M11: =K11*4 | N11: 1089
A12: 10132411501101 | B12: CARTERA F GRAPHY WHITE | C12: Default Title | D12: 27/04/2026 | E12: 2026 | F12: ABRIL | G12: DINA DU | H12: DINA DU 27/04/2026 | I12: 2 | J12: 52 | K12: 1406.3043 | L12: =I12*K12 | M12: =K12*4 | N12: 4300
A13: 10132411606189 | B13: CARTERA F BAGUETTE MINI | C13: Default Title | D13: 27/04/2026 | E13: 2026 | F13: ABRIL | G13: DINA DU | H13: DINA DU 27/04/2026 | I13: 2 | J13: 75 | K13: 2028.3235 | L13: =I13*K13 | M13: =K13*4 | N13: 6500
... A19: 10427542282892 | B19: RELOJ SANTOS SILVER | C19: 34mm Mujer Con Caja | D19: 08/06/2026 | E19: 2026 | F19: JUNIO | G19: ZOEY | H19: ZOEY 08/06/2026 | I19: 3 | J19: 68 | K19: 1666.7777 | L19: =I19*K19 | M19: =K19*4 | N19: 6699
A20: 10427542282893 | C20: 39mm Hombre Con Caja | D20: 02/10/2025 | E20: 2025 | F20: OCTUBRE | G20: ZOEY | H20: ZOEY 02/10/2025 | I20: 5 | J20: 68 | K20: 1606.4276 | L20: =I20*K20 | M20: =K20*4 | N20: 5650
A21: 10427542282893 | B21: RELOJ SANTOS SILVER | C21: women | D21: 25/10/2025 | E21: 2025 | F21: OCTUBRE | G21: ZOEY | H21: ZOEY 25/10/2025 | I21: 4 | J21: 58 | K21: 1438.4063 | L21: =I21*K21 | M21: =K21*4 | N21: 5650
A22: 10427542282893 | B22: RELOJ SANTOS SILVER | C22: 39mm Hombre Con Caja | D22: 08/06/2026 | E22: 2026 | F22: JUNIO | G22: ZOEY | H22: ZOEY 08/06/2026 | I22: 3 | J22: 68 | K22: 1666.7777 | L22: =I22*K22 | M22: =K22*4 | N22: 6699
A23: 10473111097537 | B23: PULSERA DE CUENTAS ROSEGOLD | C23: 17cm | D23: 01/09/2025 | E23: 2025 | F23: SEPTIEMBRE | G23: ZOEY | H23: ZOEY 01/09/2025 | I23: 4 | J23: 9 | K23: 226.0606 | L23: =I23*K23 | M23: =K23*4 | N23: 750
A24: 10473111097537 | B24: PULSERA DE CUENTAS ROSEGOLD | C24: 17cm | D24: 25/10/2025 | E24: 2025 | F24: OCTUBRE | G24: ZOEY | H24: ZOEY 25/10/2025 | I24: 8 | J24: 9 | K24: 223.20098 | L24: =I24*K24 | M24: =K24*4 | N24: 750
A25: 10473111097537 | B25: PULSERA DE CUENTAS ROSEGOLD | C25: 17cm | D25: 20/01/2026 | E25: 2026 | F25: ENERO | G25: ZOEY | H25: ZOEY 20/01/2026 | I25: 2 | J25: 9 | K25: 234.28439 | L25: =I25*K25 | M25: =K25*4 | N25: 899
A26: 10473111097537 | B26: PULSERA DE CUENTAS ROSEGOLD | C26: 17cm | D26: 02/03/2026 | E26: 2026 | F26: MARZO | G26: ZOEY | H26: ZOEY 02/03/2026 | I26: 2 | J26: 6 | K26: 157.66185 | L26: =I26*K26 | M26: =K26*4 | N26: 899
A27: 10473111097537 | B27: PULSERA DE CUENTAS ROSEGOLD | C27: 17cm | D27: 08/06/2026 | E27: 2026 | F27: JUNIO | G27: ZOEY | H27: ZOEY 08/06/2026 | I27: 6 | J27: 9 | K27: 220.60293 | L27: =I27*K27 | M27: =K27*4 | N27: 899
A28: 10717801055213 | B28: ANILLO CD ZIRCONIAS GOLD-BLACK | C28: 7 | D28: 20/01/2026 | E28: 2026 | F28: ENERO | G28: HAIFENG | H28: HAIFENG 20/01/2026 | I28: 1 | J28: 9.5 | K28: 201.40397 | L28: =I28*K28 | M28: =K28*4 | N28: 790.5
A29: 10717801055213 | C29: 7 | D29: 10/02/2026 | E29: 2026 | F29: FEBRERO | G29: HAIFENG | H29: HAIFENG 10/02/2026 | I29: 2 | J29: 9.5 | K29: 200.15071 | L29: =I29*K29 | M29: =K29*4 | N29: 790.5
A30: 10956321024557 | B30: ANILLO BV BUMPS GOLD ZIRCONIAS-6 | C30: 6 | D30: 25/09/2025 | E30: 2025 | F30: SEPTIEMBRE | G30: HAIFENG | H30: HAIFENG 25/09/2025 | I30: 2 | J30: 10 | K30: 210.96886 | L30: =I30*K30 | M30: =K30*4 | N30: 999
A31: 10956321024557 | B31: ANILLO BV BUMPS GOLD ZIRCONIAS | C31: 6 | D31: 11/03/2026 | E31: 2026 | F31: MARZO | G31: HAIFENG | H31: HAIFENG 11/03/2026 | I31: 2 | J31: 11 | K31: 234.34286 | L31: =I31*K31 | M31: =K31*4 | N31: 999
A32: 10956321157325 | B32: ANILLO BV BUMPS GOLD ZIRCONIAS.7 | C32: 7 | D32: 25/09/2025 | E32: 2025 | F32: SEPTIEMBRE | G32: HAIFENG | H32: HAIFENG 25/09/2025 | I32: 2 | J32: 10 | K32: 210.96886 | L32: =I32*K32 | M32: =K32*4 | N32: 999
A33: 10956321157325 | C33: 7 | D33: 10/02/2026 | E33: 2026 | F33: FEBRERO | G33: HAIFENG | H33: HAIFENG 10/02/2026 | I33: 2 | J33: 11 | K33: 231.75346 | L33: =I33*K33 | M33: =K33*4 | N33: 999
A34: 10956321157325 | B34: ANILLO BV BUMPS GOLD ZIRCONIAS | C34: 7 | D34: 06/05/2026 | E34: 2026 | F34: MAYO | G34: HAIFENG | H34: HAIFENG 06/05/2026 | I34: 2 | J34: 12 | K34: 254.62371 | L34: =I34*K34 | M34: =K34*4 | N34: 999
A35: 10956321291309 | B35: ANILLO BV BUMPS SILVER ZIRCONIAS-6 | C35: 6 | D35: 25/09/2025 | E35: 2025 | F35: SEPTIEMBRE | G35: HAIFENG | H35: HAIFENG 25/09/2025 | I35: 2 | J35: 10 | K35: 210.96886 | L35: =I35*K35 | M35: =K35*4 | N35: 850
A36: 10956321324077 | B36: ANILLO BV BUMPS SILVER ZIRCONIAS-7 | C36: 7 | D36: 25/09/2025 | E36: 2025 | F36: SEPTIEMBRE | G36: HAIFENG | H36: HAIFENG 25/09/2025 | I36: 2 | J36: 10 | K36: 210.96886 | L36: =I36*K36 | M36: =K36*4 | N36: 850
A37: 10956321324077 | B37: ANILLO BV BUMPS SILVER ZIRCONIAS | C37: 7 | D37: 16/04/2026 | E37: 2026 | F37: ABRIL | G37: HAIFENG | H37: HAIFENG 16/04/2026 | I37: 1 | J37: 10 | K37: 210.31474 | L37: =I37*K37 | M37: =K37*4 | N37: 850
A38: 11078751761037 | B38: COLLAR C GOLD ZIRCONIAS | C38: Default Title | D38: 22/10/2025 | E38: 2025 | F38: OCTUBRE | G38: HAIFENG | H38: HAIFENG 22/10/2025 | I38: 2 | J38: 5.99 | K38: 126.55829 | L38: =I38*K38 | M38: =K38*4 | N38: 550
A39: 11078751761037 | B39: COLLAR C GOLD ZIRCONIAS | C39: Default Title | D39: 10/02/2026 | E39: 2026 | F39: FEBRERO | G39: HAIFENG | H39: HAIFENG 10/02/2026 | I39: 3 | J39: 5.99 | K39: 126.20029 | L39: =I39*K39 | M39: =K39*4 | N39: 550
A40: 11078751761037 | B40: COLLAR C GOLD ZIRCONIAS | C40: Default Title | D40: 16/04/2026 | E40: 2026 | F40: ABRIL | G40: HAIFENG | H40: HAIFENG 16/04/2026 | I40: 8 | J40: 5.99 | K40: 125.97853 | L40: =I40*K40 | M40: =K40*4 | N40: 550
A41: 11078751761037 | B41: COLLAR C GOLD ZIRCONIAS | C41: Default Title | D41: 26/05/2026 | E41: 2026 | F41: MAYO | G41: HAIFENG | H41: HAIFENG 26/05/2026 | I41: 5 | J41: 5.99 | K41: 125.72588 | L41: =I41*K41 | M41: =K41*4 | N41: 550
A42: 11078751910221 | B42: ARETES C GOLD ZIRCONIAS | C42: Default Title | D42: 22/10/2025 | E42: 2025 | F42: OCTUBRE | G42: HAIFENG | H42: HAIFENG 22/10/2025 | I42: 3 | J42: 5.99 | K42: 126.55829 | L42: =I42*K42 | M42: =K42*4 | N42: 575
A43: 11078751910221 | B43: ARETES C GOLD ZIRCONIAS | C43: Default Title | D43: 20/01/2026 | E43: 2026 | F43: ENERO | G43: HAIFENG | H43: HAIFENG 20/01/2026 | I43: 3 | J43: 5.99 | K43: 126.9905 | L43: =I43*K43 | M43: =K43*4 | N43: 575
A44: 11078751910221 | B44: ARETES C GOLD ZIRCONIAS | C44: Default Title | D44: 10/02/2026 | E44: 2026 | F44: FEBRERO | G44: HAIFENG | H44: HAIFENG 10/02/2026 | I44: 3 | J44: 5.99 | K44: 126.20029 | L44: =I44*K44 | M44: =K44*4 | N44: 575
A45: 11078751910221 | B45: ARETES C GOLD ZIRCONIAS | C45: Default Title | D45: 16/04/2026 | E45: 2026 | F45: ABRIL | G45: HAIFENG | H45: HAIFENG 16/04/2026 | I45: 7 | J45: 5.99 | K45: 125.97853 | L45: =I45*K45 | M45: =K45*4 | N45: 575
...

Sheet COSTO POR MES
A1: COSTO UNITARIO TOTAL (MXN) POR MES — celda vacía = no se compró ese mes
A3: SKU | B3: PRODUCTO | C3: MAY-25 | D3: SEP-25 | E3: OCT-25 | F3: NOV-25 | G3: DIC-25 | H3: ENE-26 | I3: FEB-26 | J3: MAR-26 | K3: ABR-26 | L3: MAY-26 | M3: JUN-26 | N3: JUL-26
A4: 10065591041229 | B4: TRAJE DE BAÑO COMPLETO TRIOMPHE | J4: 644.55124 | M4: 612.78591
A5: 10065591106765 | B5: TRAJE DE BAÑO C TRIOMPHE ALL BLACK | J5: 644.55124
A6: 10065591251949 | B6: TRAJE DE BAÑO GC PINK | J6: 644.55124
A7: 10065591348557 | B7: TRAJE DE BAÑO COMPLETO CD | J7: 644.55124
A8: 10132411046285 | B8: SANDALIAS CD DIORACT BLACK | K8: 946.55095
A9: 10132411116909 | B9: BOLSO CD SADDLE ALL BLACK | K9: 1703.7917
A10: 10132411251373 | B10: BOLSO CD BOW BURGUNDY | K10: 1920.1462
A11: 10132411318605 | B11: BOLSO CD BOW BLACK | K11: 1920.1462
A12: 10132411463245 | B12: GORRO F LOGOS | K12: 270.44313
A13: 10132411501101 | B13: CARTERA F GRAPHY WHITE | K13: 1406.3043
A14: 10132411606189 | B14: CARTERA F BAGUETTE MINI | K14: 2028.3235
A15: 10132411776813 | B15: BOLSO F GRAPHY LOGOS | K15: 2109.4564
A16: 10427542282892 | B16: RELOJ SANTOS SILVER | D16: 1708.0134 | E16: 1528.2979 | J16: 1786.8343 | M16: 1666.7777
A17: 10427542282893 | B17: RELOJ SANTOS SILVER | E17: 1522.417 | M17: 1666.7777
A18: 10473111097537 | B18: PULSERA DE CUENTAS ROSEGOLD | D18: 226.0606 | E18: 223.20098 | H18: 234.28439 | J18: 157.66185 | M18: 220.60293
A19: 10717801055213 | B19: ANILLO CD ZIRCONIAS GOLD-BLACK | H19: 201.40397 | I19: 200.15071
A20: 10956321024557 | B20: ANILLO BV BUMPS GOLD ZIRCONIAS | D20: 210.96886 | J20: 234.34286
A21: 10956321157325 | B21: ANILLO BV BUMPS GOLD ZIRCONIAS | D21: 210.96886 | I21: 231.75346 | L21: 254.62371
A22: 10956321291309 | B22: ANILLO BV BUMPS SILVER ZIRCONIAS-6 | D22: 210.96886
A23: 10956321324077 | B23: ANILLO BV BUMPS SILVER ZIRCONIAS | D23: 210.96886 | K23: 210.31474
A24: 11078751761037 | B24: COLLAR C GOLD ZIRCONIAS | E24: 126.55829 | I24: 126.20029 | K24: 125.97853 | L24: 125.72588
A25: 11078751910221 | B25: ARETES C GOLD ZIRCONIAS | E25: 126.55829 | H25: 126.9905 | I25: 126.20029 | K25: 125.97853 | L25: 125.72588
A26: 11078752382541 | B26: ARETES C GOLD PEARL | E26: 126.55829 | H26: 126.9905 | I26: 126.20029 | K26: 125.97853 | M26: 125.87749
A27: 11453671120077 | B27: ARETES FR GOLD ONE PEARL | H27: 127.20251
A28: 11915813184811 | B28: LENTES DE SOL MM BROWN | D28: 705.01471 | J28: 778.86506
A29: 11915820343339 | B29: LENTES MM HAVANA | D29: 679.83562 | E29: 707.44924 | H29: 717.86055 | L29: 715.52821
A30: 11915825730987 | B30: TRAJE DE BAÑO C | J30: 859.43731
A31: 11915825763755 | B31: TRAJE DE BAÑO C | K31: 830.40296
A32: 11915826071979 | B32: LENTES LV EVIDENCE | D32: 226.61187 | H32: 239.28685 | J32: 241.71674 | L32: 238.5094
A33: 11915828032299 | B33: BOLSO DE VIAJE G BOWLING 55 GREEN | L33: 1987.5784
A34: 11915828105387 | B34: TRAJE DE BAÑO V | D34: 246.75515 | J34: 290.06009 | K34: 280.261
A35: 11915828138155 | B35: TRAJE DE BAÑO V | D35: 246.75515 | L35: 286.21129
A36: 11966951169965 | B36: PULSERA DE CUENTAS CON INSIGNIA DE CORAZÓN BLUE | M36: 105.07303
A37: 12314361063501 | B37: ANILLO F DOBLE GOLD | E37: 147.89783 | H37: 148.40292 | I37: 147.47947 | K37: 147.22032 | L37: 148.5305 | M37: 147.10225
A38: 12314361226797 | B38: ARRACADAS COLGANTES F ZIRCONIA | E38: 169.0261 | H38: 169.60334 | I38: 168.54797
A39: 12314361364653 | B39: ARETES F GOLD PEARL | E39: 169.0261 | H39: 169.60334 | I39: 168.54797 | L39: 167.91436 | M39: 168.11685
A40: 12314361469741 | B40: ARETES F FILO GOLD | E40: 126.76957 | L40: 167.70447
A41: 12314361504205 | B41: ANILLO F SILVER ZIRCONIAS | E41: 147.89783 | M41: 147.10225
...

Sheet SIN HISTORIAL DE PRECIO
